Workbook

Sheet ANALISE
A3: Rótulos de Linha | B3: Soma de DIFERENÇA VALOR
A4: Insumo Terc. | B4: 0
A5: AÇUCAR | B5: 0
A6: LACRE | B6: 0
A7: AROMA | B7: 0
A8: LATA | B8: 0
A9: CARVAO | B9: 0
A10: LUPULO | B10: 0
A11: CONCENTRADO | B11: 0
A12: MALTE | B12: 0
A13: CORANTE | B13: 0
A14: PREFORMA | B14: 0
A15: ELABORAÇÃO | B15: 0
... A35: Total Geral | B35: 0

Sheet KPI
B2: VALOR ESTOQUE FÍSICO (MP) | M2: CUSTO (R$) DIVERGÊNCIA (MP)
B3: MÊS | C3: VALOR (R$) | M3: MÊS | N3: VALOR (R$)
B4: JANEIRO | C4: 14484679 | M4: JANEIRO | N4: 118144.18
B5: FEVEREIRO | C5: 13521013 | M5: FEVEREIRO | N5: 267353.14
B6: MARÇO | C6: 14243064 | M6: MARÇO | N6: 281640.56
B7: ABRIL | C7: 12258289 | M7: ABRIL | N7: 206892.35
B8: MAIO | C8: 9350849.2 | M8: MAIO | N8: 85994.001
B9: JUNHO | C9: 8710025.7 | M9: JUNHO | N9: 100512.52
B10: JULHO | M10: JULHO
B11: AGOSTO | M11: AGOSTO
B12: SETEMBRO | M12: SETEMBRO
B13: OUTUBRO | C13: 9786201.2 | M13: OUTUBRO | N13: =C13-C29 -> -823245.49
B14: NOVEMBRO | C14: 11626525 | M14: NOVEMBRO | N14: =C14-C30 -> 47666.517
B15: DEZEMBRO | C15: 11050986 | M15: DEZEMBRO | N15: 55057.669
B16: MÉDIA | C16: =AVERAGE(C4:C15) -> 11670181 | M16: MÉDIA | N16: =AVERAGE(N4:N15) -> 37779.494
B18: VALOR ESTOQUE SISTEMA (MP) | M18: % DIVERGÊNCIA (MP)
B19: MÊS | C19: VALOR (R$) | M19: MÊS | N19: VALOR (R$)
B20: JANEIRO | C20: 14366535 | M20: JANEIRO | N20: 0.0082235682
B21: FEVEREIRO | C21: 13253660 | M21: FEVEREIRO | N21: 0.020172023
B22: MARÇO | C22: 13961423 | M22: MARÇO | N22: 0.020172769
B23: ABRIL | C23: 12051397 | M23: ABRIL | N23: 0.017167499
B24: MAIO | C24: 9264855.2 | M24: MAIO | N24: 0.0092817426
B25: JUNHO | C25: 8609513.2 | M25: JUNHO | N25: 0.011674588
B26: JULHO | M26: JULHO
B27: AGOSTO | M27: AGOSTO
B28: SETEMBRO | M28: SETEMBRO
B29: OUTUBRO | C29: 10609447 | M29: OUTUBRO | N29: =IFERROR(N13/C29,"") -> -0.077595516
B30: NOVEMBRO | C30: 11578858 | M30: NOVEMBRO | N30: =IFERROR(N14/C30,"") -> 0.0041166855
B31: DEZEMBRO | C31: 10995928 | M31: DEZEMBRO | N31: 0.0050070962
B32: MÉDIA | C32: =AVERAGE(C20:C31) -> 11632402 | M32: MÉDIA | N32: =AVERAGE(N20:N31) -> 0.0020244951
B34: VALOR ESTOQUE FÍSICO (PA) | M34: ACURACIDADE QUALITATIVA (MP)
B35: MÊS | C35: VALOR (R$) | M35: MÊS | N35: %
B36: JANEIRO | C36: 2390297.8 | M36: JANEIRO | N36: 0.64661654
B37: FEVEREIRO | C37: 3642342.8 | M37: FEVEREIRO | N37: 0.62737643
B38: MARÇO | C38: 1858028.3 | M38: MARÇO | N38: 0.6627907
B39: ABRIL | C39: 1454970.4 | M39: ABRIL | N39: 0.70342205
B40: MAIO | C40: 1203577.7 | M40: MAIO | N40: 0.73705179
B41: JUNHO | C41: 2240566.9 | M41: JUNHO | N41: 0.74501992
B42: JULHO | M42: JULHO
B43: AGOSTO | M43: AGOSTO
...

Sheet BASE PRODUTOS
A1: BASE DE CADASTRO TOTVS
A2: Codigo | B2: Descricao | C2: Tipo | D2: Unidade | E2: Fator Conv.
A3: 2000010001 | B3: AT MALDIVES 12X250ML | C3: PA | D3: FD | E3: 12
A4: 2000010002 | B4: REFRIKO COLA 12X200ML | C4: PA | D4: FD | E4: 12
A5: 2000010003 | B5: REFRIKO COLA 12X500ML | C5: PA | D5: FD | E5: 12
A6: 2000010004 | B6: REFRIKO COLA 4X3LT | C6: PA | D6: FD | E6: 4
A7: 2000010005 | B7: REFRIKO COLA 6X2LT | C7: PA | D7: FD | E7: 6
A8: 2000010006 | B8: REFRIKO COLA 6X350ML | C8: PA | D8: FD | E8: 6
A9: 2000010007 | B9: REFRIKO FRAMBOESA 6X2LT | C9: PA | D9: FD | E9: 6
A10: 2000010008 | B10: REFRIKO GUARANA 12X200ML | C10: PA | D10: FD | E10: 12
A11: 2000010009 | B11: REFRIKO GUARANA 12X500ML | C11: PA | D11: FD | E11: 12
A12: 2000010010 | B12: REFRIKO GUARANA 24X600ML - RET | C12: PA | D12: CX | E12: 24
A13: 2000010011 | B13: REFRIKO GUARANA 4X3LT | C13: PA | D13: FD | E13: 4
A14: 2000010012 | B14: REFRIKO GUARANA 6X2LT | C14: PA | D14: FD | E14: 6
... A13198: 9999990006 | B13198: REEMBOLSO DE VIAGEM | C13198: OU | D13198: UN | E13198: 0
A13199: FL03040001 | B13199: FILTRO DE PAPEL MELITTA | C13199: MC | D13199: UN | E13199: 0
A13200: 2701010044 | B13200: ROTULO SLEEVE FURIOSO TANGERINA E LIMAO ZERO 473ML | E13200: 0.0020921

Sheet CONCILIÇÃO_COM_CERVEJA
J1: Valor Estoque Físico | M1: Valor Estoque Sistema | R1: Acuracidade Qualitativa | S1: Custo Diferença | T1: Percentual Diferença
J2: =SUBTOTAL(9,#REF!) -> #REF! | M2: =SUBTOTAL(9,CONCILIÇÃO_COM_CERVEJA!$N$5:$N$378) -> 9260128.5 | R2: =(COUNTIF(CONCILIÇÃO_COM_CERVEJA!$J$5:$J$378,">0")-COUNTIF(CONCILIÇÃO_COM_CERVEJA!$T$5:$T$378,">1,05")-COUNTIF(CONCILIÇÃO_COM_CERVEJA!$T$5:$T$378,"<0,95"))/COUNTIF(CONCILIÇÃO_COM_CERVEJA!$J$5:$J$378,">0") -> 1 | S2: =SUBTOTAL(9,CONCILIÇÃO_COM_CERVEJA!$S$5:$S$378) -> -500976.35 | T2: =S2/M2 -> -0.054100367
A4: CÓD. SAIB | B4: CÓD. PRODUTO | C4: CODIGO NOVO | D4: DESCRIÇÃO | E4: Consumo total mês 7 | F4: CLASSE | G4: Fator Conv. | H4: 30/jun | I4: ? | J4: Contagem | K4: SIST COD KG | L4: SIST COD UND | M4: SALDO SISTEMA TOTAL | N4: CUSTO SISTEMA | O4: DIFERENÇA ANTERIOR | P4: Diferença atual | Q4: Diveregencia mês anterior | R4: CUSTO MP (UN) | S4: CUSTO DIVERGÊNCIA | T4: ACURACIDADE | U4: DIFERENÇA VALOR | V4: OBS
A5: 55 | B5: 2701080001 | C5: - | D5: ACUCAR CRISTAL | E5: =IFERROR(VLOOKUP(B5,[1]AGLUTINADO!$A:$C,3,0),0)/G5 -> 133961.33 | F5: AÇUCAR | G5: 1 | H5: =VLOOKUP(CONCILIÇÃO_COM_CERVEJA!$B5,CONT_ANTE!A:D,4,0) -> 42000 | I5: =IF(AND(E5=0,H5<>J5),"!@##@!","ok") -> ok | J5: 55200 | K5: =SUMIF(SISTEMA!B:B,CONCILIÇÃO_COM_CERVEJA!$B5,SISTEMA!I:I)/G5 -> 63047.67 | L5: =SUMIF(SISTEMA!B:B,CONCILIÇÃO_COM_CERVEJA!$C5,SISTEMA!I:I) -> 0 | M5: =K5+L5 -> 63047.67 | N5: =IFERROR(SUM(CONCILIÇÃO_COM_CERVEJA!$M5*CONCILIÇÃO_COM_CERVEJA!$R5),0) -> 148650.93 | O5: =IFERROR(VLOOKUP(CONCILIÇÃO_COM_CERVEJA!$B5,DIF_ANTE!A:D,4,0),"0")/CONCILIÇÃO_COM_CERVEJA!$G5 -> 991 | P5: =J5-M5 -> -7847.67 | Q5: =CONCILIÇÃO_COM_CERVEJA!$P5-CONCILIÇÃO_COM_CERVEJA!$O5 -> -8838.67 | R5: =IFERROR(VLOOKUP(CONCILIÇÃO_COM_CERVEJA!$B5,CUSTO!E:H,4,0),(VLOOKUP(CONCILIÇÃO_COM_CERVEJA!$A5,CUSTO!A:H,8,0))) -> 2.3577545 | S5: =IFERROR(SUM(CONCILIÇÃO_COM_CERVEJA!$P5*CONCILIÇÃO_COM_CERVEJA!$R5),0) -> -18502.879 | T5: =IFERROR(#REF!/CONCILIÇÃO_COM_CERVEJA!$M5,"") | U5: =IFERROR(#REF!*CONCILIÇÃO_COM_CERVEJA!$R5,"-") -> - | V5: VERIFICAR
A6: 31395 | B6: 2701170002 | C6: - | D6: ETANOL NEUTRO ALCOOL ETILICO POTAVEL 96° | E6: =IFERROR(VLOOKUP(B6,[1]AGLUTINADO!$A:$C,3,0),0)/G6 -> 67132.062 | F6: ALCOOL | G6: 1 | H6: =VLOOKUP(CONCILIÇÃO_COM_CERVEJA!$B6,CONT_ANTE!A:D,4,0) -> 41958 | I6: =IF(AND(E6=0,H6<>J6),"!@##@!","ok") -> ok | J6: 52674 | K6: =SUMIF(SISTEMA!B:B,CONCILIÇÃO_COM_CERVEJA!$B6,SISTEMA!I:I)/G6 -> 65761 | L6: =SUMIF(SISTEMA!B:B,CONCILIÇÃO_COM_CERVEJA!$C6,SISTEMA!I:I) -> 0 | M6: =K6+L6 -> 65761 | N6: =IFERROR(SUM(CONCILIÇÃO_COM_CERVEJA!$M6*CONCILIÇÃO_COM_CERVEJA!$R6),0) -> 252294.82 | O6: =IFERROR(VLOOKUP(CONCILIÇÃO_COM_CERVEJA!$B6,DIF_ANTE!A:D,4,0),"0")/CONCILIÇÃO_COM_CERVEJA!$G6 -> 428.93839 | P6: =J6-M6 -> -13087 | Q6: =CONCILIÇÃO_COM_CERVEJA!$P6-CONCILIÇÃO_COM_CERVEJA!$O6 -> -13515.938 | R6: =IFERROR(VLOOKUP(CONCILIÇÃO_COM_CERVEJA!$B6,CUSTO!E:H,4,0),(VLOOKUP(CONCILIÇÃO_COM_CERVEJA!$A6,CUSTO!A:H,8,0))) -> 3.8365417 | S6: =IFERROR(SUM(CONCILIÇÃO_COM_CERVEJA!$P6*CONCILIÇÃO_COM_CERVEJA!$R6),0) -> -50208.822 | T6: =IFERROR(#REF!/CONCILIÇÃO_COM_CERVEJA!$M6,"") | U6: =IFERROR(#REF!*CONCILIÇÃO_COM_CERVEJA!$R6,"-") -> - | V6: ok
A7: 31352 | B7: 2701050004 | C7: - | D7: AROMA ARTIFICIAL ENERGY SYMRISE | E7: =IFERROR(VLOOKUP(B7,[1]AGLUTINADO!$A:$C,3,0),0)/G7 -> 0 | F7: AROMA | G7: 1 | H7: =VLOOKUP(CONCILIÇÃO_COM_CERVEJA!$B7,CONT_ANTE!A:D,4,0) -> 0 | I7: =IF(AND(E7=0,H7<>J7),"!@##@!","ok") -> ok | J7: =VLOOKUP(CONCILIÇÃO_COM_CERVEJA!$B7,CONTAGEM!B:G,6,0) -> 0 | K7: =SUMIF(SISTEMA!B:B,CONCILIÇÃO_COM_CERVEJA!$B7,SISTEMA!I:I)/G7 -> 0 | L7: =SUMIF(SISTEMA!B:B,CONCILIÇÃO_COM_CERVEJA!$C7,SISTEMA!I:I) -> 0 | M7: =K7+L7 -> 0 | N7: =IFERROR(SUM(CONCILIÇÃO_COM_CERVEJA!$M7*CONCILIÇÃO_COM_CERVEJA!$R7),0) -> 0 | O7: =IFERROR(VLOOKUP(CONCILIÇÃO_COM_CERVEJA!$B7,DIF_ANTE!A:D,4,0),"0")/CONCILIÇÃO_COM_CERVEJA!$G7 -> 0 | P7: =J7-M7 -> 0 | Q7: =CONCILIÇÃO_COM_CERVEJA!$P7-CONCILIÇÃO_COM_CERVEJA!$O7 -> 0 | R7: =IFERROR(VLOOKUP(CONCILIÇÃO_COM_CERVEJA!$B7,CUSTO!E:H,4,0),(VLOOKUP(CONCILIÇÃO_COM_CERVEJA!$A7,CUSTO!A:H,8,0))) -> 103.63169 | S7: =IFERROR(SUM(CONCILIÇÃO_COM_CERVEJA!$P7*CONCILIÇÃO_COM_CERVEJA!$R7),0) -> 0 | T7: =IFERROR(#REF!/CONCILIÇÃO_COM_CERVEJA!$M7,"") | U7: =IFERROR(#REF!*CONCILIÇÃO_COM_CERVEJA!$R7,"-") -> - | V7: OK
A8: 31335 | B8: 2701050008 | C8: - | D8: AROMA ARTIFICIAL FRUTAS TROPICAIS MONARCH | E8: =IFERROR(VLOOKUP(B8,[1]AGLUTINADO!$A:$C,3,0),0)/G8 -> 92.35 | F8: AROMA | G8: 1 | H8: =VLOOKUP(CONCILIÇÃO_COM_CERVEJA!$B8,CONT_ANTE!A:D,4,0) -> 331 | I8: =IF(AND(E8=0,H8<>J8),"!@##@!","ok") -> ok | J8: =VLOOKUP(CONCILIÇÃO_COM_CERVEJA!$B8,CONTAGEM!B:G,6,0) -> 240 | K8: =SUMIF(SISTEMA!B:B,CONCILIÇÃO_COM_CERVEJA!$B8,SISTEMA!I:I)/G8 -> 241.65 | L8: =SUMIF(SISTEMA!B:B,CONCILIÇÃO_COM_CERVEJA!$C8,SISTEMA!I:I) -> 0 | M8: =K8+L8 -> 241.65 | N8: =IFERROR(SUM(CONCILIÇÃO_COM_CERVEJA!$M8*CONCILIÇÃO_COM_CERVEJA!$R8),0) -> 30803.162 | O8: =IFERROR(VLOOKUP(CONCILIÇÃO_COM_CERVEJA!$B8,DIF_ANTE!A:D,4,0),"0")/CONCILIÇÃO_COM_CERVEJA!$G8 -> -3 | P8: =J8-M8 -> -1.65 | Q8: =CONCILIÇÃO_COM_CERVEJA!$P8-CONCILIÇÃO_COM_CERVEJA!$O8 -> 1.35 | R8: =IFERROR(VLOOKUP(CONCILIÇÃO_COM_CERVEJA!$B8,CUSTO!E:H,4,0),(VLOOKUP(CONCILIÇÃO_COM_CERVEJA!$A8,CUSTO!A:H,8,0))) -> 127.47015 | S8: =IFERROR(SUM(CONCILIÇÃO_COM_CERVEJA!$P8*CONCILIÇÃO_COM_CERVEJA!$R8),0) -> -210.32575 | T8: =IFERROR(#REF!/CONCILIÇÃO_COM_CERVEJA!$M8,"") | U8: =IFERROR(#REF!*CONCILIÇÃO_COM_CERVEJA!$R8,"-") -> - | V8: ok
A9: 31351 | B9: 2701050009 | C9: - | D9: AROMA ARTIFICIAL GUARANA DUAS RODAS | E9: =IFERROR(VLOOKUP(B9,[1]AGLUTINADO!$A:$C,3,0),0)/G9 -> 0 | F9: AROMA | G9: 1 | H9: =VLOOKUP(CONCILIÇÃO_COM_CERVEJA!$B9,CONT_ANTE!A:D,4,0) -> 0 | I9: =IF(AND(E9=0,H9<>J9),"!@##@!","ok") -> ok | J9: =VLOOKUP(CONCILIÇÃO_COM_CERVEJA!$B9,CONTAGEM!B:G,6,0) -> 0 | K9: =SUMIF(SISTEMA!B:B,CONCILIÇÃO_COM_CERVEJA!$B9,SISTEMA!I:I)/G9 -> 0 | L9: =SUMIF(SISTEMA!B:B,CONCILIÇÃO_COM_CERVEJA!$C9,SISTEMA!I:I) -> 0 | M9: =K9+L9 -> 0 | N9: =IFERROR(SUM(CONCILIÇÃO_COM_CERVEJA!$M9*CONCILIÇÃO_COM_CERVEJA!$R9),0) -> 0 | O9: =IFERROR(VLOOKUP(CONCILIÇÃO_COM_CERVEJA!$B9,DIF_ANTE!A:D,4,0),"0")/CONCILIÇÃO_COM_CERVEJA!$G9 -> 0 | P9: =J9-M9 -> 0 | Q9: =CONCILIÇÃO_COM_CERVEJA!$P9-CONCILIÇÃO_COM_CERVEJA!$O9 -> 0 | R9: =IFERROR(VLOOKUP(CONCILIÇÃO_COM_CERVEJA!$B9,CUSTO!E:H,4,0),(VLOOKUP(CONCILIÇÃO_COM_CERVEJA!$A9,CUSTO!A:H,8,0))) -> 49.614813 | S9: =IFERROR(SUM(CONCILIÇÃO_COM_CERVEJA!$P9*CONCILIÇÃO_COM_CERVEJA!$R9),0) -> 0 | T9: =IFERROR(#REF!/CONCILIÇÃO_COM_CERVEJA!$M9,"") | U9: =IFERROR(#REF!*CONCILIÇÃO_COM_CERVEJA!$R9,"-") -> - | V9: OK
B10: 2701050035 | C10: - | D10: AROMA ARTIFICIAL GUARANA IFB | E10: =IFERROR(VLOOKUP(B10,[1]AGLUTINADO!$A:$C,3,0),0)/G10 -> 151.03 | F10: AROMA | G10: 1 | H10: =VLOOKUP(CONCILIÇÃO_COM_CERVEJA!$B10,CONT_ANTE!A:D,4,0) -> 952 | I10: =IF(AND(E10=0,H10<>J10),"!@##@!","ok") -> ok | J10: =VLOOKUP(CONCILIÇÃO_COM_CERVEJA!$B10,CONTAGEM!B:G,6,0) -> 797 | K10: =SUMIF(SISTEMA!B:B,CONCILIÇÃO_COM_CERVEJA!$B10,SISTEMA!I:I)/G10 -> 812.43 | L10: =SUMIF(SISTEMA!B:B,CONCILIÇÃO_COM_CERVEJA!$C10,SISTEMA!I:I) -> 0 | M10: =K10+L10 -> 812.43 | N10: =IFERROR(SUM(CONCILIÇÃO_COM_CERVEJA!$M10*CONCILIÇÃO_COM_CERVEJA!$R10),0) -> 30612.362 | O10: =IFERROR(VLOOKUP(CONCILIÇÃO_COM_CERVEJA!$B10,DIF_ANTE!A:D,4,0),"0")/CONCILIÇÃO_COM_CERVEJA!$G10 -> -11.46 | P10: =J10-M10 -> -15.43 | Q10: =CONCILIÇÃO_COM_CERVEJA!$P10-CONCILIÇÃO_COM_CERVEJA!$O10 -> -3.97 | R10: =IFERROR(VLOOKUP(CONCILIÇÃO_COM_CERVEJA!$B10,CUSTO!E:H,4,0),(VLOOKUP(CONCILIÇÃO_COM_CERVEJA!$A10,CUSTO!A:H,8,0))) -> 37.68 | S10: =IFERROR(SUM(CONCILIÇÃO_COM_CERVEJA!$P10*CONCILIÇÃO_COM_CERVEJA!$R10),0) -> -581.4024 | T10: =IFERROR(#REF!/CONCILIÇÃO_COM_CERVEJA!$M10,"") | U10: =IFERROR(#REF!*CONCILIÇÃO_COM_CERVEJA!$R10,"-") -> -
A11: 31349 | B11: 2701050017 | C11: - | D11: AROMA ARTIFICIAL MELANCIA DUAS RODAS | E11: =IFERROR(VLOOKUP(B11,[1]AGLUTINADO!$A:$C,3,0),0)/G11 -> 69.71 | F11: AROMA | G11: 1 | H11: =VLOOKUP(CONCILIÇÃO_COM_CERVEJA!$B11,CONT_ANTE!A:D,4,0) -> 159 | I11: =IF(AND(E11=0,H11<>J11),"!@##@!","ok") -> ok | J11: =VLOOKUP(CONCILIÇÃO_COM_CERVEJA!$B11,CONTAGEM!B:G,6,0) -> 184 | K11: =SUMIF(SISTEMA!B:B,CONCILIÇÃO_COM_CERVEJA!$B11,SISTEMA!I:I)/G11 -> 204.1 | L11: =SUMIF(SISTEMA!B:B,CONCILIÇÃO_COM_CERVEJA!$C11,SISTEMA!I:I) -> 0 | M11: =K11+L11 -> 204.1 | N11: =IFERROR(SUM(CONCILIÇÃO_COM_CERVEJA!$M11*CONCILIÇÃO_COM_CERVEJA!$R11),0) -> 6403.0742 | O11: =IFERROR(VLOOKUP(CONCILIÇÃO_COM_CERVEJA!$B11,DIF_ANTE!A:D,4,0),"0")/CONCILIÇÃO_COM_CERVEJA!$G11 -> -14.81 | P11: =J11-M11 -> -20.1 | Q11: =CONCILIÇÃO_COM_CERVEJA!$P11-CONCILIÇÃO_COM_CERVEJA!$O11 -> -5.29 | R11: =IFERROR(VLOOKUP(CONCILIÇÃO_COM_CERVEJA!$B11,CUSTO!E:H,4,0),(VLOOKUP(CONCILIÇÃO_COM_CERVEJA!$A11,CUSTO!A:H,8,0))) -> 31.37224 | S11: =IFERROR(SUM(CONCILIÇÃO_COM_CERVEJA!$P11*CONCILIÇÃO_COM_CERVEJA!$R11),0) -> -630.58202 | T11: =IFERROR(#REF!/CONCILIÇÃO_COM_CERVEJA!$M11,"") | U11: =IFERROR(#REF!*CONCILIÇÃO_COM_CERVEJA!$R11,"-") -> -
A12: 31354 | B12: 2701050006 | C12: - | D12: AROMA IDENTICO AO NATURAL BLUEBERRY KALABROS | E12: =IFERROR(VLOOKUP(B12,[1]AGLUTINADO!$A:$C,3,0),0)/G12 -> 0 | F12: AROMA | G12: 1 | H12: =VLOOKUP(CONCILIÇÃO_COM_CERVEJA!$B12,CONT_ANTE!A:D,4,0) -> 0 | I12: =IF(AND(E12=0,H12<>J12),"!@##@!","ok") -> ok | J12: =VLOOKUP(CONCILIÇÃO_COM_CERVEJA!$B12,CONTAGEM!B:G,6,0) -> 0 | K12: =SUMIF(SISTEMA!B:B,CONCILIÇÃO_COM_CERVEJA!$B12,SISTEMA!I:I)/G12 -> 0 | L12: =SUMIF(SISTEMA!B:B,CONCILIÇÃO_COM_CERVEJA!$C12,SISTEMA!I:I) -> 0 | M12: =K12+L12 -> 0 | N12: =IFERROR(SUM(CONCILIÇÃO_COM_CERVEJA!$M12*CONCILIÇÃO_COM_CERVEJA!$R12),0) -> 0 | O12: =IFERROR(VLOOKUP(CONCILIÇÃO_COM_CERVEJA!$B12,DIF_ANTE!A:D,4,0),"0")/CONCILIÇÃO_COM_CERVEJA!$G12 -> 0 | P12: =J12-M12 -> 0 | Q12: =CONCILIÇÃO_COM_CERVEJA!$P12-CONCILIÇÃO_COM_CERVEJA!$O12 -> 0 | R12: =IFERROR(VLOOKUP(CONCILIÇÃO_COM_CERVEJA!$B12,CUSTO!E:H,4,0),(VLOOKUP(CONCILIÇÃO_COM_CERVEJA!$A12,CUSTO!A:H,8,0))) -> 45.981938 | S12: =IFERROR(SUM(CONCILIÇÃO_COM_CERVEJA!$P12*CONCILIÇÃO_COM_CERVEJA!$R12),0) -> 0 | T12: =IFERROR(#REF!/CONCILIÇÃO_COM_CERVEJA!$M12,"") | U12: =IFERROR(#REF!*CONCILIÇÃO_COM_CERVEJA!$R12,"-") -> - | V12: OK
B13: 2701050029 | C13: - | D13: AROMA IDENTICO AO NATURAL CLOUDING LEMON | E13: =IFERROR(VLOOKUP(B13,[1]AGLUTINADO!$A:$C,3,0),0)/G13 -> 0 | F13: AROMA | G13: 1 | H13: =VLOOKUP(CONCILIÇÃO_COM_CERVEJA!$B13,CONT_ANTE!A:D,4,0) -> 0 | I13: =IF(AND(E13=0,H13<>J13),"!@##@!","ok") -> ok | J13: =VLOOKUP(CONCILIÇÃO_COM_CERVEJA!$B13,CONTAGEM!B:G,6,0) -> 0 | K13: =SUMIF(SISTEMA!B:B,CONCILIÇÃO_COM_CERVEJA!$B13,SISTEMA!I:I)/G13 -> 0 | L13: =SUMIF(SISTEMA!B:B,CONCILIÇÃO_COM_CERVEJA!$C13,SISTEMA!I:I) -> 0 | M13: =K13+L13 -> 0 | N13: =IFERROR(SUM(CONCILIÇÃO_COM_CERVEJA!$M13*CONCILIÇÃO_COM_CERVEJA!$R13),0) -> 0 | O13: =IFERROR(VLOOKUP(CONCILIÇÃO_COM_CERVEJA!$B13,DIF_ANTE!A:D,4,0),"0")/CONCILIÇÃO_COM_CERVEJA!$G13 -> 0 | P13: =J13-M13 -> 0 | Q13: =CONCILIÇÃO_COM_CERVEJA!$P13-CONCILIÇÃO_COM_CERVEJA!$O13 -> 0 | R13: =IFERROR(VLOOKUP(CONCILIÇÃO_COM_CERVEJA!$B13,CUSTO!E:H,4,0),(VLOOKUP(CONCILIÇÃO_COM_CERVEJA!$A13,CUSTO!A:H,8,0))) -> 0.11037425 | S13: =IFERROR(SUM(CONCILIÇÃO_COM_CERVEJA!$P13*CONCILIÇÃO_COM_CERVEJA!$R13),0) -> 0 | T13: =IFERROR(#REF!/CONCILIÇÃO_COM_CERVEJA!$M13,"") | U13: =IFERROR(#REF!*CONCILIÇÃO_COM_CERVEJA!$R13,"-") -> - | V13: ok
A14: 1820 | B14: 2701050010 | C14: - | D14: AROMA IDENTICO AO NATURAL DE LARANJA | E14: =IFERROR(VLOOKUP(B14,[1]AGLUTINADO!$A:$C,3,0),0)/G14 -> 1.08 | F14: AROMA | G14: 1 | H14: =VLOOKUP(CONCILIÇÃO_COM_CERVEJA!$B14,CONT_ANTE!A:D,4,0) -> 15.5 | I14: =IF(AND(E14=0,H14<>J14),"!@##@!","ok") -> ok | J14: =VLOOKUP(CONCILIÇÃO_COM_CERVEJA!$B14,CONTAGEM!B:G,6,0) -> 14.5 | K14: =SUMIF(SISTEMA!B:B,CONCILIÇÃO_COM_CERVEJA!$B14,SISTEMA!I:I)/G14 -> 15.31 | L14: =SUMIF(SISTEMA!B:B,CONCILIÇÃO_COM_CERVEJA!$C14,SISTEMA!I:I) -> 0 | M14: =K14+L14 -> 15.31 | N14: =IFERROR(SUM(CONCILIÇÃO_COM_CERVEJA!$M14*CONCILIÇÃO_COM_CERVEJA!$R14),0) -> 919.68871 | O14: =IFERROR(VLOOKUP(CONCILIÇÃO_COM_CERVEJA!$B14,DIF_ANTE!A:D,4,0),"0")/CONCILIÇÃO_COM_CERVEJA!$G14 -> -0.89 | P14: =J14-M14 -> -0.81 | Q14: =CONCILIÇÃO_COM_CERVEJA!$P14-CONCILIÇÃO_COM_CERVEJA!$O14 -> 0.08 | R14: =IFERROR(VLOOKUP(CONCILIÇÃO_COM_CERVEJA!$B14,CUSTO!E:H,4,0),(VLOOKUP(CONCILIÇÃO_COM_CERVEJA!$A14,CUSTO!A:H,8,0))) -> 60.071111 | S14: =IFERROR(SUM(CONCILIÇÃO_COM_CERVEJA!$P14*CONCILIÇÃO_COM_CERVEJA!$R14),0) -> -48.6576 | T14: =IFERROR(#REF!/CONCILIÇÃO_COM_CERVEJA!$M14,"") | U14: =IFERROR(#REF!*CONCILIÇÃO_COM_CERVEJA!$R14,"-") -> -
A15: 43 | B15: 2701050011 | C15: - | D15: AROMA IDENTICO AO NATURAL DE LIMAO 41 SAPORITI | E15: =IFERROR(VLOOKUP(B15,[1]AGLUTINADO!$A:$C,3,0),0)/G15 -> 14.36 | F15: AROMA | G15: 1 | H15: =VLOOKUP(CONCILIÇÃO_COM_CERVEJA!$B15,CONT_ANTE!A:D,4,0) -> 6 | I15: =IF(AND(E15=0,H15<>J15),"!@##@!","ok") -> ok | J15: =VLOOKUP(CONCILIÇÃO_COM_CERVEJA!$B15,CONTAGEM!B:G,6,0) -> 61.5 | K15: =SUMIF(SISTEMA!B:B,CONCILIÇÃO_COM_CERVEJA!$B15,SISTEMA!I:I)/G15 -> 77.91 | L15: =SUMIF(SISTEMA!B:B,CONCILIÇÃO_COM_CERVEJA!$C15,SISTEMA!I:I) -> 0 | M15: =K15+L15 -> 77.91 | N15: =IFERROR(SUM(CONCILIÇÃO_COM_CERVEJA!$M15*CONCILIÇÃO_COM_CERVEJA!$R15),0) -> 3156.199 | O15: =IFERROR(VLOOKUP(CONCILIÇÃO_COM_CERVEJA!$B15,DIF_ANTE!A:D,4,0),"0")/CONCILIÇÃO_COM_CERVEJA!$G15 -> -14.27 | P15: =J15-M15 -> -16.41 | Q15: =CONCILIÇÃO_COM_CERVEJA!$P15-CONCILIÇÃO_COM_CERVEJA!$O15 -> -2.14 | R15: =IFERROR(VLOOKUP(CONCILIÇÃO_COM_CERVEJA!$B15,CUSTO!E:H,4,0),(VLOOKUP(CONCILIÇÃO_COM_CERVEJA!$A15,CUSTO!A:H,8,0))) -> 40.510833 | S15: =IFERROR(SUM(CONCILIÇÃO_COM_CERVEJA!$P15*CONCILIÇÃO_COM_CERVEJA!$R15),0) -> -664.78277 | T15: =IFERROR(#REF!/CONCILIÇÃO_COM_CERVEJA!$M15,"") | U15: =IFERROR(#REF!*CONCILIÇÃO_COM_CERVEJA!$R15,"-") -> -
A16: 41 | B16: 2701050027 | C16: - | D16: AROMA IDENTICO AO NATURAL DE UVA SAPORITI | E16: =IFERROR(VLOOKUP(B16,[1]AGLUTINADO!$A:$C,3,0),0)/G16 -> 119.35 | F16: AROMA | G16: 1 | H16: =VLOOKUP(CONCILIÇÃO_COM_CERVEJA!$B16,CONT_ANTE!A:D,4,0) -> 129.5 | I16: =IF(AND(E16=0,H16<>J16),"!@##@!","ok") -> ok | J16: =VLOOKUP(CONCILIÇÃO_COM_CERVEJA!$B16,CONTAGEM!B:G,6,0) -> 113 | K16: =SUMIF(SISTEMA!B:B,CONCILIÇÃO_COM_CERVEJA!$B16,SISTEMA!I:I)/G16 -> 123.51 | L16: =SUMIF(SISTEMA!B:B,CONCILIÇÃO_COM_CERVEJA!$C16,SISTEMA!I:I) -> 0 | M16: =K16+L16 -> 123.51 | N16: =IFERROR(SUM(CONCILIÇÃO_COM_CERVEJA!$M16*CONCILIÇÃO_COM_CERVEJA!$R16),0) -> 3048.1562 | O16: =IFERROR(VLOOKUP(CONCILIÇÃO_COM_CERVEJA!$B16,DIF_ANTE!A:D,4,0),"0")/CONCILIÇÃO_COM_CERVEJA!$G16 -> -8.36 | P16: =J16-M16 -> -10.51 | Q16: =CONCILIÇÃO_COM_CERVEJA!$P16-CONCILIÇÃO_COM_CERVEJA!$O16 -> -2.15 | R16: =IFERROR(VLOOKUP(CONCILIÇÃO_COM_CERVEJA!$B16,CUSTO!E:H,4,0),(VLOOKUP(CONCILIÇÃO_COM_CERVEJA!$A16,CUSTO!A:H,8,0))) -> 24.679429 | S16: =IFERROR(SUM(CONCILIÇÃO_COM_CERVEJA!$P16*CONCILIÇÃO_COM_CERVEJA!$R16),0) -> -259.38079 | T16: =IFERROR(#REF!/CONCILIÇÃO_COM_CERVEJA!$M16,"") | U16: =IFERROR(#REF!*CONCILIÇÃO_COM_CERVEJA!$R16,"-") -> -
B17: 2701050033 | C17: - | D17: AROMA IDENTICO AO NATURAL DE UVA VERDE SAPORITI | E17: =IFERROR(VLOOKUP(B17,[1]AGLUTINADO!$A:$C,3,0),0)/G17 -> 16.36 | F17: AROMA | G17: 1 | H17: =VLOOKUP(CONCILIÇÃO_COM_CERVEJA!$B17,CONT_ANTE!A:D,4,0) -> 147 | I17: =IF(AND(E17=0,H17<>J17),"!@##@!","ok") -> ok | J17: =VLOOKUP(CONCILIÇÃO_COM_CERVEJA!$B17,CONTAGEM!B:G,6,0) -> 129.5 | K17: =SUMIF(SISTEMA!B:B,CONCILIÇÃO_COM_CERVEJA!$B17,SISTEMA!I:I)/G17 -> 135.28 | L17: =SUMIF(SISTEMA!B:B,CONCILIÇÃO_COM_CERVEJA!$C17,SISTEMA!I:I) -> 0 | M17: =K17+L17 -> 135.28 | N17: =IFERROR(SUM(CONCILIÇÃO_COM_CERVEJA!$M17*CONCILIÇÃO_COM_CERVEJA!$R17),0) -> 12674.195 | O17: =IFERROR(VLOOKUP(CONCILIÇÃO_COM_CERVEJA!$B17,DIF_ANTE!A:D,4,0),"0")/CONCILIÇÃO_COM_CERVEJA!$G17 -> -4.64 | P17: =J17-M17 -> -5.78 | Q17: =CONCILIÇÃO_COM_CERVEJA!$P17-CONCILIÇÃO_COM_CERVEJA!$O17 -> -1.14 | R17: =IFERROR(VLOOKUP(CONCILIÇÃO_COM_CERVEJA!$B17,CUSTO!E:H,4,0),(VLOOKUP(CONCILIÇÃO_COM_CERVEJA!$A17,CUSTO!A:H,8,0))) -> 93.688611 | S17: =IFERROR(SUM(CONCILIÇÃO_COM_CERVEJA!$P17*CONCILIÇÃO_COM_CERVEJA!$R17),0) -> -541.52017 | T17: =IFERROR(#REF!/CONCILIÇÃO_COM_CERVEJA!$M17,"") | U17: =IFERROR(#REF!*CONCILIÇÃO_COM_CERVEJA!$R17,"-") -> -
A18: 31337 | B18: 2701050013 | C18: - | D18: AROMA IDENTICO AO NATURAL MACA VERDE DUAS RODAS | E18: =IFERROR(VLOOKUP(B18,[1]AGLUTINADO!$A:$C,3,0),0)/G18 -> 51.848 | F18: AROMA | G18: 1 | H18: =VLOOKUP(CONCILIÇÃO_COM_CERVEJA!$B18,CONT_ANTE!A:D,4,0) -> 68 | I18: =IF(AND(E18=0,H18<>J18),"!@##@!","ok") -> ok | J18: =VLOOKUP(CONCILIÇÃO_COM_CERVEJA!$B18,CONTAGEM!B:G,6,0) -> 98 | K18: =SUMIF(SISTEMA!B:B,CONCILIÇÃO_COM_CERVEJA!$B18,SISTEMA!I:I)/G18 -> 104.392 | L18: =SUMIF(SISTEMA!B:B,CONCILIÇÃO_COM_CERVEJA!$C18,SISTEMA!I:I) -> 0 | M18: =K18+L18 -> 104.392 | N18: =IFERROR(SUM(CONCILIÇÃO_COM_CERVEJA!$M18*CONCILIÇÃO_COM_CERVEJA!$R18),0) -> 4092.1323 | O18: =IFERROR(VLOOKUP(CONCILIÇÃO_COM_CERVEJA!$B18,DIF_ANTE!A:D,4,0),"0")/CONCILIÇÃO_COM_CERVEJA!$G18 -> -3.24 | P18: =J18-M18 -> -6.392 | Q18: =CONCILIÇÃO_COM_CERVEJA!$P18-CONCILIÇÃO_COM_CERVEJA!$O18 -> -3.152 | R18: =IFERROR(VLOOKUP(CONCILIÇÃO_COM_CERVEJA!$B18,CUSTO!E:H,4,0),(VLOOKUP(CONCILIÇÃO_COM_CERVEJA!$A18,CUSTO!A:H,8,0))) -> 39.199673 | S18: =IFERROR(SUM(CONCILIÇÃO_COM_CERVEJA!$P18*CONCILIÇÃO_COM_CERVEJA!$R18),0) -> -250.56431 | T18: =IFERROR(#REF!/CONCILIÇÃO_COM_CERVEJA!$M18,"") | U18: =IFERROR(#REF!*CONCILIÇÃO_COM_CERVEJA!$R18,"-") -> -
A19: 31786 | B19: 2701050014 | C19: - | D19: AROMA IDENTICO AO NATURAL MANGA HS 25409 SAPORITI | E19: =IFERROR(VLOOKUP(B19,[1]AGLUTINADO!$A:$C,3,0),0)/G19 -> 0 | F19: AROMA | G19: 1 | H19: =VLOOKUP(CONCILIÇÃO_COM_CERVEJA!$B19,CONT_ANTE!A:D,4,0) -> 0 | I19: =IF(AND(E19=0,H19<>J19),"!@##@!","ok") -> ok | J19: =VLOOKUP(CONCILIÇÃO_COM_CERVEJA!$B19,CONTAGEM!B:G,6,0) -> 0 | K19: =SUMIF(SISTEMA!B:B,CONCILIÇÃO_COM_CERVEJA!$B19,SISTEMA!I:I)/G19 -> 0 | L19: =SUMIF(SISTEMA!B:B,CONCILIÇÃO_COM_CERVEJA!$C19,SISTEMA!I:I) -> 0 | M19: =K19+L19 -> 0 | N19: =IFERROR(SUM(CONCILIÇÃO_COM_CERVEJA!$M19*CONCILIÇÃO_COM_CERVEJA!$R19),0) -> 0 | O19: =IFERROR(VLOOKUP(CONCILIÇÃO_COM_CERVEJA!$B19,DIF_ANTE!A:D,4,0),"0")/CONCILIÇÃO_COM_CERVEJA!$G19 -> 0 | P19: =J19-M19 -> 0 | Q19: =CONCILIÇÃO_COM_CERVEJA!$P19-CONCILIÇÃO_COM_CERVEJA!$O19 -> 0 | R19: =IFERROR(VLOOKUP(CONCILIÇÃO_COM_CERVEJA!$B19,CUSTO!E:H,4,0),(VLOOKUP(CONCILIÇÃO_COM_CERVEJA!$A19,CUSTO!A:H,8,0))) -> 44.0552 | S19: =IFERROR(SUM(CONCILIÇÃO_COM_CERVEJA!$P19*CONCILIÇÃO_COM_CERVEJA!$R19),0) -> 0 | T19: =IFERROR(#REF!/CONCILIÇÃO_COM_CERVEJA!$M19,"") | U19: =IFERROR(#REF!*CONCILIÇÃO_COM_CERVEJA!$R19,"-") -> - | V19: OK
A20: 31348 | B20: 2701050015 | C20: - | D20: AROMA IDENTICO AO NATURAL MARACUJA DUAS RODAS | E20: =IFERROR(VLOOKUP(B20,[1]AGLUTINADO!$A:$C,3,0),0)/G20 -> 0 | F20: AROMA | G20: 1 | H20: =VLOOKUP(CONCILIÇÃO_COM_CERVEJA!$B20,CONT_ANTE!A:D,4,0) -> 0 | I20: =IF(AND(E20=0,H20<>J20),"!@##@!","ok") -> ok | J20: =VLOOKUP(CONCILIÇÃO_COM_CERVEJA!$B20,CONTAGEM!B:G,6,0) -> 0 | K20: =SUMIF(SISTEMA!B:B,CONCILIÇÃO_COM_CERVEJA!$B20,SISTEMA!I:I)/G20 -> 0.535 | L20: =SUMIF(SISTEMA!B:B,CONCILIÇÃO_COM_CERVEJA!$C20,SISTEMA!I:I) -> 0 | M20: =K20+L20 -> 0.535 | N20: =IFERROR(SUM(CONCILIÇÃO_COM_CERVEJA!$M20*CONCILIÇÃO_COM_CERVEJA!$R20),0) -> 24.475448 | O20: =IFERROR(VLOOKUP(CONCILIÇÃO_COM_CERVEJA!$B20,DIF_ANTE!A:D,4,0),"0")/CONCILIÇÃO_COM_CERVEJA!$G20 -> -0.535 | P20: =J20-M20 -> -0.535 | Q20: =CONCILIÇÃO_COM_CERVEJA!$P20-CONCILIÇÃO_COM_CERVEJA!$O20 -> 0 | R20: =IFERROR(VLOOKUP(CONCILIÇÃO_COM_CERVEJA!$B20,CUSTO!E:H,4,0),(VLOOKUP(CONCILIÇÃO_COM_CERVEJA!$A20,CUSTO!A:H,8,0))) -> 45.7485 | S20: =IFERROR(SUM(CONCILIÇÃO_COM_CERVEJA!$P20*CONCILIÇÃO_COM_CERVEJA!$R20),0) -> -24.475448 | T20: =IFERROR(#REF!/CONCILIÇÃO_COM_CERVEJA!$M20,"") | U20: =IFERROR(#REF!*CONCILIÇÃO_COM_CERVEJA!$R20,"-") -> - | V20: OK
A21: 31336 | B21: 2701050019 | C21: - | D21: AROMA IDENTICO AO NATURAL MELAO DUAS RODAS | E21: =IFERROR(VLOOKUP(B21,[1]AGLUTINADO!$A:$C,3,0),0)/G21 -> 116.3 | F21: AROMA | G21: 1 | H21: =VLOOKUP(CONCILIÇÃO_COM_CERVEJA!$B21,CONT_ANTE!A:D,4,0) -> 188.5 | I21: =IF(AND(E21=0,H21<>J21),"!@##@!","ok") -> ok | J21: =VLOOKUP(CONCILIÇÃO_COM_CERVEJA!$B21,CONTAGEM!B:G,6,0) -> 325 | K21: =SUMIF(SISTEMA!B:B,CONCILIÇÃO_COM_CERVEJA!$B21,SISTEMA!I:I)/G21 -> 353.7704 | L21: =SUMIF(SISTEMA!B:B,CONCILIÇÃO_COM_CERVEJA!$C21,SISTEMA!I:I) -> 0 | M21: =K21+L21 -> 353.7704 | N21: =IFERROR(SUM(CONCILIÇÃO_COM_CERVEJA!$M21*CONCILIÇÃO_COM_CERVEJA!$R21),0) -> 17607.93 | O21: =IFERROR(VLOOKUP(CONCILIÇÃO_COM_CERVEJA!$B21,DIF_ANTE!A:D,4,0),"0")/CONCILIÇÃO_COM_CERVEJA!$G21 -> -26.5704 | P21: =J21-M21 -> -28.7704 | Q21: =CONCILIÇÃO_COM_CERVEJA!$P21-CONCILIÇÃO_COM_CERVEJA!$O21 -> -2.2 | R21: =IFERROR(VLOOKUP(CONCILIÇÃO_COM_CERVEJA!$B21,CUSTO!E:H,4,0),(VLOOKUP(CONCILIÇÃO_COM_CERVEJA!$A21,CUSTO!A:H,8,0))) -> 49.772196 | S21: =IFERROR(SUM(CONCILIÇÃO_COM_CERVEJA!$P21*CONCILIÇÃO_COM_CERVEJA!$R21),0) -> -1431.966 | T21: =IFERROR(#REF!/CONCILIÇÃO_COM_CERVEJA!$M21,"") | U21: =IFERROR(#REF!*CONCILIÇÃO_COM_CERVEJA!$R21,"-") -> -
A22: 31350 | B22: 2701050021 | C22: - | D22: AROMA IDENTICO AO NATURAL MORANGO DUAS RODAS | E22: =IFERROR(VLOOKUP(B22,[1]AGLUTINADO!$A:$C,3,0),0)/G22 -> 39.05 | F22: AROMA | G22: 1 | H22: =VLOOKUP(CONCILIÇÃO_COM_CERVEJA!$B22,CONT_ANTE!A:D,4,0) -> 110 | I22: =IF(AND(E22=0,H22<>J22),"!@##@!","ok") -> ok | J22: =VLOOKUP(CONCILIÇÃO_COM_CERVEJA!$B22,CONTAGEM!B:G,6,0) -> 121 | K22: =SUMIF(SISTEMA!B:B,CONCILIÇÃO_COM_CERVEJA!$B22,SISTEMA!I:I)/G22 -> 117.23 | L22: =SUMIF(SISTEMA!B:B,CONCILIÇÃO_COM_CERVEJA!$C22,SISTEMA!I:I) -> 0 | M22: =K22+L22 -> 117.23 | N22: =IFERROR(SUM(CONCILIÇÃO_COM_CERVEJA!$M22*CONCILIÇÃO_COM_CERVEJA!$R22),0) -> 7507.8957 | O22: =IFERROR(VLOOKUP(CONCILIÇÃO_COM_CERVEJA!$B22,DIF_ANTE!A:D,4,0),"0")/CONCILIÇÃO_COM_CERVEJA!$G22 -> 3.72 | P22: =J22-M22 -> 3.77 | Q22: =CONCILIÇÃO_COM_CERVEJA!$P22-CONCILIÇÃO_COM_CERVEJA!$O22 -> 0.05 | R22: =IFERROR(VLOOKUP(CONCILIÇÃO_COM_CERVEJA!$B22,CUSTO!E:H,4,0),(VLOOKUP(CONCILIÇÃO_COM_CERVEJA!$A22,CUSTO!A:H,8,0))) -> 64.04415 | S22: =IFERROR(SUM(CONCILIÇÃO_COM_CERVEJA!$P22*CONCILIÇÃO_COM_CERVEJA!$R22),0) -> 241.44645 | T22: =IFERROR(#REF!/CONCILIÇÃO_COM_CERVEJA!$M22,"") | U22: =IFERROR(#REF!*CONCILIÇÃO_COM_CERVEJA!$R22,"-") -> -
A23: 31346 | B23: 2701050026 | C23: - | D23: AROMA IDENTICO AO NATURAL PESSEGO RB 25049 SAPORITI | E23: =IFERROR(VLOOKUP(B23,[1]AGLUTINADO!$A:$C,3,0),0)/G23 -> 12.31 | F23: AROMA | G23: 1 | H23: =VLOOKUP(CONCILIÇÃO_COM_CERVEJA!$B23,CONT_ANTE!A:D,4,0) -> 55 | I23: =IF(AND(E23=0,H23<>J23),"!@##@!","ok") -> ok | J23: =VLOOKUP(CONCILIÇÃO_COM_CERVEJA!$B23,CONTAGEM!B:G,6,0) -> 41 | K23: =SUMIF(SISTEMA!B:B,CONCILIÇÃO_COM_CERVEJA!$B23,SISTEMA!I:I)/G23 -> 44.59 | L23: =SUMIF(SISTEMA!B:B,CONCILIÇÃO_COM_CERVEJA!$C23,SISTEMA!I:I) -> 0 | M23: =K23+L23 -> 44.59 | N23: =IFERROR(SUM(CONCILIÇÃO_COM_CERVEJA!$M23*CONCILIÇÃO_COM_CERVEJA!$R23),0) -> 2194.3185 | O23: =IFERROR(VLOOKUP(CONCILIÇÃO_COM_CERVEJA!$B23,DIF_ANTE!A:D,4,0),"0")/CONCILIÇÃO_COM_CERVEJA!$G23 -> -1.9 | P23: =J23-M23 -> -3.59 | Q23: =CONCILIÇÃO_COM_CERVEJA!$P23-CONCILIÇÃO_COM_CERVEJA!$O23 -> -1.69 | R23: =IFERROR(VLOOKUP(CONCILIÇÃO_COM_CERVEJA!$B23,CUSTO!E:H,4,0),(VLOOKUP(CONCILIÇÃO_COM_CERVEJA!$A23,CUSTO!A:H,8,0))) -> 49.211 | S23: =IFERROR(SUM(CONCILIÇÃO_COM_CERVEJA!$P23*CONCILIÇÃO_COM_CERVEJA!$R23),0) -> -176.66749 | T23: =IFERROR(#REF!/CONCILIÇÃO_COM_CERVEJA!$M23,"") | U23: =IFERROR(#REF!*CONCILIÇÃO_COM_CERVEJA!$R23,"-") -> -
A24: 31355 | B24: 2701050005 | C24: - | D24: AROMA NATURAL BAUNILHA KALABROS | E24: =IFERROR(VLOOKUP(B24,[1]AGLUTINADO!$A:$C,3,0),0)/G24 -> 0 | F24: AROMA | G24: 1 | H24: =VLOOKUP(CONCILIÇÃO_COM_CERVEJA!$B24,CONT_ANTE!A:D,4,0) -> 0 | I24: =IF(AND(E24=0,H24<>J24),"!@##@!","ok") -> ok | J24: =VLOOKUP(CONCILIÇÃO_COM_CERVEJA!$B24,CONTAGEM!B:G,6,0) -> 0 | K24: =SUMIF(SISTEMA!B:B,CONCILIÇÃO_COM_CERVEJA!$B24,SISTEMA!I:I)/G24 -> 0 | L24: =SUMIF(SISTEMA!B:B,CONCILIÇÃO_COM_CERVEJA!$C24,SISTEMA!I:I) -> 0 | M24: =K24+L24 -> 0 | N24: =IFERROR(SUM(CONCILIÇÃO_COM_CERVEJA!$M24*CONCILIÇÃO_COM_CERVEJA!$R24),0) -> 0 | O24: =IFERROR(VLOOKUP(CONCILIÇÃO_COM_CERVEJA!$B24,DIF_ANTE!A:D,4,0),"0")/CONCILIÇÃO_COM_CERVEJA!$G24 -> 0 | P24: =J24-M24 -> 0 | Q24: =CONCILIÇÃO_COM_CERVEJA!$P24-CONCILIÇÃO_COM_CERVEJA!$O24 -> 0 | R24: =IFERROR(VLOOKUP(CONCILIÇÃO_COM_CERVEJA!$B24,CUSTO!E:H,4,0),(VLOOKUP(CONCILIÇÃO_COM_CERVEJA!$A24,CUSTO!A:H,8,0))) -> 45.476671 | S24: =IFERROR(SUM(CONCILIÇÃO_COM_CERVEJA!$P24*CONCILIÇÃO_COM_CERVEJA!$R24),0) -> 0 | T24: =IFERROR(#REF!/CONCILIÇÃO_COM_CERVEJA!$M24,"") | U24: =IFERROR(#REF!*CONCILIÇÃO_COM_CERVEJA!$R24,"-") -> - | V24: OK
B25: 2701050007 | C25: - | D25: AROMA NATURAL DE CITRUS RB 25395 SAPORITI | E25: =IFERROR(VLOOKUP(B25,[1]AGLUTINADO!$A:$C,3,0),0)/G25 -> 0 | F25: AROMA | G25: 1 | H25: =VLOOKUP(CONCILIÇÃO_COM_CERVEJA!$B25,CONT_ANTE!A:D,4,0) -> 0 | I25: =IF(AND(E25=0,H25<>J25),"!@##@!","ok") -> ok | J25: =VLOOKUP(CONCILIÇÃO_COM_CERVEJA!$B25,CONTAGEM!B:G,6,0) -> 0 | K25: =SUMIF(SISTEMA!B:B,CONCILIÇÃO_COM_CERVEJA!$B25,SISTEMA!I:I)/G25 -> 0 | L25: =SUMIF(SISTEMA!B:B,CONCILIÇÃO_COM_CERVEJA!$C25,SISTEMA!I:I) -> 0 | M25: =K25+L25 -> 0 | N25: =IFERROR(SUM(CONCILIÇÃO_COM_CERVEJA!$M25*CONCILIÇÃO_COM_CERVEJA!$R25),0) -> 0 | O25: =IFERROR(VLOOKUP(CONCILIÇÃO_COM_CERVEJA!$B25,DIF_ANTE!A:D,4,0),"0")/CONCILIÇÃO_COM_CERVEJA!$G25 -> 0 | P25: =J25-M25 -> 0 | Q25: =CONCILIÇÃO_COM_CERVEJA!$P25-CONCILIÇÃO_COM_CERVEJA!$O25 -> 0 | R25: =IFERROR(VLOOKUP(CONCILIÇÃO_COM_CERVEJA!$B25,CUSTO!E:H,4,0),(VLOOKUP(CONCILIÇÃO_COM_CERVEJA!$A25,CUSTO!A:H,8,0))) -> 88.617222 | S25: =IFERROR(SUM(CONCILIÇÃO_COM_CERVEJA!$P25*CONCILIÇÃO_COM_CERVEJA!$R25),0) -> 0 | T25: =IFERROR(#REF!/CONCILIÇÃO_COM_CERVEJA!$M25,"") | U25: =IFERROR(#REF!*CONCILIÇÃO_COM_CERVEJA!$R25,"-") -> - | V25: OK
B26: 2701050036 | C26: - | D26: AROMA NATURAL DE TANGERINA DOHLER | E26: =IFERROR(VLOOKUP(B26,[1]AGLUTINADO!$A:$C,3,0),0)/G26 -> 0 | F26: AROMA | G26: 1 | H26: =VLOOKUP(CONCILIÇÃO_COM_CERVEJA!$B26,CONT_ANTE!A:D,4,0) -> 110 | I26: =IF(AND(E26=0,H26<>J26),"!@##@!","ok") -> ok | J26: =VLOOKUP(CONCILIÇÃO_COM_CERVEJA!$B26,CONTAGEM!B:G,6,0) -> 110 | K26: =SUMIF(SISTEMA!B:B,CONCILIÇÃO_COM_CERVEJA!$B26,SISTEMA!I:I)/G26 -> 119.11 | L26: =SUMIF(SISTEMA!B:B,CONCILIÇÃO_COM_CERVEJA!$C26,SISTEMA!I:I) -> 0 | M26: =K26+L26 -> 119.11 | N26: =IFERROR(SUM(CONCILIÇÃO_COM_CERVEJA!$M26*CONCILIÇÃO_COM_CERVEJA!$R26),0) -> 17253.905 | O26: =IFERROR(VLOOKUP(CONCILIÇÃO_COM_CERVEJA!$B26,DIF_ANTE!A:D,4,0),"0")/CONCILIÇÃO_COM_CERVEJA!$G26 -> -9.11 | P26: =J26-M26 -> -9.11 | Q26: =CONCILIÇÃO_COM_CERVEJA!$P26-CONCILIÇÃO_COM_CERVEJA!$O26 -> 0 | R26: =IFERROR(VLOOKUP(CONCILIÇÃO_COM_CERVEJA!$B26,CUSTO!E:H,4,0),(VLOOKUP(CONCILIÇÃO_COM_CERVEJA!$A26,CUSTO!A:H,8,0))) -> 144.8569 | S26: =IFERROR(SUM(CONCILIÇÃO_COM_CERVEJA!$P26*CONCILIÇÃO_COM_CERVEJA!$R26),0) -> -1319.6464 | T26: =IFERROR(#REF!/CONCILIÇÃO_COM_CERVEJA!$M26,"") | U26: =IFERROR(#REF!*CONCILIÇÃO_COM_CERVEJA!$R26,"-") -> - | V26: OK
A27: 31312 | B27: 2701050012 | C27: - | D27: AROMA NATURAL LIMAO VERDE MAJUFRAN | E27: =IFERROR(VLOOKUP(B27,[1]AGLUTINADO!$A:$C,3,0),0)/G27 -> 0 | F27: AROMA | G27: 1 | H27: =VLOOKUP(CONCILIÇÃO_COM_CERVEJA!$B27,CONT_ANTE!A:D,4,0) -> 25 | I27: =IF(AND(E27=0,H27<>J27),"!@##@!","ok") -> !@##@! | J27: =VLOOKUP(CONCILIÇÃO_COM_CERVEJA!$B27,CONTAGEM!B:G,6,0) -> 0 | K27: =SUMIF(SISTEMA!B:B,CONCILIÇÃO_COM_CERVEJA!$B27,SISTEMA!I:I)/G27 -> 0 | L27: =SUMIF(SISTEMA!B:B,CONCILIÇÃO_COM_CERVEJA!$C27,SISTEMA!I:I) -> 0 | M27: =K27+L27 -> 0 | N27: =IFERROR(SUM(CONCILIÇÃO_COM_CERVEJA!$M27*CONCILIÇÃO_COM_CERVEJA!$R27),0) -> 0 | O27: =IFERROR(VLOOKUP(CONCILIÇÃO_COM_CERVEJA!$B27,DIF_ANTE!A:D,4,0),"0")/CONCILIÇÃO_COM_CERVEJA!$G27 -> -0.90412 | P27: =J27-M27 -> 0 | Q27: =CONCILIÇÃO_COM_CERVEJA!$P27-CONCILIÇÃO_COM_CERVEJA!$O27 -> 0.90412 | R27: =IFERROR(VLOOKUP(CONCILIÇÃO_COM_CERVEJA!$B27,CUSTO!E:H,4,0),(VLOOKUP(CONCILIÇÃO_COM_CERVEJA!$A27,CUSTO!A:H,8,0))) -> 30.3832 | S27: =IFERROR(SUM(CONCILIÇÃO_COM_CERVEJA!$P27*CONCILIÇÃO_COM_CERVEJA!$R27),0) -> 0 | T27: =IFERROR(#REF!/CONCILIÇÃO_COM_CERVEJA!$M27,"") | U27: =IFERROR(#REF!*CONCILIÇÃO_COM_CERVEJA!$R27,"-") -> - | V27: OK
A28: 2477 | B28: 2701050001 | C28: - | D28: AROMA NATURAL MOUTHFEEL ADM | E28: =IFERROR(VLOOKUP(B28,[1]AGLUTINADO!$A:$C,3,0),0)/G28 -> 33.64 | F28: AROMA | G28: 1 | H28: =VLOOKUP(CONCILIÇÃO_COM_CERVEJA!$B28,CONT_ANTE!A:D,4,0) -> 114.84 | I28: =IF(AND(E28=0,H28<>J28),"!@##@!","ok") -> ok | J28: =VLOOKUP(CONCILIÇÃO_COM_CERVEJA!$B28,CONTAGEM!B:G,6,0) -> 70 | K28: =SUMIF(SISTEMA!B:B,CONCILIÇÃO_COM_CERVEJA!$B28,SISTEMA!I:I)/G28 -> 60.36 | L28: =SUMIF(SISTEMA!B:B,CONCILIÇÃO_COM_CERVEJA!$C28,SISTEMA!I:I) -> 0 | M28: =K28+L28 -> 60.36 | N28: =IFERROR(SUM(CONCILIÇÃO_COM_CERVEJA!$M28*CONCILIÇÃO_COM_CERVEJA!$R28),0) -> 8697.8849 | O28: =IFERROR(VLOOKUP(CONCILIÇÃO_COM_CERVEJA!$B28,DIF_ANTE!A:D,4,0),"0")/CONCILIÇÃO_COM_CERVEJA!$G28 -> -15.44 | P28: =J28-M28 -> 9.64 | Q28: =CONCILIÇÃO_COM_CERVEJA!$P28-CONCILIÇÃO_COM_CERVEJA!$O28 -> 25.08 | R28: =IFERROR(VLOOKUP(CONCILIÇÃO_COM_CERVEJA!$B28,CUSTO!E:H,4,0),(VLOOKUP(CONCILIÇÃO_COM_CERVEJA!$A28,CUSTO!A:H,8,0))) -> 144.10015 | S28: =IFERROR(SUM(CONCILIÇÃO_COM_CERVEJA!$P28*CONCILIÇÃO_COM_CERVEJA!$R28),0) -> 1389.1254 | T28: =IFERROR(#REF!/CONCILIÇÃO_COM_CERVEJA!$M28,"") | U28: =IFERROR(#REF!*CONCILIÇÃO_COM_CERVEJA!$R28,"-") -> -
A29: 353 | B29: 2701050028 | C29: - | D29: AROMA NATURAL VODKA DUAS RODAS | E29: =IFERROR(VLOOKUP(B29,[1]AGLUTINADO!$A:$C,3,0),0)/G29 -> 152.17 | F29: AROMA | G29: 1 | H29: =VLOOKUP(CONCILIÇÃO_COM_CERVEJA!$B29,CONT_ANTE!A:D,4,0) -> 0 | I29: =IF(AND(E29=0,H29<>J29),"!@##@!","ok") -> ok | J29: =VLOOKUP(CONCILIÇÃO_COM_CERVEJA!$B29,CONTAGEM!B:G,6,0) -> 270.5 | K29: =SUMIF(SISTEMA!B:B,CONCILIÇÃO_COM_CERVEJA!$B29,SISTEMA!I:I)/G29 -> 302.33 | L29: =SUMIF(SISTEMA!B:B,CONCILIÇÃO_COM_CERVEJA!$C29,SISTEMA!I:I) -> 0 | M29: =K29+L29 -> 302.33 | N29: =IFERROR(SUM(CONCILIÇÃO_COM_CERVEJA!$M29*CONCILIÇÃO_COM_CERVEJA!$R29),0) -> 6603.5292 | O29: =IFERROR(VLOOKUP(CONCILIÇÃO_COM_CERVEJA!$B29,DIF_ANTE!A:D,4,0),"0")/CONCILIÇÃO_COM_CERVEJA!$G29 -> 0 | P29: =J29-M29 -> -31.83 | Q29: =CONCILIÇÃO_COM_CERVEJA!$P29-CONCILIÇÃO_COM_CERVEJA!$O29 -> -31.83 | R29: =IFERROR(VLOOKUP(CONCILIÇÃO_COM_CERVEJA!$B29,CUSTO!E:H,4,0),(VLOOKUP(CONCILIÇÃO_COM_CERVEJA!$A29,CUSTO!A:H,8,0))) -> 21.842123 | S29: =IFERROR(SUM(CONCILIÇÃO_COM_CERVEJA!$P29*CONCILIÇÃO_COM_CERVEJA!$R29),0) -> -695.23479 | T29: =IFERROR(#REF!/CONCILIÇÃO_COM_CERVEJA!$M29,"") | U29: =IFERROR(#REF!*CONCILIÇÃO_COM_CERVEJA!$R29,"-") -> - | V29: ok
A30: 31518 | B30: 2701050023 | C30: - | D30: PREPARADO ACIDO COLA | E30: =IFERROR(VLOOKUP(B30,[1]AGLUTINADO!$A:$C,3,0),0)/G30 -> 61.52 | F30: AROMA | G30: 1 | H30: =VLOOKUP(CONCILIÇÃO_COM_CERVEJA!$B30,CONT_ANTE!A:D,4,0) -> 115 | I30: =IF(AND(E30=0,H30<>J30),"!@##@!","ok") -> ok | J30: =VLOOKUP(CONCILIÇÃO_COM_CERVEJA!$B30,CONTAGEM!B:G,6,0) -> 395 | K30: =SUMIF(SISTEMA!B:B,CONCILIÇÃO_COM_CERVEJA!$B30,SISTEMA!I:I)/G30 -> 372.21 | L30: =SUMIF(SISTEMA!B:B,CONCILIÇÃO_COM_CERVEJA!$C30,SISTEMA!I:I) -> 0 | M30: =K30+L30 -> 372.21 | N30: =IFERROR(SUM(CONCILIÇÃO_COM_CERVEJA!$M30*CONCILIÇÃO_COM_CERVEJA!$R30),0) -> 7508.034 | O30: =IFERROR(VLOOKUP(CONCILIÇÃO_COM_CERVEJA!$B30,DIF_ANTE!A:D,4,0),"0")/CONCILIÇÃO_COM_CERVEJA!$G30 -> 1.27 | P30: =J30-M30 -> 22.79 | Q30: =CONCILIÇÃO_COM_CERVEJA!$P30-CONCILIÇÃO_COM_CERVEJA!$O30 -> 21.52 | R30: =IFERROR(VLOOKUP(CONCILIÇÃO_COM_CERVEJA!$B30,CUSTO!E:H,4,0),(VLOOKUP(CONCILIÇÃO_COM_CERVEJA!$A30,CUSTO!A:H,8,0))) -> 20.1715 | S30: =IFERROR(SUM(CONCILIÇÃO_COM_CERVEJA!$P30*CONCILIÇÃO_COM_CERVEJA!$R30),0) -> 459.70849 | T30: =IFERROR(#REF!/CONCILIÇÃO_COM_CERVEJA!$M30,"") | U30: =IFERROR(#REF!*CONCILIÇÃO_COM_CERVEJA!$R30,"-") -> -
A31: 30758 | B31: 2701160011 | C31: - | D31: CAIXA CER BAMBOA LAGER 12X330ML | E31: =IFERROR(VLOOKUP(B31,[1]AGLUTINADO!$A:$C,3,0),0)/G31 -> 6688 | F31: CAIXA | G31: 1 | H31: =VLOOKUP(CONCILIÇÃO_COM_CERVEJA!$B31,CONT_ANTE!A:D,4,0) -> 39805 | I31: =IF(AND(E31=0,H31<>J31),"!@##@!","ok") -> ok | J31: =VLOOKUP(CONCILIÇÃO_COM_CERVEJA!$B31,CONTAGEM!B:G,6,0) -> 32600 | K31: =SUMIF(SISTEMA!B:B,CONCILIÇÃO_COM_CERVEJA!$B31,SISTEMA!I:I)/G31 -> 34779 | L31: =SUMIF(SISTEMA!B:B,CONCILIÇÃO_COM_CERVEJA!$C31,SISTEMA!I:I) -> 0 | M31: =K31+L31 -> 34779 | N31: =IFERROR(SUM(CONCILIÇÃO_COM_CERVEJA!$M31*CONCILIÇÃO_COM_CERVEJA!$R31),0) -> 54008.524 | O31: =IFERROR(VLOOKUP(CONCILIÇÃO_COM_CERVEJA!$B31,DIF_ANTE!A:D,4,0),"0")/CONCILIÇÃO_COM_CERVEJA!$G31 -> -1662 | P31: =J31-M31 -> -2179 | Q31: =CONCILIÇÃO_COM_CERVEJA!$P31-CONCILIÇÃO_COM_CERVEJA!$O31 -> -517 | R31: =IFERROR(VLOOKUP(CONCILIÇÃO_COM_CERVEJA!$B31,CUSTO!E:H,4,0),(VLOOKUP(CONCILIÇÃO_COM_CERVEJA!$A31,CUSTO!A:H,8,0))) -> 1.5529062 | S31: =IFERROR(SUM(CONCILIÇÃO_COM_CERVEJA!$P31*CONCILIÇÃO_COM_CERVEJA!$R31),0) -> -3383.7826 | T31: =IFERROR(#REF!/CONCILIÇÃO_COM_CERVEJA!$M31,"") | U31: =IFERROR(#REF!*CONCILIÇÃO_COM_CERVEJA!$R31,"-") -> -
A32: 30756 | B32: 2701160008 | C32: - | D32: CAIXA CER BAMBOA PILSEN 12X300ML | E32: =IFERROR(VLOOKUP(B32,[1]AGLUTINADO!$A:$C,3,0),0)/G32 -> 0 | F32: CAIXA | G32: 1 | H32: =VLOOKUP(CONCILIÇÃO_COM_CERVEJA!$B32,CONT_ANTE!A:D,4,0) -> 0 | I32: =IF(AND(E32=0,H32<>J32),"!@##@!","ok") -> ok | J32: =VLOOKUP(CONCILIÇÃO_COM_CERVEJA!$B32,CONTAGEM!B:G,6,0) -> 0 | K32: =SUMIF(SISTEMA!B:B,CONCILIÇÃO_COM_CERVEJA!$B32,SISTEMA!I:I)/G32 -> 0 | L32: =SUMIF(SISTEMA!B:B,CONCILIÇÃO_COM_CERVEJA!$C32,SISTEMA!I:I) -> 0 | M32: =K32+L32 -> 0 | N32: =IFERROR(SUM(CONCILIÇÃO_COM_CERVEJA!$M32*CONCILIÇÃO_COM_CERVEJA!$R32),0) -> 0 | O32: =IFERROR(VLOOKUP(CONCILIÇÃO_COM_CERVEJA!$B32,DIF_ANTE!A:D,4,0),"0")/CONCILIÇÃO_COM_CERVEJA!$G32 -> 0 | P32: =J32-M32 -> 0 | Q32: =CONCILIÇÃO_COM_CERVEJA!$P32-CONCILIÇÃO_COM_CERVEJA!$O32 -> 0 | R32: =IFERROR(VLOOKUP(CONCILIÇÃO_COM_CERVEJA!$B32,CUSTO!E:H,4,0),(VLOOKUP(CONCILIÇÃO_COM_CERVEJA!$A32,CUSTO!A:H,8,0))) -> 1.3587996 | S32: =IFERROR(SUM(CONCILIÇÃO_COM_CERVEJA!$P32*CONCILIÇÃO_COM_CERVEJA!$R32),0) -> 0 | T32: =IFERROR(#REF!/CONCILIÇÃO_COM_CERVEJA!$M32,"") | U32: =IFERROR(#REF!*CONCILIÇÃO_COM_CERVEJA!$R32,"-") -> - | V32: OK
A33: 1444 | B33: 2701160007 | C33: - | D33: CAIXA CER BAMBOA PILSEN 6X600ML | E33: =IFERROR(VLOOKUP(B33,[1]AGLUTINADO!$A:$C,3,0),0)/G33 -> 0 | F33: CAIXA | G33: 1 | H33: =VLOOKUP(CONCILIÇÃO_COM_CERVEJA!$B33,CONT_ANTE!A:D,4,0) -> 0 | I33: =IF(AND(E33=0,H33<>J33),"!@##@!","ok") -> ok | J33: =VLOOKUP(CONCILIÇÃO_COM_CERVEJA!$B33,CONTAGEM!B:G,6,0) -> 0 | K33: =SUMIF(SISTEMA!B:B,CONCILIÇÃO_COM_CERVEJA!$B33,SISTEMA!I:I)/G33 -> 0 | L33: =SUMIF(SISTEMA!B:B,CONCILIÇÃO_COM_CERVEJA!$C33,SISTEMA!I:I) -> 0 | M33: =K33+L33 -> 0 | N33: =IFERROR(SUM(CONCILIÇÃO_COM_CERVEJA!$M33*CONCILIÇÃO_COM_CERVEJA!$R33),0) -> 0 | O33: =IFERROR(VLOOKUP(CONCILIÇÃO_COM_CERVEJA!$B33,DIF_ANTE!A:D,4,0),"0")/CONCILIÇÃO_COM_CERVEJA!$G33 -> 0 | P33: =J33-M33 -> 0 | Q33: =CONCILIÇÃO_COM_CERVEJA!$P33-CONCILIÇÃO_COM_CERVEJA!$O33 -> 0 | R33: =IFERROR(VLOOKUP(CONCILIÇÃO_COM_CERVEJA!$B33,CUSTO!E:H,4,0),(VLOOKUP(CONCILIÇÃO_COM_CERVEJA!$A33,CUSTO!A:H,8,0))) -> 2.1716379 | S33: =IFERROR(SUM(CONCILIÇÃO_COM_CERVEJA!$P33*CONCILIÇÃO_COM_CERVEJA!$R33),0) -> 0 | T33: =IFERROR(#REF!/CONCILIÇÃO_COM_CERVEJA!$M33,"") | U33: =IFERROR(#REF!*CONCILIÇÃO_COM_CERVEJA!$R33,"-") -> - | V33: OK
A34: 30739 | B34: 2701160006 | C34: - | D34: CAIXA CER MOEMA 12X300ML | E34: =IFERROR(VLOOKUP(B34,[1]AGLUTINADO!$A:$C,3,0),0)/G34 -> 0 | F34: CAIXA | G34: 1 | H34: =VLOOKUP(CONCILIÇÃO_COM_CERVEJA!$B34,CONT_ANTE!A:D,4,0) -> 4400 | I34: =IF(AND(E34=0,H34<>J34),"!@##@!","ok") -> ok | J34: =VLOOKUP(CONCILIÇÃO_COM_CERVEJA!$B34,CONTAGEM!B:G,6,0) -> 4400 | K34: =SUMIF(SISTEMA!B:B,CONCILIÇÃO_COM_CERVEJA!$B34,SISTEMA!I:I)/G34 -> 4400 | L34: =SUMIF(SISTEMA!B:B,CONCILIÇÃO_COM_CERVEJA!$C34,SISTEMA!I:I) -> 0 | M34: =K34+L34 -> 4400 | N34: =IFERROR(SUM(CONCILIÇÃO_COM_CERVEJA!$M34*CONCILIÇÃO_COM_CERVEJA!$R34),0) -> 8173.3211 | O34: =IFERROR(VLOOKUP(CONCILIÇÃO_COM_CERVEJA!$B34,DIF_ANTE!A:D,4,0),"0")/CONCILIÇÃO_COM_CERVEJA!$G34 -> 0 | P34: =J34-M34 -> 0 | Q34: =CONCILIÇÃO_COM_CERVEJA!$P34-CONCILIÇÃO_COM_CERVEJA!$O34 -> 0 | R34: =IFERROR(VLOOKUP(CONCILIÇÃO_COM_CERVEJA!$B34,CUSTO!E:H,4,0),(VLOOKUP(CONCILIÇÃO_COM_CERVEJA!$A34,CUSTO!A:H,8,0))) -> 1.857573 | S34: =IFERROR(SUM(CONCILIÇÃO_COM_CERVEJA!$P34*CONCILIÇÃO_COM_CERVEJA!$R34),0) -> 0 | T34: =IFERROR(#REF!/CONCILIÇÃO_COM_CERVEJA!$M34,"") | U34: =IFERROR(#REF!*CONCILIÇÃO_COM_CERVEJA!$R34,"-") -> - | V34: OK
A35: 30738 | B35: 2701160005 | C35: - | D35: CAIXA CER MOEMA 6X600ML | E35: =IFERROR(VLOOKUP(B35,[1]AGLUTINADO!$A:$C,3,0),0)/G35 -> 0 | F35: CAIXA | G35: 1 | H35: =VLOOKUP(CONCILIÇÃO_COM_CERVEJA!$B35,CONT_ANTE!A:D,4,0) -> 10597 | I35: =IF(AND(E35=0,H35<>J35),"!@##@!","ok") -> !@##@! | J35: =VLOOKUP(CONCILIÇÃO_COM_CERVEJA!$B35,CONTAGEM!B:G,6,0) -> 10537 | K35: =SUMIF(SISTEMA!B:B,CONCILIÇÃO_COM_CERVEJA!$B35,SISTEMA!I:I)/G35 -> 11537 | L35: =SUMIF(SISTEMA!B:B,CONCILIÇÃO_COM_CERVEJA!$C35,SISTEMA!I:I) -> 0 | M35: =K35+L35 -> 11537 | N35: =IFERROR(SUM(CONCILIÇÃO_COM_CERVEJA!$M35*CONCILIÇÃO_COM_CERVEJA!$R35),0) -> 15676.471 | O35: =IFERROR(VLOOKUP(CONCILIÇÃO_COM_CERVEJA!$B35,DIF_ANTE!A:D,4,0),"0")/CONCILIÇÃO_COM_CERVEJA!$G35 -> -1000 | P35: =J35-M35 -> -1000 | Q35: =CONCILIÇÃO_COM_CERVEJA!$P35-CONCILIÇÃO_COM_CERVEJA!$O35 -> 0 | R35: =IFERROR(VLOOKUP(CONCILIÇÃO_COM_CERVEJA!$B35,CUSTO!E:H,4,0),(VLOOKUP(CONCILIÇÃO_COM_CERVEJA!$A35,CUSTO!A:H,8,0))) -> 1.3587996 | S35: =IFERROR(SUM(CONCILIÇÃO_COM_CERVEJA!$P35*CONCILIÇÃO_COM_CERVEJA!$R35),0) -> -1358.7996 | T35: =IFERROR(#REF!/CONCILIÇÃO_COM_CERVEJA!$M35,"") | U35: =IFERROR(#REF!*CONCILIÇÃO_COM_CERVEJA!$R35,"-") -> - | V35: OK
A36: 32711 | B36: 2701160001 | C36: - | D36: CAIXA GIN JAMES COOK 6X900ML | E36: =IFERROR(VLOOKUP(B36,[1]AGLUTINADO!$A:$C,3,0),0)/G36 -> 795 | F36: CAIXA | G36: 1 | H36: =VLOOKUP(CONCILIÇÃO_COM_CERVEJA!$B36,CONT_ANTE!A:D,4,0) -> 800 | I36: =IF(AND(E36=0,H36<>J36),"!@##@!","ok") -> ok | J36: =VLOOKUP(CONCILIÇÃO_COM_CERVEJA!$B36,CONTAGEM!B:G,6,0) -> 0 | K36: =SUMIF(SISTEMA!B:B,CONCILIÇÃO_COM_CERVEJA!$B36,SISTEMA!I:I)/G36 -> 20 | L36: =SUMIF(SISTEMA!B:B,CONCILIÇÃO_COM_CERVEJA!$C36,SISTEMA!I:I) -> 0 | M36: =K36+L36 -> 20 | N36: =IFERROR(SUM(CONCILIÇÃO_COM_CERVEJA!$M36*CONCILIÇÃO_COM_CERVEJA!$R36),0) -> 49.96335 | O36: =IFERROR(VLOOKUP(CONCILIÇÃO_COM_CERVEJA!$B36,DIF_ANTE!A:D,4,0),"0")/CONCILIÇÃO_COM_CERVEJA!$G36 -> -15 | P36: =J36-M36 -> -20 | Q36: =CONCILIÇÃO_COM_CERVEJA!$P36-CONCILIÇÃO_COM_CERVEJA!$O36 -> -5 | R36: =IFERROR(VLOOKUP(CONCILIÇÃO_COM_CERVEJA!$B36,CUSTO!E:H,4,0),(VLOOKUP(CONCILIÇÃO_COM_CERVEJA!$A36,CUSTO!A:H,8,0))) -> 2.4981675 | S36: =IFERROR(SUM(CONCILIÇÃO_COM_CERVEJA!$P36*CONCILIÇÃO_COM_CERVEJA!$R36),0) -> -49.96335 | T36: =IFERROR(#REF!/CONCILIÇÃO_COM_CERVEJA!$M36,"") | U36: =IFERROR(#REF!*CONCILIÇÃO_COM_CERVEJA!$R36,"-") -> -
A37: 31584 | B37: 2701160012 | C37: - | D37: CAIXA REFRIGERANTE REFRIKO TUBAINA 12X300ML | E37: =IFERROR(VLOOKUP(B37,[1]AGLUTINADO!$A:$C,3,0),0)/G37 -> 10177 | F37: CAIXA | G37: 1 | H37: =VLOOKUP(CONCILIÇÃO_COM_CERVEJA!$B37,CONT_ANTE!A:D,4,0) -> 17200 | I37: =IF(AND(E37=0,H37<>J37),"!@##@!","ok") -> ok | J37: =VLOOKUP(CONCILIÇÃO_COM_CERVEJA!$B37,CONTAGEM!B:G,6,0) -> 25425 | K37: =SUMIF(SISTEMA!B:B,CONCILIÇÃO_COM_CERVEJA!$B37,SISTEMA!I:I)/G37 -> 28252 | L37: =SUMIF(SISTEMA!B:B,CONCILIÇÃO_COM_CERVEJA!$C37,SISTEMA!I:I) -> 0 | M37: =K37+L37 -> 28252 | N37: =IFERROR(SUM(CONCILIÇÃO_COM_CERVEJA!$M37*CONCILIÇÃO_COM_CERVEJA!$R37),0) -> 44532.761 | O37: =IFERROR(VLOOKUP(CONCILIÇÃO_COM_CERVEJA!$B37,DIF_ANTE!A:D,4,0),"0")/CONCILIÇÃO_COM_CERVEJA!$G37 -> -454 | P37: =J37-M37 -> -2827 | Q37: =CONCILIÇÃO_COM_CERVEJA!$P37-CONCILIÇÃO_COM_CERVEJA!$O37 -> -2373 | R37: =IFERROR(VLOOKUP(CONCILIÇÃO_COM_CERVEJA!$B37,CUSTO!E:H,4,0),(VLOOKUP(CONCILIÇÃO_COM_CERVEJA!$A37,CUSTO!A:H,8,0))) -> 1.5762693 | S37: =IFERROR(SUM(CONCILIÇÃO_COM_CERVEJA!$P37*CONCILIÇÃO_COM_CERVEJA!$R37),0) -> -4456.1133 | T37: =IFERROR(#REF!/CONCILIÇÃO_COM_CERVEJA!$M37,"") | U37: =IFERROR(#REF!*CONCILIÇÃO_COM_CERVEJA!$R37,"-") -> -
B38: 2701160013 | C38: - | D38: CAIXA REFRIGERANTE REFRIKO TUBAINA 12X355ML | E38: =IFERROR(VLOOKUP(B38,[1]AGLUTINADO!$A:$C,3,0),0)/G38 -> 0 | F38: CAIXA | G38: 1 | H38: =VLOOKUP(CONCILIÇÃO_COM_CERVEJA!$B38,CONT_ANTE!A:D,4,0) -> 21167 | I38: =IF(AND(E38=0,H38<>J38),"!@##@!","ok") -> !@##@! | J38: =VLOOKUP(CONCILIÇÃO_COM_CERVEJA!$B38,CONTAGEM!B:G,6,0) -> 18812 | K38: =SUMIF(SISTEMA!B:B,CONCILIÇÃO_COM_CERVEJA!$B38,SISTEMA!I:I)/G38 -> 18877 | L38: =SUMIF(SISTEMA!B:B,CONCILIÇÃO_COM_CERVEJA!$C38,SISTEMA!I:I) -> 0 | M38: =K38+L38 -> 18877 | N38: =IFERROR(SUM(CONCILIÇÃO_COM_CERVEJA!$M38*CONCILIÇÃO_COM_CERVEJA!$R38),0) -> 35614.631 | O38: =IFERROR(VLOOKUP(CONCILIÇÃO_COM_CERVEJA!$B38,DIF_ANTE!A:D,4,0),"0")/CONCILIÇÃO_COM_CERVEJA!$G38 -> 0 | P38: =J38-M38 -> -65 | Q38: =CONCILIÇÃO_COM_CERVEJA!$P38-CONCILIÇÃO_COM_CERVEJA!$O38 -> -65 | R38: =IFERROR(VLOOKUP(CONCILIÇÃO_COM_CERVEJA!$B38,CUSTO!E:H,4,0),(VLOOKUP(CONCILIÇÃO_COM_CERVEJA!$A38,CUSTO!A:H,8,0))) -> 1.886668 | S38: =IFERROR(SUM(CONCILIÇÃO_COM_CERVEJA!$P38*CONCILIÇÃO_COM_CERVEJA!$R38),0) -> -122.63342 | T38: =IFERROR(#REF!/CONCILIÇÃO_COM_CERVEJA!$M38,"") | U38: =IFERROR(#REF!*CONCILIÇÃO_COM_CERVEJA!$R38,"-") -> -
B39: 2701160009 | C39: - | D39: CAIXA REFRIGERANTE REFRIKO TUBAINA S/ ACUCARES 12X300ML | E39: =IFERROR(VLOOKUP(B39,[1]AGLUTINADO!$A:$C,3,0),0)/G39 -> 2693 | F39: CAIXA | G39: 1 | H39: =VLOOKUP(CONCILIÇÃO_COM_CERVEJA!$B39,CONT_ANTE!A:D,4,0) -> 26875 | I39: =IF(AND(E39=0,H39<>J39),"!@##@!","ok") -> ok | J39: =VLOOKUP(CONCILIÇÃO_COM_CERVEJA!$B39,CONTAGEM!B:G,6,0) -> 23945 | K39: =SUMIF(SISTEMA!B:B,CONCILIÇÃO_COM_CERVEJA!$B39,SISTEMA!I:I)/G39 -> 24182 | L39: =SUMIF(SISTEMA!B:B,CONCILIÇÃO_COM_CERVEJA!$C39,SISTEMA!I:I) -> 0 | M39: =K39+L39 -> 24182 | N39: =IFERROR(SUM(CONCILIÇÃO_COM_CERVEJA!$M39*CONCILIÇÃO_COM_CERVEJA!$R39),0) -> 37122.88 | O39: =IFERROR(VLOOKUP(CONCILIÇÃO_COM_CERVEJA!$B39,DIF_ANTE!A:D,4,0),"0")/CONCILIÇÃO_COM_CERVEJA!$G39 -> 0 | P39: =J39-M39 -> -237 | Q39: =CONCILIÇÃO_COM_CERVEJA!$P39-CONCILIÇÃO_COM_CERVEJA!$O39 -> -237 | R39: =IFERROR(VLOOKUP(CONCILIÇÃO_COM_CERVEJA!$B39,CUSTO!E:H,4,0),(VLOOKUP(CONCILIÇÃO_COM_CERVEJA!$A39,CUSTO!A:H,8,0))) -> 1.5351451 | S39: =IFERROR(SUM(CONCILIÇÃO_COM_CERVEJA!$P39*CONCILIÇÃO_COM_CERVEJA!$R39),0) -> -363.8294 | T39: =IFERROR(#REF!/CONCILIÇÃO_COM_CERVEJA!$M39,"") | U39: =IFERROR(#REF!*CONCILIÇÃO_COM_CERVEJA!$R39,"-") -> -
A40: 32714 | B40: 2701160002 | C40: - | D40: CAIXA VODKA JAMES COOK 6X900ML | E40: =IFERROR(VLOOKUP(B40,[1]AGLUTINADO!$A:$C,3,0),0)/G40 -> 1736 | F40: CAIXA | G40: 1 | H40: =VLOOKUP(CONCILIÇÃO_COM_CERVEJA!$B40,CONT_ANTE!A:D,4,0) -> 4804 | I40: =IF(AND(E40=0,H40<>J40),"!@##@!","ok") -> ok | J40: =VLOOKUP(CONCILIÇÃO_COM_CERVEJA!$B40,CONTAGEM!B:G,6,0) -> 3284 | K40: =SUMIF(SISTEMA!B:B,CONCILIÇÃO_COM_CERVEJA!$B40,SISTEMA!I:I)/G40 -> 3112 | L40: =SUMIF(SISTEMA!B:B,CONCILIÇÃO_COM_CERVEJA!$C40,SISTEMA!I:I) -> 0 | M40: =K40+L40 -> 3112 | N40: =IFERROR(SUM(CONCILIÇÃO_COM_CERVEJA!$M40*CONCILIÇÃO_COM_CERVEJA!$R40),0) -> 7774.2854 | O40: =IFERROR(VLOOKUP(CONCILIÇÃO_COM_CERVEJA!$B40,DIF_ANTE!A:D,4,0),"0")/CONCILIÇÃO_COM_CERVEJA!$G40 -> -44 | P40: =J40-M40 -> 172 | Q40: =CONCILIÇÃO_COM_CERVEJA!$P40-CONCILIÇÃO_COM_CERVEJA!$O40 -> 216 | R40: =IFERROR(VLOOKUP(CONCILIÇÃO_COM_CERVEJA!$B40,CUSTO!E:H,4,0),(VLOOKUP(CONCILIÇÃO_COM_CERVEJA!$A40,CUSTO!A:H,8,0))) -> 2.4981637 | S40: =IFERROR(SUM(CONCILIÇÃO_COM_CERVEJA!$P40*CONCILIÇÃO_COM_CERVEJA!$R40),0) -> 429.68415 | T40: =IFERROR(#REF!/CONCILIÇÃO_COM_CERVEJA!$M40,"") | U40: =IFERROR(#REF!*CONCILIÇÃO_COM_CERVEJA!$R40,"-") -> -
A41: 30574 | B41: 2701240002 | C41: - | D41: CANTONEIRA SIMPLES 100X100X1580MM | E41: =IFERROR(VLOOKUP(B41,[1]AGLUTINADO!$A:$C,3,0),0)/G41 -> 556.46477 | F41: CAIXA | G41: 1 | H41: =VLOOKUP(CONCILIÇÃO_COM_CERVEJA!$B41,CONT_ANTE!A:D,4,0) -> 6360 | I41: =IF(AND(E41=0,H41<>J41),"!@##@!","ok") -> ok | J41: =VLOOKUP(CONCILIÇÃO_COM_CERVEJA!$B41,CONTAGEM!B:G,6,0) -> 6200 | K41: =SUMIF(SISTEMA!B:B,CONCILIÇÃO_COM_CERVEJA!$B41,SISTEMA!I:I)/G41 -> 4126.6767 | L41: =SUMIF(SISTEMA!B:B,CONCILIÇÃO_COM_CERVEJA!$C41,SISTEMA!I:I) -> 0 | M41: =K41+L41 -> 4126.6767 | N41: =IFERROR(SUM(CONCILIÇÃO_COM_CERVEJA!$M41*CONCILIÇÃO_COM_CERVEJA!$R41),0) -> 5035.4694 | O41: =IFERROR(VLOOKUP(CONCILIÇÃO_COM_CERVEJA!$B41,DIF_ANTE!A:D,4,0),"0")/CONCILIÇÃO_COM_CERVEJA!$G41 -> 120.8601 | P41: =J41-M41 -> 2073.3233 | Q41: =CONCILIÇÃO_COM_CERVEJA!$P41-CONCILIÇÃO_COM_CERVEJA!$O41 -> 1952.4632 | R41: =IFERROR(VLOOKUP(CONCILIÇÃO_COM_CERVEJA!$B41,CUSTO!E:H,4,0),(VLOOKUP(CONCILIÇÃO_COM_CERVEJA!$A41,CUSTO!A:H,8,0))) -> 1.2202239 | S41: =IFERROR(SUM(CONCILIÇÃO_COM_CERVEJA!$P41*CONCILIÇÃO_COM_CERVEJA!$R41),0) -> 2529.9186 | T41: =IFERROR(#REF!/CONCILIÇÃO_COM_CERVEJA!$M41,"") | U41: =IFERROR(#REF!*CONCILIÇÃO_COM_CERVEJA!$R41,"-") -> -
...

Sheet Planilha2
L2: Sistema | M2: Produção
K3: Saldo em 31/12 | L3: 2311041 | M3: 2311041
I4: Entradas | J4: jan | K4: =1460160*3 -> 4380480 | L4: =SUM(K4:K6) -> 11681280 | M4: =SUM(L4:L6) -> 11681280
J5: Fev | K5: =1460160*2 -> 2920320
J6: Mar | K6: =1460160*3 -> 4380480
I7: Saidas | J7: Jan | K7: 4929395 | L7: =SUM(K7:K9) -> 11807538 | M7: =4916976+17762 -> 4934738
J8: Fev | K8: 1593143 | M8: =1588356+6231 -> 1594587
J9: Mar | K9: 5285000 | M9: =4641756+16653 -> 4658409
K10: Saldo em 31/03 | L10: =L3+L4-L7 -> 2184783 | M10: =M3+M4-M7-M8-M9 -> 2804587
K11: Contagem 31/03 | L11: 3047780
K14: Saldo em 31/12 | L14: 12830 | M14: 723648 | Q14: jan | R14: fev | S14: mar
K15: Compra | L15: 66340 | M15: 341760 | Q15: 74826 | R15: 50448 | S15: 109824
K16: Consumo | L16: 53770 | M16: 291655 | N16: 298428 | O16: =M16-N16 -> -6773 | Q16: 188964 | R16: 73944 | S16: 198246
K17: Saldo em 31/01 | L17: =L14+L15-L16 -> 25400 | M17: =M14+M15-M16 -> 773753 | Q17: 8478 | R17: 12342 | S17: 13976
K18: Compra | L18: 28070 | M18: 0 | Q18: 26160 | R18: 42078 | S18: 50784
K19: Consumo | L19: 33510 | M19: 179241 | N19: 178812 | O19: =M19-N19 -> 429 | P19: total | Q19: =SUM(Q15:Q18) -> 298428 | R19: =SUM(R15:R18) -> 178812 | S19: =SUM(S15:S18) -> 372830
K20: Saldo em 28/02 | L20: =L17+L18-L19 -> 19960 | M20: =M17+M18-M19 -> 594512
K21: Compra | L21: 70440 | M21: 0
K22: Consumo | L22: 72300 | M22: =433062-59808 -> 373254 | N22: 372830 | O22: =M22-N22 -> 424
K23: Saldo em 31/03 | L23: =L20+L21-L22 -> 18100 | M23: =M20-M22+M21 -> 221258

Sheet CONCILIÇÃO_SEM_VASILHAME
L1: Valor Estoque Físico | O1: Valor Estoque Sistema | T1: Acuracidade Qualitativa | U1: Custo Diferença | V1: Percentual Diferença
L2: =SUBTOTAL(9,BASE_CONCILI12[CUSTO FÍSICO]) -> 395987.7 | O2: =SUBTOTAL(9,BASE_CONCILI12[CUSTO SISTEMA]) -> 0 | T2: =(COUNTIF(BASE_CONCILI12[30/jun],">0")-COUNTIF(BASE_CONCILI12[ACURACIDADE],">1,05")-COUNTIF(BASE_CONCILI12[ACURACIDADE],"<0,95"))/COUNTIF(BASE_CONCILI12[30/jun],">0") -> 1 | U2: =SUBTOTAL(9,BASE_CONCILI12[CUSTO DIVERGÊNCIA]) -> 0 | V2: =U2/O2 -> #DIV/0!
A4: CÓD. SAIB | B4: CÓD. PRODUTO | C4: DESCRIÇÃO | D4: CLASSE | E4: 30/mai | F4: CONSUMO REAL | G4: CONSUMO TEORICO | H4: DIFERENÇA CONSUMO | I4: RECEBIMENTO | J4: TRANSFERÊNCIA | K4: QTDE. FINAL | L4: 30/jun | M4: CUSTO FÍSICO | N4: 01/fev | O4: SISTEMA | P4: CUSTO SISTEMA | Q4: DIFERENÇA ANTERIOR | R4: DIFERENÇA ATUAL | S4: DIFERENÇA MÊS | T4: CUSTO MP (UN) | U4: CUSTO DIVERGÊNCIA | V4: ACURACIDADE | W4: DIFERENÇA VALOR | X4: OBSERVAÇÃO
A5: 55 | C5: ACUCAR CRISTAL | D5: AÇUCAR | E5: =VLOOKUP(BASE_CONCILI12[[#This Row],[CÓD. SAIB]],CONT_ANTE!A:D,4,0) -> #N/A | F5: =SUMIF(#REF!,BASE_CONCILI12[[#This Row],[CÓD. SAIB]],#REF!) -> #REF! | G5: =SUMIF(#REF!,BASE_CONCILI12[[#This Row],[CÓD. SAIB]],#REF!) -> #REF! | H5: =BASE_CONCILI12[[#This Row],[CONSUMO REAL]]-BASE_CONCILI12[[#This Row],[CONSUMO TEORICO]] -> #REF! | I5: =SUMIF(#REF!,BASE_CONCILI12[[#This Row],[CÓD. SAIB]],#REF!) -> #REF! | J5: =SUMIF(#REF!,BASE_CONCILI12[[#This Row],[CÓD. SAIB]],#REF!) -> #REF! | K5: =BASE_CONCILI12[[#This Row],[30/mai]]+BASE_CONCILI12[[#This Row],[RECEBIMENTO]]-BASE_CONCILI12[[#This Row],[TRANSFERÊNCIA]]-BASE_CONCILI12[[#This Row],[CONSUMO REAL]] -> #N/A | L5: =IFERROR(VLOOKUP(BASE_CONCILI12[[#This Row],[CÓD. SAIB]],BASE_CONTAG[[LAVRE]:[CONTAGEM FINAL]],7,0),0) -> 70 | M5: =IFERROR(SUM(BASE_CONCILI12[[#This Row],[30/jun]]*BASE_CONCILI12[[#This Row],[CUSTO MP (UN)]]),0) -> 0 | N5: =IFERROR(VLOOKUP(BASE_CONCILI12[[#This Row],[CÓD. SAIB]],BASE_CONTAG[],5,0),"") -> 70 | O5: =SUMIF(SISTEMA!#REF!,BASE_CONCILI12[[#This Row],[CÓD. SAIB]],SISTEMA!#REF!) -> #REF! | P5: =IFERROR(SUM(BASE_CONCILI12[[#This Row],[SISTEMA]]*BASE_CONCILI12[[#This Row],[CUSTO MP (UN)]]),0) -> 0 | Q5: =IFERROR(VLOOKUP(BASE_CONCILI12[[#This Row],[CÓD. SAIB]],BASE_DIFERENÇA[],4,0),"0") -> 0 | R5: =BASE_CONCILI12[[#This Row],[30/jun]]-BASE_CONCILI12[[#This Row],[SISTEMA]] -> #REF! | S5: =IFERROR(BASE_CONCILI12[[#This Row],[DIFERENÇA ANTERIOR]]-BASE_CONCILI12[[#This Row],[DIFERENÇA ATUAL]],"-") -> - | T5: =VLOOKUP(BASE_CONCILI12[[#This Row],[CÓD. SAIB]],CUSTO!A:C,3,0) -> 0 | U5: =IFERROR(SUM(BASE_CONCILI12[[#This Row],[DIFERENÇA ATUAL]]*BASE_CONCILI12[[#This Row],[CUSTO MP (UN)]]),0) -> 0 | V5: =IFERROR(BASE_CONCILI12[[#This Row],[30/jun]]/BASE_CONCILI12[[#This Row],[SISTEMA]],"") | W5: =IFERROR(BASE_CONCILI12[[#This Row],[DIFERENÇA MÊS]]*BASE_CONCILI12[[#This Row],[CUSTO MP (UN)]],"-") -> - | X5: OK
A6: 31395 | C6: ETANOL HIDRATADO | D6: ALCOOL | E6: =VLOOKUP(BASE_CONCILI12[[#This Row],[CÓD. SAIB]],CONT_ANTE!A:D,4,0) -> #N/A | F6: =SUMIF(#REF!,BASE_CONCILI12[[#This Row],[CÓD. SAIB]],#REF!) -> #REF! | G6: =SUMIF(#REF!,BASE_CONCILI12[[#This Row],[CÓD. SAIB]],#REF!) -> #REF! | H6: =BASE_CONCILI12[[#This Row],[CONSUMO REAL]]-BASE_CONCILI12[[#This Row],[CONSUMO TEORICO]] -> #REF! | I6: =SUMIF(#REF!,BASE_CONCILI12[[#This Row],[CÓD. SAIB]],#REF!) -> #REF! | J6: =SUMIF(#REF!,BASE_CONCILI12[[#This Row],[CÓD. SAIB]],#REF!) -> #REF! | K6: =BASE_CONCILI12[[#This Row],[30/mai]]+BASE_CONCILI12[[#This Row],[RECEBIMENTO]]-BASE_CONCILI12[[#This Row],[TRANSFERÊNCIA]]-BASE_CONCILI12[[#This Row],[CONSUMO REAL]] -> #N/A | L6: =IFERROR(VLOOKUP(BASE_CONCILI12[[#This Row],[CÓD. SAIB]],BASE_CONTAG[[LAVRE]:[CONTAGEM FINAL]],7,0),0) -> 110 | M6: =IFERROR(SUM(BASE_CONCILI12[[#This Row],[30/jun]]*BASE_CONCILI12[[#This Row],[CUSTO MP (UN)]]),0) -> 0 | N6: =IFERROR(VLOOKUP(BASE_CONCILI12[[#This Row],[CÓD. SAIB]],BASE_CONTAG[],5,0),"") -> 110 | O6: =SUMIF(SISTEMA!#REF!,BASE_CONCILI12[[#This Row],[CÓD. SAIB]],SISTEMA!#REF!) -> #REF! | P6: =IFERROR(SUM(BASE_CONCILI12[[#This Row],[SISTEMA]]*BASE_CONCILI12[[#This Row],[CUSTO MP (UN)]]),0) -> 0 | Q6: =IFERROR(VLOOKUP(BASE_CONCILI12[[#This Row],[CÓD. SAIB]],BASE_DIFERENÇA[],4,0),"0") -> 0 | R6: =BASE_CONCILI12[[#This Row],[30/jun]]-BASE_CONCILI12[[#This Row],[SISTEMA]] -> #REF! | S6: =IFERROR(BASE_CONCILI12[[#This Row],[DIFERENÇA ANTERIOR]]-BASE_CONCILI12[[#This Row],[DIFERENÇA ATUAL]],"-") -> - | T6: =VLOOKUP(BASE_CONCILI12[[#This Row],[CÓD. SAIB]],CUSTO!A:C,3,0) -> 0 | U6: =IFERROR(SUM(BASE_CONCILI12[[#This Row],[DIFERENÇA ATUAL]]*BASE_CONCILI12[[#This Row],[CUSTO MP (UN)]]),0) -> 0 | V6: =IFERROR(BASE_CONCILI12[[#This Row],[30/jun]]/BASE_CONCILI12[[#This Row],[SISTEMA]],"") | W6: =IFERROR(BASE_CONCILI12[[#This Row],[DIFERENÇA MÊS]]*BASE_CONCILI12[[#This Row],[CUSTO MP (UN)]],"-") -> - | X6: OK
A7: 31352 | C7: AA ENERGY FLAVOR | D7: AROMA | E7: =VLOOKUP(BASE_CONCILI12[[#This Row],[CÓD. SAIB]],CONT_ANTE!A:D,4,0) -> #N/A | F7: =SUMIF(#REF!,BASE_CONCILI12[[#This Row],[CÓD. SAIB]],#REF!) -> #REF! | G7: =SUMIF(#REF!,BASE_CONCILI12[[#This Row],[CÓD. SAIB]],#REF!) -> #REF! | H7: =BASE_CONCILI12[[#This Row],[CONSUMO REAL]]-BASE_CONCILI12[[#This Row],[CONSUMO TEORICO]] -> #REF! | I7: =SUMIF(#REF!,BASE_CONCILI12[[#This Row],[CÓD. SAIB]],#REF!) -> #REF! | J7: =SUMIF(#REF!,BASE_CONCILI12[[#This Row],[CÓD. SAIB]],#REF!) -> #REF! | K7: =BASE_CONCILI12[[#This Row],[30/mai]]+BASE_CONCILI12[[#This Row],[RECEBIMENTO]]-BASE_CONCILI12[[#This Row],[TRANSFERÊNCIA]]-BASE_CONCILI12[[#This Row],[CONSUMO REAL]] -> #N/A | L7: =IFERROR(VLOOKUP(BASE_CONCILI12[[#This Row],[CÓD. SAIB]],BASE_CONTAG[[LAVRE]:[CONTAGEM FINAL]],7,0),0) -> 0 | M7: =IFERROR(SUM(BASE_CONCILI12[[#This Row],[30/jun]]*BASE_CONCILI12[[#This Row],[CUSTO MP (UN)]]),0) -> 0 | N7: =IFERROR(VLOOKUP(BASE_CONCILI12[[#This Row],[CÓD. SAIB]],BASE_CONTAG[],5,0),"") -> 0 | O7: =SUMIF(SISTEMA!#REF!,BASE_CONCILI12[[#This Row],[CÓD. SAIB]],SISTEMA!#REF!) -> #REF! | P7: =IFERROR(SUM(BASE_CONCILI12[[#This Row],[SISTEMA]]*BASE_CONCILI12[[#This Row],[CUSTO MP (UN)]]),0) -> 0 | Q7: =IFERROR(VLOOKUP(BASE_CONCILI12[[#This Row],[CÓD. SAIB]],BASE_DIFERENÇA[],4,0),"0") -> 0 | R7: =BASE_CONCILI12[[#This Row],[30/jun]]-BASE_CONCILI12[[#This Row],[SISTEMA]] -> #REF! | S7: =IFERROR(BASE_CONCILI12[[#This Row],[DIFERENÇA ANTERIOR]]-BASE_CONCILI12[[#This Row],[DIFERENÇA ATUAL]],"-") -> - | T7: =VLOOKUP(BASE_CONCILI12[[#This Row],[CÓD. SAIB]],CUSTO!A:C,3,0) -> 31352CB01 | U7: =IFERROR(SUM(BASE_CONCILI12[[#This Row],[DIFERENÇA ATUAL]]*BASE_CONCILI12[[#This Row],[CUSTO MP (UN)]]),0) -> 0 | V7: =IFERROR(BASE_CONCILI12[[#This Row],[30/jun]]/BASE_CONCILI12[[#This Row],[SISTEMA]],"") | W7: =IFERROR(BASE_CONCILI12[[#This Row],[DIFERENÇA MÊS]]*BASE_CONCILI12[[#This Row],[CUSTO MP (UN)]],"-") -> - | X7: OK
A8: 2089 | C8: AROMA ART DE TUTTI FRUTTI RB 10766 | D8: AROMA | E8: =VLOOKUP(BASE_CONCILI12[[#This Row],[CÓD. SAIB]],CONT_ANTE!A:D,4,0) -> #N/A | F8: =SUMIF(#REF!,BASE_CONCILI12[[#This Row],[CÓD. SAIB]],#REF!) -> #REF! | G8: =SUMIF(#REF!,BASE_CONCILI12[[#This Row],[CÓD. SAIB]],#REF!) -> #REF! | H8: =BASE_CONCILI12[[#This Row],[CONSUMO REAL]]-BASE_CONCILI12[[#This Row],[CONSUMO TEORICO]] -> #REF! | I8: =SUMIF(#REF!,BASE_CONCILI12[[#This Row],[CÓD. SAIB]],#REF!) -> #REF! | J8: =SUMIF(#REF!,BASE_CONCILI12[[#This Row],[CÓD. SAIB]],#REF!) -> #REF! | K8: =BASE_CONCILI12[[#This Row],[30/mai]]+BASE_CONCILI12[[#This Row],[RECEBIMENTO]]-BASE_CONCILI12[[#This Row],[TRANSFERÊNCIA]]-BASE_CONCILI12[[#This Row],[CONSUMO REAL]] -> #N/A | L8: =IFERROR(VLOOKUP(BASE_CONCILI12[[#This Row],[CÓD. SAIB]],BASE_CONTAG[[LAVRE]:[CONTAGEM FINAL]],7,0),0) -> 0 | M8: =IFERROR(SUM(BASE_CONCILI12[[#This Row],[30/jun]]*BASE_CONCILI12[[#This Row],[CUSTO MP (UN)]]),0) -> 0 | N8: =IFERROR(VLOOKUP(BASE_CONCILI12[[#This Row],[CÓD. SAIB]],BASE_CONTAG[],5,0),"") | O8: =SUMIF(SISTEMA!#REF!,BASE_CONCILI12[[#This Row],[CÓD. SAIB]],SISTEMA!#REF!) -> #REF! | P8: =IFERROR(SUM(BASE_CONCILI12[[#This Row],[SISTEMA]]*BASE_CONCILI12[[#This Row],[CUSTO MP (UN)]]),0) -> 0 | Q8: =IFERROR(VLOOKUP(BASE_CONCILI12[[#This Row],[CÓD. SAIB]],BASE_DIFERENÇA[],4,0),"0") -> 0 | R8: =BASE_CONCILI12[[#This Row],[30/jun]]-BASE_CONCILI12[[#This Row],[SISTEMA]] -> #REF! | S8: =IFERROR(BASE_CONCILI12[[#This Row],[DIFERENÇA ANTERIOR]]-BASE_CONCILI12[[#This Row],[DIFERENÇA ATUAL]],"-") -> - | T8: =VLOOKUP(BASE_CONCILI12[[#This Row],[CÓD. SAIB]],CUSTO!A:C,3,0) -> 2089CB01 | U8: =IFERROR(SUM(BASE_CONCILI12[[#This Row],[DIFERENÇA ATUAL]]*BASE_CONCILI12[[#This Row],[CUSTO MP (UN)]]),0) -> 0 | V8: =IFERROR(BASE_CONCILI12[[#This Row],[30/jun]]/BASE_CONCILI12[[#This Row],[SISTEMA]],"") | W8: =IFERROR(BASE_CONCILI12[[#This Row],[DIFERENÇA MÊS]]*BASE_CONCILI12[[#This Row],[CUSTO MP (UN)]],"-") -> - | X8: OK
