Workbook

Sheet ANALISE
A3: Rótulos de Linha | B3: Soma de DIFERENÇA VALOR
A4: ROTULO | B4: -7616644.2
A5: ELABORAÇÃO | B5: -1848261.1
A6: RÓTULO | B6: -1393112.7
A7: FILME | B7: -155369
A8: MALTE | B8: -62468.37
A9: VASILHAME | B9: -19390.82
A10: CERVEJARIA | B10: -11524.321
A11: AÇUCAR | B11: -5345.3953
A12: Insumo Terc. | B12: 0
A13: VINHO | B13: 0
A14: INDUSTRIALIZAÇÃO | B14: 0
A15: LACRE | B15: 4.26173
... A35: Total Geral | B35: 2347321.2

Sheet KPI
B2: VALOR ESTOQUE FÍSICO (MP) | M2: CUSTO (R$) DIVERGÊNCIA (MP)
B3: MÊS | C3: VALOR (R$) | M3: MÊS | N3: VALOR (R$)
B4: JANEIRO | C4: 14484679 | M4: JANEIRO | N4: 118144.18
B5: FEVEREIRO | C5: 13521013 | M5: FEVEREIRO | N5: 267353.14
B6: MARÇO | C6: 14243064 | M6: MARÇO | N6: 281640.56
B7: ABRIL | C7: 12258289 | M7: ABRIL | N7: 206892.35
B8: MAIO | C8: 9350849.2 | M8: MAIO | N8: 85994.001
B9: JUNHO | C9: 8710025.7 | M9: JUNHO | N9: 100512.52
B10: JULHO | M10: JULHO
B11: AGOSTO | M11: AGOSTO
B12: SETEMBRO | M12: SETEMBRO
B13: OUTUBRO | C13: 9786201.2 | M13: OUTUBRO | N13: =C13-C29 -> -823245.49
B14: NOVEMBRO | C14: 11626525 | M14: NOVEMBRO | N14: =C14-C30 -> 47666.517
B15: DEZEMBRO | C15: 11050986 | M15: DEZEMBRO | N15: 55057.669
B16: MÉDIA | C16: =AVERAGE(C4:C15) -> 11670181 | M16: MÉDIA | N16: =AVERAGE(N4:N15) -> 37779.494
B18: VALOR ESTOQUE SISTEMA (MP) | M18: % DIVERGÊNCIA (MP)
B19: MÊS | C19: VALOR (R$) | M19: MÊS | N19: VALOR (R$)
B20: JANEIRO | C20: 14366535 | M20: JANEIRO | N20: 0.0082235682
B21: FEVEREIRO | C21: 13253660 | M21: FEVEREIRO | N21: 0.020172023
B22: MARÇO | C22: 13961423 | M22: MARÇO | N22: 0.020172769
B23: ABRIL | C23: 12051397 | M23: ABRIL | N23: 0.017167499
B24: MAIO | C24: 9264855.2 | M24: MAIO | N24: 0.0092817426
B25: JUNHO | C25: 8609513.2 | M25: JUNHO | N25: 0.011674588
B26: JULHO | M26: JULHO
B27: AGOSTO | M27: AGOSTO
B28: SETEMBRO | M28: SETEMBRO
B29: OUTUBRO | C29: 10609447 | M29: OUTUBRO | N29: =IFERROR(N13/C29,"") -> -0.077595516
B30: NOVEMBRO | C30: 11578858 | M30: NOVEMBRO | N30: =IFERROR(N14/C30,"") -> 0.0041166855
B31: DEZEMBRO | C31: 10995928 | M31: DEZEMBRO | N31: 0.0050070962
B32: MÉDIA | C32: =AVERAGE(C20:C31) -> 11632402 | M32: MÉDIA | N32: =AVERAGE(N20:N31) -> 0.0020244951
B34: VALOR ESTOQUE FÍSICO (PA) | M34: ACURACIDADE QUALITATIVA (MP)
B35: MÊS | C35: VALOR (R$) | M35: MÊS | N35: %
B36: JANEIRO | C36: 2390297.8 | M36: JANEIRO | N36: 0.64661654
B37: FEVEREIRO | C37: 3642342.8 | M37: FEVEREIRO | N37: 0.62737643
B38: MARÇO | C38: 1858028.3 | M38: MARÇO | N38: 0.6627907
B39: ABRIL | C39: 1454970.4 | M39: ABRIL | N39: 0.70342205
B40: MAIO | C40: 1203577.7 | M40: MAIO | N40: 0.73705179
B41: JUNHO | C41: 2240566.9 | M41: JUNHO | N41: 0.74501992
B42: JULHO | M42: JULHO
B43: AGOSTO | M43: AGOSTO
...

Sheet BASE PRODUTOS
A1: BASE DE CADASTRO TOTVS
A2: Codigo | B2: Descricao | C2: Tipo | D2: Unidade | E2: Fator Conv.
A3: 2000010001 | B3: AT MALDIVES 12X250ML | C3: PA | D3: FD | E3: 12
A4: 2000010002 | B4: REFRIKO COLA 12X200ML | C4: PA | D4: FD | E4: 12
A5: 2000010003 | B5: REFRIKO COLA 12X500ML | C5: PA | D5: FD | E5: 12
A6: 2000010004 | B6: REFRIKO COLA 4X3LT | C6: PA | D6: FD | E6: 4
A7: 2000010005 | B7: REFRIKO COLA 6X2LT | C7: PA | D7: FD | E7: 6
A8: 2000010006 | B8: REFRIKO COLA 6X350ML | C8: PA | D8: FD | E8: 6
A9: 2000010007 | B9: REFRIKO FRAMBOESA 6X2LT | C9: PA | D9: FD | E9: 6
A10: 2000010008 | B10: REFRIKO GUARANA 12X200ML | C10: PA | D10: FD | E10: 12
A11: 2000010009 | B11: REFRIKO GUARANA 12X500ML | C11: PA | D11: FD | E11: 12
A12: 2000010010 | B12: REFRIKO GUARANA 24X600ML - RET | C12: PA | D12: CX | E12: 24
A13: 2000010011 | B13: REFRIKO GUARANA 4X3LT | C13: PA | D13: FD | E13: 4
A14: 2000010012 | B14: REFRIKO GUARANA 6X2LT | C14: PA | D14: FD | E14: 6
... A13198: 9999990006 | B13198: REEMBOLSO DE VIAGEM | C13198: OU | D13198: UN | E13198: 0
A13199: FL03040001 | B13199: FILTRO DE PAPEL MELITTA | C13199: MC | D13199: UN | E13199: 0
A13200: 2701010044 | B13200: ROTULO SLEEVE FURIOSO TANGERINA E LIMAO ZERO 473ML | E13200: 0.0020921

Sheet CONCILIÇÃO_COM_CERVEJA
M1: Valor Estoque Físico | Q1: Valor Estoque Sistema | V1: Acuracidade Qualitativa | W1: Custo Diferença | X1: Percentual Diferença | Y1: Acuracidade
M2: =SUBTOTAL(9,N5:N1048576) -> 13706820 | Q2: =SUBTOTAL(9,CONCILIÇÃO_COM_CERVEJA!$R$5:$R$373) -> 13592060 | V2: =(COUNTIF(CONCILIÇÃO_COM_CERVEJA!$M$5:$M$373,">0")-COUNTIF(CONCILIÇÃO_COM_CERVEJA!$X$5:$X$373,">1,05")-COUNTIF(CONCILIÇÃO_COM_CERVEJA!$X$5:$X$373,"<0,95"))/COUNTIF(CONCILIÇÃO_COM_CERVEJA!$M$5:$M$373,">0") -> -0.053497942 | W2: =SUBTOTAL(9,W5:W1048576) -> 114759.67 | X2: =W2/Q2 -> 0.0084431405 | Y2: =1-X2 -> 0.99155686
A4: CÓD. PRODUTO | B4: CODIGO NOVO | C4: DESCRIÇÃO | D4: Estoque Inicial | E4: Total de entrada | F4: Consumo total mês 8 (RxS) | G4: Total saidas | H4: Teorico Final | I4: CLASSE | J4: Fator Conv. | K4: 46265 | L4: ? | M4: Contagem | N4: CUSTO FISICO | O4: SIST COD KG | P4: SIST COD UND | Q4: SALDO SISTEMA TOTAL | R4: CUSTO SISTEMA | S4: DIFERENÇA ANTERIOR | T4: Diferença atual | U4: Diveregencia mês anterior | V4: CUSTO MP (UN) | W4: CUSTO DIVERGÊNCIA | X4: ACURACIDADE | Y4: DIFERENÇA VALOR | Z4: OBS
A5: 2701080001 | B5: - | C5: ACUCAR CRISTAL | D5: 63047.67 | E5: =IFERROR(IFERROR(VLOOKUP(B5,[1]Planilha1!$A$4:$C$277,3,0),VLOOKUP(A5,[1]Planilha1!$A$4:$C$277,3,0)),0) -> 229233.29 | F5: =IFERROR(IFERROR(VLOOKUP(A5,[2]Planilha1!$A$4:$C$258,3,0),VLOOKUP(B5,[2]Planilha1!$A$4:$C$258,3,0)),0) -> 165059.43 | G5: =IFERROR(IFERROR(VLOOKUP(A5,[1]Planilha1!$A$4:$D$277,4,0),VLOOKUP(B5,[1]Planilha1!$A$4:$D$277,4,0)),0) -> 230063.25 | H5: =D5+E5-G5 -> 62217.709 | I5: AÇUCAR | J5: 1 | K5: =VLOOKUP(A5,CONT_ANTE!A:D,4,0) -> 55200 | L5: =IF(AND(F5=0,K5<>M5),"!@##@!","ok") -> ok | M5: =IFERROR(VLOOKUP(A5,CONTAGEM!B:G,6,0),VLOOKUP(B5,CONTAGEM!B:G,6,0)) -> 50000 | N5: =IFERROR(SUM(M5*V5),0) -> 90292.635 | O5: =SUMIF(SISTEMA!B:B,A5,SISTEMA!I:I)/J5 -> 76826.709 | P5: =SUMIF(SISTEMA!B:B,B5,SISTEMA!I:I) -> 0 | Q5: =O5+P5 -> 76826.709 | R5: =IFERROR(SUM(Q5*V5),0) -> 138737.72 | S5: =IFERROR(VLOOKUP(A5,DIF_ANTE!A:D,4,0),"0")/J5 -> -7847.67 | T5: =M5-Q5 -> -26826.709 | U5: =T5-S5 -> -18979.039 | V5: =IFERROR(VLOOKUP(A5,CUSTO!A:C,3,0),VLOOKUP(B5,CUSTO!A:C,3,0)) -> 1.8058527 | W5: =IFERROR(SUM(T5*V5),0) -> -48445.086 | X5: =IFERROR(T5/Q5,"") -> -0.34918467 | Y5: =IFERROR(U5*V5,"-") -> -34273.35 | Z5: ok
A6: 2701170002 | B6: - | C6: ETANOL NEUTRO ALCOOL ETILICO POTAVEL 96° | D6: 65761 | E6: =IFERROR(IFERROR(VLOOKUP(B6,[1]Planilha1!$A$4:$C$277,3,0),VLOOKUP(A6,[1]Planilha1!$A$4:$C$277,3,0)),0) -> 45000 | F6: =IFERROR(IFERROR(VLOOKUP(A6,[2]Planilha1!$A$4:$C$258,3,0),VLOOKUP(B6,[2]Planilha1!$A$4:$C$258,3,0)),0) -> 52758 | G6: =IFERROR(IFERROR(VLOOKUP(A6,[1]Planilha1!$A$4:$D$277,4,0),VLOOKUP(B6,[1]Planilha1!$A$4:$D$277,4,0)),0) -> 52758 | H6: =D6+E6-G6 -> 58003 | I6: ALCOOL | J6: 1 | K6: =VLOOKUP(A6,CONT_ANTE!A:D,4,0) -> 52674 | L6: =IF(AND(F6=0,K6<>M6),"!@##@!","ok") -> ok | M6: =IFERROR(VLOOKUP(A6,CONTAGEM!B:G,6,0),VLOOKUP(B6,CONTAGEM!B:G,6,0)) -> 45000 | N6: =IFERROR(SUM(M6*V6),0) -> 169254.89 | O6: =SUMIF(SISTEMA!B:B,A6,SISTEMA!I:I)/J6 -> 46744 | P6: =SUMIF(SISTEMA!B:B,B6,SISTEMA!I:I) -> 0 | Q6: =O6+P6 -> 46744 | R6: =IFERROR(SUM(Q6*V6),0) -> 175814.46 | S6: =IFERROR(VLOOKUP(A6,DIF_ANTE!A:D,4,0),"0")/J6 -> -13087 | T6: =M6-Q6 -> -1744 | U6: =T6-S6 -> 11343 | V6: =IFERROR(VLOOKUP(A6,CUSTO!A:C,3,0),VLOOKUP(B6,CUSTO!A:C,3,0)) -> 3.7612199 | W6: =IFERROR(SUM(T6*V6),0) -> -6559.5674 | X6: =IFERROR(T6/Q6,"") -> -0.037309601 | Y6: =IFERROR(U6*V6,"-") -> 42663.517 | Z6: ok
A7: 2701050004 | B7: - | C7: AROMA ARTIFICIAL ENERGY SYMRISE | D7: 0 | E7: =IFERROR(IFERROR(VLOOKUP(B7,[1]Planilha1!$A$4:$C$277,3,0),VLOOKUP(A7,[1]Planilha1!$A$4:$C$277,3,0)),0) -> 0 | F7: =IFERROR(IFERROR(VLOOKUP(A7,[2]Planilha1!$A$4:$C$258,3,0),VLOOKUP(B7,[2]Planilha1!$A$4:$C$258,3,0)),0) -> 0 | G7: =IFERROR(IFERROR(VLOOKUP(A7,[1]Planilha1!$A$4:$D$277,4,0),VLOOKUP(B7,[1]Planilha1!$A$4:$D$277,4,0)),0) -> 0 | H7: =D7+E7-G7 -> 0 | I7: AROMA | J7: 1 | K7: =VLOOKUP(A7,CONT_ANTE!A:D,4,0) -> 0 | L7: =IF(AND(F7=0,K7<>M7),"!@##@!","ok") -> ok | M7: =IFERROR(VLOOKUP(A7,CONTAGEM!B:G,6,0),VLOOKUP(B7,CONTAGEM!B:G,6,0)) -> 0 | N7: =IFERROR(SUM(M7*V7),0) -> 0 | O7: =SUMIF(SISTEMA!B:B,A7,SISTEMA!I:I)/J7 -> 0 | P7: =SUMIF(SISTEMA!B:B,B7,SISTEMA!I:I) -> 0 | Q7: =O7+P7 -> 0 | R7: =IFERROR(SUM(Q7*V7),0) -> 0 | S7: =IFERROR(VLOOKUP(A7,DIF_ANTE!A:D,4,0),"0")/J7 -> 0 | T7: =M7-Q7 -> 0 | U7: =T7-S7 -> 0 | V7: =IFERROR(VLOOKUP(A7,CUSTO!A:C,3,0),VLOOKUP(B7,CUSTO!A:C,3,0)) -> 103.63169 | W7: =IFERROR(SUM(T7*V7),0) -> 0 | X7: =IFERROR(T7/Q7,"") | Y7: =IFERROR(U7*V7,"-") -> 0 | Z7: ok
A8: 2701050008 | B8: - | C8: AROMA ARTIFICIAL FRUTAS TROPICAIS MONARCH | D8: 241.65 | E8: =IFERROR(IFERROR(VLOOKUP(B8,[1]Planilha1!$A$4:$C$277,3,0),VLOOKUP(A8,[1]Planilha1!$A$4:$C$277,3,0)),0) -> 0 | F8: =IFERROR(IFERROR(VLOOKUP(A8,[2]Planilha1!$A$4:$C$258,3,0),VLOOKUP(B8,[2]Planilha1!$A$4:$C$258,3,0)),0) -> 112.73 | G8: =IFERROR(IFERROR(VLOOKUP(A8,[1]Planilha1!$A$4:$D$277,4,0),VLOOKUP(B8,[1]Planilha1!$A$4:$D$277,4,0)),0) -> 112.73 | H8: =D8+E8-G8 -> 128.92 | I8: AROMA | J8: 1 | K8: =VLOOKUP(A8,CONT_ANTE!A:D,4,0) -> 240 | L8: =IF(AND(F8=0,K8<>M8),"!@##@!","ok") -> ok | M8: =IFERROR(VLOOKUP(A8,CONTAGEM!B:G,6,0),VLOOKUP(B8,CONTAGEM!B:G,6,0)) -> 142.5 | N8: =IFERROR(SUM(M8*V8),0) -> 17987.775 | O8: =SUMIF(SISTEMA!B:B,A8,SISTEMA!I:I)/J8 -> 128.92 | P8: =SUMIF(SISTEMA!B:B,B8,SISTEMA!I:I) -> 0 | Q8: =O8+P8 -> 128.92 | R8: =IFERROR(SUM(Q8*V8),0) -> 16273.572 | S8: =IFERROR(VLOOKUP(A8,DIF_ANTE!A:D,4,0),"0")/J8 -> -1.65 | T8: =M8-Q8 -> 13.58 | U8: =T8-S8 -> 15.23 | V8: =IFERROR(VLOOKUP(A8,CUSTO!A:C,3,0),VLOOKUP(B8,CUSTO!A:C,3,0)) -> 126.23 | W8: =IFERROR(SUM(T8*V8),0) -> 1714.2034 | X8: =IFERROR(T8/Q8,"") -> 0.10533664 | Y8: =IFERROR(U8*V8,"-") -> 1922.4829 | Z8: ok
A9: 2701050009 | B9: - | C9: AROMA ARTIFICIAL GUARANA DUAS RODAS | D9: 0 | E9: =IFERROR(IFERROR(VLOOKUP(B9,[1]Planilha1!$A$4:$C$277,3,0),VLOOKUP(A9,[1]Planilha1!$A$4:$C$277,3,0)),0) -> 0 | F9: =IFERROR(IFERROR(VLOOKUP(A9,[2]Planilha1!$A$4:$C$258,3,0),VLOOKUP(B9,[2]Planilha1!$A$4:$C$258,3,0)),0) -> 0 | G9: =IFERROR(IFERROR(VLOOKUP(A9,[1]Planilha1!$A$4:$D$277,4,0),VLOOKUP(B9,[1]Planilha1!$A$4:$D$277,4,0)),0) -> 0 | H9: =D9+E9-G9 -> 0 | I9: AROMA | J9: 1 | K9: =VLOOKUP(A9,CONT_ANTE!A:D,4,0) -> 0 | L9: =IF(AND(F9=0,K9<>M9),"!@##@!","ok") -> ok | M9: =IFERROR(VLOOKUP(A9,CONTAGEM!B:G,6,0),VLOOKUP(B9,CONTAGEM!B:G,6,0)) -> 0 | N9: =IFERROR(SUM(M9*V9),0) -> 0 | O9: =SUMIF(SISTEMA!B:B,A9,SISTEMA!I:I)/J9 -> 0 | P9: =SUMIF(SISTEMA!B:B,B9,SISTEMA!I:I) -> 0 | Q9: =O9+P9 -> 0 | R9: =IFERROR(SUM(Q9*V9),0) -> 0 | S9: =IFERROR(VLOOKUP(A9,DIF_ANTE!A:D,4,0),"0")/J9 -> 0 | T9: =M9-Q9 -> 0 | U9: =T9-S9 -> 0 | V9: =IFERROR(VLOOKUP(A9,CUSTO!A:C,3,0),VLOOKUP(B9,CUSTO!A:C,3,0)) -> 49.614813 | W9: =IFERROR(SUM(T9*V9),0) -> 0 | X9: =IFERROR(T9/Q9,"") | Y9: =IFERROR(U9*V9,"-") -> 0 | Z9: ok
A10: 2701050035 | B10: - | C10: AROMA ARTIFICIAL GUARANA IFB | D10: 812.43 | E10: =IFERROR(IFERROR(VLOOKUP(B10,[1]Planilha1!$A$4:$C$277,3,0),VLOOKUP(A10,[1]Planilha1!$A$4:$C$277,3,0)),0) -> 0 | F10: =IFERROR(IFERROR(VLOOKUP(A10,[2]Planilha1!$A$4:$C$258,3,0),VLOOKUP(B10,[2]Planilha1!$A$4:$C$258,3,0)),0) -> 92.43 | G10: =IFERROR(IFERROR(VLOOKUP(A10,[1]Planilha1!$A$4:$D$277,4,0),VLOOKUP(B10,[1]Planilha1!$A$4:$D$277,4,0)),0) -> 77.52 | H10: =D10+E10-G10 -> 734.91 | I10: AROMA | J10: 1 | K10: =VLOOKUP(A10,CONT_ANTE!A:D,4,0) -> 797 | L10: =IF(AND(F10=0,K10<>M10),"!@##@!","ok") -> ok | M10: =IFERROR(VLOOKUP(A10,CONTAGEM!B:G,6,0),VLOOKUP(B10,CONTAGEM!B:G,6,0)) -> 720 | N10: =IFERROR(SUM(M10*V10),0) -> 27129.6 | O10: =SUMIF(SISTEMA!B:B,A10,SISTEMA!I:I)/J10 -> 734.91 | P10: =SUMIF(SISTEMA!B:B,B10,SISTEMA!I:I) -> 0 | Q10: =O10+P10 -> 734.91 | R10: =IFERROR(SUM(Q10*V10),0) -> 27691.409 | S10: =IFERROR(VLOOKUP(A10,DIF_ANTE!A:D,4,0),"0")/J10 -> -15.43 | T10: =M10-Q10 -> -14.91 | U10: =T10-S10 -> 0.52 | V10: =IFERROR(VLOOKUP(A10,CUSTO!A:C,3,0),VLOOKUP(B10,CUSTO!A:C,3,0)) -> 37.68 | W10: =IFERROR(SUM(T10*V10),0) -> -561.8088 | X10: =IFERROR(T10/Q10,"") -> -0.020288199 | Y10: =IFERROR(U10*V10,"-") -> 19.5936 | Z10: OK
A11: 2701050017 | B11: - | C11: AROMA ARTIFICIAL MELANCIA DUAS RODAS | D11: 204.1 | E11: =IFERROR(IFERROR(VLOOKUP(B11,[1]Planilha1!$A$4:$C$277,3,0),VLOOKUP(A11,[1]Planilha1!$A$4:$C$277,3,0)),0) -> 500 | F11: =IFERROR(IFERROR(VLOOKUP(A11,[2]Planilha1!$A$4:$C$258,3,0),VLOOKUP(B11,[2]Planilha1!$A$4:$C$258,3,0)),0) -> 150.54 | G11: =IFERROR(IFERROR(VLOOKUP(A11,[1]Planilha1!$A$4:$D$277,4,0),VLOOKUP(B11,[1]Planilha1!$A$4:$D$277,4,0)),0) -> 550.54 | H11: =D11+E11-G11 -> 153.56 | I11: AROMA | J11: 1 | K11: =VLOOKUP(A11,CONT_ANTE!A:D,4,0) -> 184 | L11: =IF(AND(F11=0,K11<>M11),"!@##@!","ok") -> ok | M11: =IFERROR(VLOOKUP(A11,CONTAGEM!B:G,6,0),VLOOKUP(B11,CONTAGEM!B:G,6,0)) -> 130 | N11: =IFERROR(SUM(M11*V11),0) -> 4078.399 | O11: =SUMIF(SISTEMA!B:B,A11,SISTEMA!I:I)/J11 -> 153.56 | P11: =SUMIF(SISTEMA!B:B,B11,SISTEMA!I:I) -> 0 | Q11: =O11+P11 -> 153.56 | R11: =IFERROR(SUM(Q11*V11),0) -> 4817.5304 | S11: =IFERROR(VLOOKUP(A11,DIF_ANTE!A:D,4,0),"0")/J11 -> -20.1 | T11: =M11-Q11 -> -23.56 | U11: =T11-S11 -> -3.46 | V11: =IFERROR(VLOOKUP(A11,CUSTO!A:C,3,0),VLOOKUP(B11,CUSTO!A:C,3,0)) -> 31.3723 | W11: =IFERROR(SUM(T11*V11),0) -> -739.13139 | X11: =IFERROR(T11/Q11,"") -> -0.15342537 | Y11: =IFERROR(U11*V11,"-") -> -108.54816 | Z11: OK, PERDA
A12: 2701050006 | B12: - | C12: AROMA IDENTICO AO NATURAL BLUEBERRY KALABROS | D12: 0 | E12: =IFERROR(IFERROR(VLOOKUP(B12,[1]Planilha1!$A$4:$C$277,3,0),VLOOKUP(A12,[1]Planilha1!$A$4:$C$277,3,0)),0) -> 0 | F12: =IFERROR(IFERROR(VLOOKUP(A12,[2]Planilha1!$A$4:$C$258,3,0),VLOOKUP(B12,[2]Planilha1!$A$4:$C$258,3,0)),0) -> 0 | G12: =IFERROR(IFERROR(VLOOKUP(A12,[1]Planilha1!$A$4:$D$277,4,0),VLOOKUP(B12,[1]Planilha1!$A$4:$D$277,4,0)),0) -> 0 | H12: =D12+E12-G12 -> 0 | I12: AROMA | J12: 1 | K12: =VLOOKUP(A12,CONT_ANTE!A:D,4,0) -> 0 | L12: =IF(AND(F12=0,K12<>M12),"!@##@!","ok") -> ok | M12: =IFERROR(VLOOKUP(A12,CONTAGEM!B:G,6,0),VLOOKUP(B12,CONTAGEM!B:G,6,0)) -> 0 | N12: =IFERROR(SUM(M12*V12),0) -> 0 | O12: =SUMIF(SISTEMA!B:B,A12,SISTEMA!I:I)/J12 -> 0 | P12: =SUMIF(SISTEMA!B:B,B12,SISTEMA!I:I) -> 0 | Q12: =O12+P12 -> 0 | R12: =IFERROR(SUM(Q12*V12),0) -> 0 | S12: =IFERROR(VLOOKUP(A12,DIF_ANTE!A:D,4,0),"0")/J12 -> 0 | T12: =M12-Q12 -> 0 | U12: =T12-S12 -> 0 | V12: =IFERROR(VLOOKUP(A12,CUSTO!A:C,3,0),VLOOKUP(B12,CUSTO!A:C,3,0)) -> 45.981938 | W12: =IFERROR(SUM(T12*V12),0) -> 0 | X12: =IFERROR(T12/Q12,"") | Y12: =IFERROR(U12*V12,"-") -> 0 | Z12: ok
A13: 2701050029 | B13: - | C13: AROMA IDENTICO AO NATURAL CLOUDING LEMON | D13: 0 | E13: =IFERROR(IFERROR(VLOOKUP(B13,[1]Planilha1!$A$4:$C$277,3,0),VLOOKUP(A13,[1]Planilha1!$A$4:$C$277,3,0)),0) -> 0 | F13: =IFERROR(IFERROR(VLOOKUP(A13,[2]Planilha1!$A$4:$C$258,3,0),VLOOKUP(B13,[2]Planilha1!$A$4:$C$258,3,0)),0) -> 0 | G13: =IFERROR(IFERROR(VLOOKUP(A13,[1]Planilha1!$A$4:$D$277,4,0),VLOOKUP(B13,[1]Planilha1!$A$4:$D$277,4,0)),0) -> 0 | H13: =D13+E13-G13 -> 0 | I13: AROMA | J13: 1 | K13: =VLOOKUP(A13,CONT_ANTE!A:D,4,0) -> 0 | L13: =IF(AND(F13=0,K13<>M13),"!@##@!","ok") -> ok | M13: =IFERROR(VLOOKUP(A13,CONTAGEM!B:G,6,0),VLOOKUP(B13,CONTAGEM!B:G,6,0)) -> 0 | N13: =IFERROR(SUM(M13*V13),0) -> 0 | O13: =SUMIF(SISTEMA!B:B,A13,SISTEMA!I:I)/J13 -> 0 | P13: =SUMIF(SISTEMA!B:B,B13,SISTEMA!I:I) -> 0 | Q13: =O13+P13 -> 0 | R13: =IFERROR(SUM(Q13*V13),0) -> 0 | S13: =IFERROR(VLOOKUP(A13,DIF_ANTE!A:D,4,0),"0")/J13 -> 0 | T13: =M13-Q13 -> 0 | U13: =T13-S13 -> 0 | V13: =IFERROR(VLOOKUP(A13,CUSTO!A:C,3,0),VLOOKUP(B13,CUSTO!A:C,3,0)) -> 3.726875 | W13: =IFERROR(SUM(T13*V13),0) -> 0 | X13: =IFERROR(T13/Q13,"") | Y13: =IFERROR(U13*V13,"-") -> 0 | Z13: ok
A14: 2701050010 | B14: - | C14: AROMA IDENTICO AO NATURAL DE LARANJA | D14: 15.31 | E14: =IFERROR(IFERROR(VLOOKUP(B14,[1]Planilha1!$A$4:$C$277,3,0),VLOOKUP(A14,[1]Planilha1!$A$4:$C$277,3,0)),0) -> 0 | F14: =IFERROR(IFERROR(VLOOKUP(A14,[2]Planilha1!$A$4:$C$258,3,0),VLOOKUP(B14,[2]Planilha1!$A$4:$C$258,3,0)),0) -> 7.09 | G14: =IFERROR(IFERROR(VLOOKUP(A14,[1]Planilha1!$A$4:$D$277,4,0),VLOOKUP(B14,[1]Planilha1!$A$4:$D$277,4,0)),0) -> 7.09 | H14: =D14+E14-G14 -> 8.22 | I14: AROMA | J14: 1 | K14: =VLOOKUP(A14,CONT_ANTE!A:D,4,0) -> 14.5 | L14: =IF(AND(F14=0,K14<>M14),"!@##@!","ok") -> ok | M14: 11 | N14: =IFERROR(SUM(M14*V14),0) -> 660.77733 | O14: =SUMIF(SISTEMA!B:B,A14,SISTEMA!I:I)/J14 -> 9 | P14: =SUMIF(SISTEMA!B:B,B14,SISTEMA!I:I) -> 0 | Q14: =O14+P14 -> 9 | R14: =IFERROR(SUM(Q14*V14),0) -> 540.636 | S14: =IFERROR(VLOOKUP(A14,DIF_ANTE!A:D,4,0),"0")/J14 -> -0.81 | T14: =M14-Q14 -> 2 | U14: =T14-S14 -> 2.81 | V14: =IFERROR(VLOOKUP(A14,CUSTO!A:C,3,0),VLOOKUP(B14,CUSTO!A:C,3,0)) -> 60.070667 | W14: =IFERROR(SUM(T14*V14),0) -> 120.14133 | X14: =IFERROR(T14/Q14,"") -> 0.22222222 | Y14: =IFERROR(U14*V14,"-") -> 168.79857 | Z14: OK
A15: 2701050011 | B15: - | C15: AROMA IDENTICO AO NATURAL DE LIMAO 41 SAPORITI | D15: 77.91 | E15: =IFERROR(IFERROR(VLOOKUP(B15,[1]Planilha1!$A$4:$C$277,3,0),VLOOKUP(A15,[1]Planilha1!$A$4:$C$277,3,0)),0) -> 0 | F15: =IFERROR(IFERROR(VLOOKUP(A15,[2]Planilha1!$A$4:$C$258,3,0),VLOOKUP(B15,[2]Planilha1!$A$4:$C$258,3,0)),0) -> 30.31 | G15: =IFERROR(IFERROR(VLOOKUP(A15,[1]Planilha1!$A$4:$D$277,4,0),VLOOKUP(B15,[1]Planilha1!$A$4:$D$277,4,0)),0) -> 30.31 | H15: =D15+E15-G15 -> 47.6 | I15: AROMA | J15: 1 | K15: =VLOOKUP(A15,CONT_ANTE!A:D,4,0) -> 61.5 | L15: =IF(AND(F15=0,K15<>M15),"!@##@!","ok") -> ok | M15: =IFERROR(VLOOKUP(A15,CONTAGEM!B:G,6,0),VLOOKUP(B15,CONTAGEM!B:G,6,0)) -> 37.6 | N15: =IFERROR(SUM(M15*V15),0) -> 1523.2073 | O15: =SUMIF(SISTEMA!B:B,A15,SISTEMA!I:I)/J15 -> 61.18 | P15: =SUMIF(SISTEMA!B:B,B15,SISTEMA!I:I) -> 0 | Q15: =O15+P15 -> 61.18 | R15: =IFERROR(SUM(Q15*V15),0) -> 2478.4528 | S15: =IFERROR(VLOOKUP(A15,DIF_ANTE!A:D,4,0),"0")/J15 -> -16.41 | T15: =M15-Q15 -> -23.58 | U15: =T15-S15 -> -7.17 | V15: =IFERROR(VLOOKUP(A15,CUSTO!A:C,3,0),VLOOKUP(B15,CUSTO!A:C,3,0)) -> 40.510833 | W15: =IFERROR(SUM(T15*V15),0) -> -955.24545 | X15: =IFERROR(T15/Q15,"") -> -0.38542007 | Y15: =IFERROR(U15*V15,"-") -> -290.46268 | Z15: OK, PERDA
A16: 2701050027 | B16: - | C16: AROMA IDENTICO AO NATURAL DE UVA SAPORITI | D16: 123.51 | E16: =IFERROR(IFERROR(VLOOKUP(B16,[1]Planilha1!$A$4:$C$277,3,0),VLOOKUP(A16,[1]Planilha1!$A$4:$C$277,3,0)),0) -> 0 | F16: =IFERROR(IFERROR(VLOOKUP(A16,[2]Planilha1!$A$4:$C$258,3,0),VLOOKUP(B16,[2]Planilha1!$A$4:$C$258,3,0)),0) -> 102.34 | G16: =IFERROR(IFERROR(VLOOKUP(A16,[1]Planilha1!$A$4:$D$277,4,0),VLOOKUP(B16,[1]Planilha1!$A$4:$D$277,4,0)),0) -> 102.34 | H16: =D16+E16-G16 -> 21.17 | I16: AROMA | J16: 1 | K16: =VLOOKUP(A16,CONT_ANTE!A:D,4,0) -> 113 | L16: =IF(AND(F16=0,K16<>M16),"!@##@!","ok") -> ok | M16: =IFERROR(VLOOKUP(A16,CONTAGEM!B:G,6,0),VLOOKUP(B16,CONTAGEM!B:G,6,0)) -> 72 | N16: =IFERROR(SUM(M16*V16),0) -> 1701.456 | O16: =SUMIF(SISTEMA!B:B,A16,SISTEMA!I:I)/J16 -> 72 | P16: =SUMIF(SISTEMA!B:B,B16,SISTEMA!I:I) -> 0 | Q16: =O16+P16 -> 72 | R16: =IFERROR(SUM(Q16*V16),0) -> 1701.456 | S16: =IFERROR(VLOOKUP(A16,DIF_ANTE!A:D,4,0),"0")/J16 -> -10.51 | T16: =M16-Q16 -> 0 | U16: =T16-S16 -> 10.51 | V16: =IFERROR(VLOOKUP(A16,CUSTO!A:C,3,0),VLOOKUP(B16,CUSTO!A:C,3,0)) -> 23.631333 | W16: =IFERROR(SUM(T16*V16),0) -> 0 | X16: =IFERROR(T16/Q16,"") -> 0 | Y16: =IFERROR(U16*V16,"-") -> 248.36531 | Z16: OK
A17: 2701050033 | B17: - | C17: AROMA IDENTICO AO NATURAL DE UVA VERDE SAPORITI | D17: 135.28 | E17: =IFERROR(IFERROR(VLOOKUP(B17,[1]Planilha1!$A$4:$C$277,3,0),VLOOKUP(A17,[1]Planilha1!$A$4:$C$277,3,0)),0) -> 108 | F17: =IFERROR(IFERROR(VLOOKUP(A17,[2]Planilha1!$A$4:$C$258,3,0),VLOOKUP(B17,[2]Planilha1!$A$4:$C$258,3,0)),0) -> 45.28 | G17: =IFERROR(IFERROR(VLOOKUP(A17,[1]Planilha1!$A$4:$D$277,4,0),VLOOKUP(B17,[1]Planilha1!$A$4:$D$277,4,0)),0) -> 147.09 | H17: =D17+E17-G17 -> 96.19 | I17: AROMA | J17: 1 | K17: =VLOOKUP(A17,CONT_ANTE!A:D,4,0) -> 129.5 | L17: =IF(AND(F17=0,K17<>M17),"!@##@!","ok") -> ok | M17: =IFERROR(VLOOKUP(A17,CONTAGEM!B:G,6,0),VLOOKUP(B17,CONTAGEM!B:G,6,0)) -> 90 | N17: =IFERROR(SUM(M17*V17),0) -> 8431.975 | O17: =SUMIF(SISTEMA!B:B,A17,SISTEMA!I:I)/J17 -> 96.19 | P17: =SUMIF(SISTEMA!B:B,B17,SISTEMA!I:I) -> 0 | Q17: =O17+P17 -> 96.19 | R17: =IFERROR(SUM(Q17*V17),0) -> 9011.9075 | S17: =IFERROR(VLOOKUP(A17,DIF_ANTE!A:D,4,0),"0")/J17 -> -5.78 | T17: =M17-Q17 -> -6.19 | U17: =T17-S17 -> -0.41 | V17: =IFERROR(VLOOKUP(A17,CUSTO!A:C,3,0),VLOOKUP(B17,CUSTO!A:C,3,0)) -> 93.688611 | W17: =IFERROR(SUM(T17*V17),0) -> -579.9325 | X17: =IFERROR(T17/Q17,"") -> -0.064351804 | Y17: =IFERROR(U17*V17,"-") -> -38.412331 | Z17: OK, PERDA
A18: 2701050013 | B18: - | C18: AROMA IDENTICO AO NATURAL MACA VERDE DUAS RODAS | D18: 104.392 | E18: =IFERROR(IFERROR(VLOOKUP(B18,[1]Planilha1!$A$4:$C$277,3,0),VLOOKUP(A18,[1]Planilha1!$A$4:$C$277,3,0)),0) -> 306 | F18: =IFERROR(IFERROR(VLOOKUP(A18,[2]Planilha1!$A$4:$C$258,3,0),VLOOKUP(B18,[2]Planilha1!$A$4:$C$258,3,0)),0) -> 54.01 | G18: =IFERROR(IFERROR(VLOOKUP(A18,[1]Planilha1!$A$4:$D$277,4,0),VLOOKUP(B18,[1]Planilha1!$A$4:$D$277,4,0)),0) -> 258.01 | H18: =D18+E18-G18 -> 152.382 | I18: AROMA | J18: 1 | K18: =VLOOKUP(A18,CONT_ANTE!A:D,4,0) -> 98 | L18: =IF(AND(F18=0,K18<>M18),"!@##@!","ok") -> ok | M18: =IFERROR(VLOOKUP(A18,CONTAGEM!B:G,6,0),VLOOKUP(B18,CONTAGEM!B:G,6,0)) -> 155 | N18: =IFERROR(SUM(M18*V18),0) -> 6336.1994 | O18: =SUMIF(SISTEMA!B:B,A18,SISTEMA!I:I)/J18 -> 152.382 | P18: =SUMIF(SISTEMA!B:B,B18,SISTEMA!I:I) -> 0 | Q18: =O18+P18 -> 152.382 | R18: =IFERROR(SUM(Q18*V18),0) -> 6229.179 | S18: =IFERROR(VLOOKUP(A18,DIF_ANTE!A:D,4,0),"0")/J18 -> -6.392 | T18: =M18-Q18 -> 2.618 | U18: =T18-S18 -> 9.01 | V18: =IFERROR(VLOOKUP(A18,CUSTO!A:C,3,0),VLOOKUP(B18,CUSTO!A:C,3,0)) -> 40.878706 | W18: =IFERROR(SUM(T18*V18),0) -> 107.02045 | X18: =IFERROR(T18/Q18,"") -> 0.017180507 | Y18: =IFERROR(U18*V18,"-") -> 368.31714 | Z18: OK
A19: 2701050014 | B19: - | C19: AROMA IDENTICO AO NATURAL MANGA HS 25409 SAPORITI | D19: 0 | E19: =IFERROR(IFERROR(VLOOKUP(B19,[1]Planilha1!$A$4:$C$277,3,0),VLOOKUP(A19,[1]Planilha1!$A$4:$C$277,3,0)),0) -> 0 | F19: =IFERROR(IFERROR(VLOOKUP(A19,[2]Planilha1!$A$4:$C$258,3,0),VLOOKUP(B19,[2]Planilha1!$A$4:$C$258,3,0)),0) -> 0 | G19: =IFERROR(IFERROR(VLOOKUP(A19,[1]Planilha1!$A$4:$D$277,4,0),VLOOKUP(B19,[1]Planilha1!$A$4:$D$277,4,0)),0) -> 0 | H19: =D19+E19-G19 -> 0 | I19: AROMA | J19: 1 | K19: =VLOOKUP(A19,CONT_ANTE!A:D,4,0) -> 0 | L19: =IF(AND(F19=0,K19<>M19),"!@##@!","ok") -> ok | M19: =IFERROR(VLOOKUP(A19,CONTAGEM!B:G,6,0),VLOOKUP(B19,CONTAGEM!B:G,6,0)) -> 0 | N19: =IFERROR(SUM(M19*V19),0) -> 0 | O19: =SUMIF(SISTEMA!B:B,A19,SISTEMA!I:I)/J19 -> 0 | P19: =SUMIF(SISTEMA!B:B,B19,SISTEMA!I:I) -> 0 | Q19: =O19+P19 -> 0 | R19: =IFERROR(SUM(Q19*V19),0) -> 0 | S19: =IFERROR(VLOOKUP(A19,DIF_ANTE!A:D,4,0),"0")/J19 -> 0 | T19: =M19-Q19 -> 0 | U19: =T19-S19 -> 0 | V19: =IFERROR(VLOOKUP(A19,CUSTO!A:C,3,0),VLOOKUP(B19,CUSTO!A:C,3,0)) -> 3.726875 | W19: =IFERROR(SUM(T19*V19),0) -> 0 | X19: =IFERROR(T19/Q19,"") | Y19: =IFERROR(U19*V19,"-") -> 0 | Z19: OK
A20: 2701050015 | B20: - | C20: AROMA IDENTICO AO NATURAL MARACUJA DUAS RODAS | D20: 0.535 | E20: =IFERROR(IFERROR(VLOOKUP(B20,[1]Planilha1!$A$4:$C$277,3,0),VLOOKUP(A20,[1]Planilha1!$A$4:$C$277,3,0)),0) -> 0 | F20: =IFERROR(IFERROR(VLOOKUP(A20,[2]Planilha1!$A$4:$C$258,3,0),VLOOKUP(B20,[2]Planilha1!$A$4:$C$258,3,0)),0) -> 0 | G20: =IFERROR(IFERROR(VLOOKUP(A20,[1]Planilha1!$A$4:$D$277,4,0),VLOOKUP(B20,[1]Planilha1!$A$4:$D$277,4,0)),0) -> 0 | H20: =D20+E20-G20 -> 0.535 | I20: AROMA | J20: 1 | K20: =VLOOKUP(A20,CONT_ANTE!A:D,4,0) -> 0 | L20: =IF(AND(F20=0,K20<>M20),"!@##@!","ok") -> ok | M20: =IFERROR(VLOOKUP(A20,CONTAGEM!B:G,6,0),VLOOKUP(B20,CONTAGEM!B:G,6,0)) -> 0 | N20: =IFERROR(SUM(M20*V20),0) -> 0 | O20: =SUMIF(SISTEMA!B:B,A20,SISTEMA!I:I)/J20 -> 0.535 | P20: =SUMIF(SISTEMA!B:B,B20,SISTEMA!I:I) -> 0 | Q20: =O20+P20 -> 0.535 | R20: =IFERROR(SUM(Q20*V20),0) -> 25.525599 | S20: =IFERROR(VLOOKUP(A20,DIF_ANTE!A:D,4,0),"0")/J20 -> -0.535 | T20: =M20-Q20 -> -0.535 | U20: =T20-S20 -> 0 | V20: =IFERROR(VLOOKUP(A20,CUSTO!A:C,3,0),VLOOKUP(B20,CUSTO!A:C,3,0)) -> 47.7114 | W20: =IFERROR(SUM(T20*V20),0) -> -25.525599 | X20: =IFERROR(T20/Q20,"") -> -1 | Y20: =IFERROR(U20*V20,"-") -> 0 | Z20: OK, PERDA
A21: 2701050019 | B21: - | C21: AROMA IDENTICO AO NATURAL MELAO DUAS RODAS | D21: 353.7704 | E21: =IFERROR(IFERROR(VLOOKUP(B21,[1]Planilha1!$A$4:$C$277,3,0),VLOOKUP(A21,[1]Planilha1!$A$4:$C$277,3,0)),0) -> 255 | F21: =IFERROR(IFERROR(VLOOKUP(A21,[2]Planilha1!$A$4:$C$258,3,0),VLOOKUP(B21,[2]Planilha1!$A$4:$C$258,3,0)),0) -> 110.77 | G21: =IFERROR(IFERROR(VLOOKUP(A21,[1]Planilha1!$A$4:$D$277,4,0),VLOOKUP(B21,[1]Planilha1!$A$4:$D$277,4,0)),0) -> 263.77 | H21: =D21+E21-G21 -> 345.0004 | I21: AROMA | J21: 1 | K21: =VLOOKUP(A21,CONT_ANTE!A:D,4,0) -> 325 | L21: =IF(AND(F21=0,K21<>M21),"!@##@!","ok") -> ok | M21: =IFERROR(VLOOKUP(A21,CONTAGEM!B:G,6,0),VLOOKUP(B21,CONTAGEM!B:G,6,0)) -> 325 | N21: =IFERROR(SUM(M21*V21),0) -> 16175.951 | O21: =SUMIF(SISTEMA!B:B,A21,SISTEMA!I:I)/J21 -> 364.2404 | P21: =SUMIF(SISTEMA!B:B,B21,SISTEMA!I:I) -> 0 | Q21: =O21+P21 -> 364.2404 | R21: =IFERROR(SUM(Q21*V21),0) -> 18129.03 | S21: =IFERROR(VLOOKUP(A21,DIF_ANTE!A:D,4,0),"0")/J21 -> -28.7704 | T21: =M21-Q21 -> -39.2404 | U21: =T21-S21 -> -10.47 | V21: =IFERROR(VLOOKUP(A21,CUSTO!A:C,3,0),VLOOKUP(B21,CUSTO!A:C,3,0)) -> 49.772157 | W21: =IFERROR(SUM(T21*V21),0) -> -1953.0793 | X21: =IFERROR(T21/Q21,"") -> -0.10773215 | Y21: =IFERROR(U21*V21,"-") -> -521.11448 | Z21: OK, PERDA
A22: 2701050021 | B22: - | C22: AROMA IDENTICO AO NATURAL MORANGO DUAS RODAS | D22: 117.23 | E22: =IFERROR(IFERROR(VLOOKUP(B22,[1]Planilha1!$A$4:$C$277,3,0),VLOOKUP(A22,[1]Planilha1!$A$4:$C$277,3,0)),0) -> 250 | F22: =IFERROR(IFERROR(VLOOKUP(A22,[2]Planilha1!$A$4:$C$258,3,0),VLOOKUP(B22,[2]Planilha1!$A$4:$C$258,3,0)),0) -> 82.23 | G22: =IFERROR(IFERROR(VLOOKUP(A22,[1]Planilha1!$A$4:$D$277,4,0),VLOOKUP(B22,[1]Planilha1!$A$4:$D$277,4,0)),0) -> 282.23 | H22: =D22+E22-G22 -> 85 | I22: AROMA | J22: 1 | K22: =VLOOKUP(A22,CONT_ANTE!A:D,4,0) -> 121 | L22: =IF(AND(F22=0,K22<>M22),"!@##@!","ok") -> ok | M22: =IFERROR(VLOOKUP(A22,CONTAGEM!B:G,6,0),VLOOKUP(B22,CONTAGEM!B:G,6,0)) -> 88.5 | N22: =IFERROR(SUM(M22*V22),0) -> 5667.9294 | O22: =SUMIF(SISTEMA!B:B,A22,SISTEMA!I:I)/J22 -> 85 | P22: =SUMIF(SISTEMA!B:B,B22,SISTEMA!I:I) -> 0 | Q22: =O22+P22 -> 85 | R22: =IFERROR(SUM(Q22*V22),0) -> 5443.774 | S22: =IFERROR(VLOOKUP(A22,DIF_ANTE!A:D,4,0),"0")/J22 -> 3.77 | T22: =M22-Q22 -> 3.5 | U22: =T22-S22 -> -0.27 | V22: =IFERROR(VLOOKUP(A22,CUSTO!A:C,3,0),VLOOKUP(B22,CUSTO!A:C,3,0)) -> 64.0444 | W22: =IFERROR(SUM(T22*V22),0) -> 224.1554 | X22: =IFERROR(T22/Q22,"") -> 0.041176471 | Y22: =IFERROR(U22*V22,"-") -> -17.291988 | Z22: OK, PERDA
A23: 2701050026 | B23: - | C23: AROMA IDENTICO AO NATURAL PESSEGO RB 25049 SAPORITI | D23: 44.59 | E23: =IFERROR(IFERROR(VLOOKUP(B23,[1]Planilha1!$A$4:$C$277,3,0),VLOOKUP(A23,[1]Planilha1!$A$4:$C$277,3,0)),0) -> 0 | F23: =IFERROR(IFERROR(VLOOKUP(A23,[2]Planilha1!$A$4:$C$258,3,0),VLOOKUP(B23,[2]Planilha1!$A$4:$C$258,3,0)),0) -> 33.59 | G23: =IFERROR(IFERROR(VLOOKUP(A23,[1]Planilha1!$A$4:$D$277,4,0),VLOOKUP(B23,[1]Planilha1!$A$4:$D$277,4,0)),0) -> 29.4 | H23: =D23+E23-G23 -> 15.19 | I23: AROMA | J23: 1 | K23: =VLOOKUP(A23,CONT_ANTE!A:D,4,0) -> 41 | L23: =IF(AND(F23=0,K23<>M23),"!@##@!","ok") -> ok | M23: =IFERROR(VLOOKUP(A23,CONTAGEM!B:G,6,0),VLOOKUP(B23,CONTAGEM!B:G,6,0)) -> 11 | N23: =IFERROR(SUM(M23*V23),0) -> 538.4555 | O23: =SUMIF(SISTEMA!B:B,A23,SISTEMA!I:I)/J23 -> 15.19 | P23: =SUMIF(SISTEMA!B:B,B23,SISTEMA!I:I) -> 0 | Q23: =O23+P23 -> 15.19 | R23: =IFERROR(SUM(Q23*V23),0) -> 743.5581 | S23: =IFERROR(VLOOKUP(A23,DIF_ANTE!A:D,4,0),"0")/J23 -> -3.59 | T23: =M23-Q23 -> -4.19 | U23: =T23-S23 -> -0.6 | V23: =IFERROR(VLOOKUP(A23,CUSTO!A:C,3,0),VLOOKUP(B23,CUSTO!A:C,3,0)) -> 48.9505 | W23: =IFERROR(SUM(T23*V23),0) -> -205.1026 | X23: =IFERROR(T23/Q23,"") -> -0.27583937 | Y23: =IFERROR(U23*V23,"-") -> -29.3703 | Z23: OK, PERDA
A24: 2701050005 | B24: - | C24: AROMA NATURAL BAUNILHA KALABROS | D24: 0 | E24: =IFERROR(IFERROR(VLOOKUP(B24,[1]Planilha1!$A$4:$C$277,3,0),VLOOKUP(A24,[1]Planilha1!$A$4:$C$277,3,0)),0) -> 0 | F24: =IFERROR(IFERROR(VLOOKUP(A24,[2]Planilha1!$A$4:$C$258,3,0),VLOOKUP(B24,[2]Planilha1!$A$4:$C$258,3,0)),0) -> 0 | G24: =IFERROR(IFERROR(VLOOKUP(A24,[1]Planilha1!$A$4:$D$277,4,0),VLOOKUP(B24,[1]Planilha1!$A$4:$D$277,4,0)),0) -> 0 | H24: =D24+E24-G24 -> 0 | I24: AROMA | J24: 1 | K24: =VLOOKUP(A24,CONT_ANTE!A:D,4,0) -> 0 | L24: =IF(AND(F24=0,K24<>M24),"!@##@!","ok") -> ok | M24: =IFERROR(VLOOKUP(A24,CONTAGEM!B:G,6,0),VLOOKUP(B24,CONTAGEM!B:G,6,0)) -> 0 | N24: =IFERROR(SUM(M24*V24),0) -> 0 | O24: =SUMIF(SISTEMA!B:B,A24,SISTEMA!I:I)/J24 -> 0 | P24: =SUMIF(SISTEMA!B:B,B24,SISTEMA!I:I) -> 0 | Q24: =O24+P24 -> 0 | R24: =IFERROR(SUM(Q24*V24),0) -> 0 | S24: =IFERROR(VLOOKUP(A24,DIF_ANTE!A:D,4,0),"0")/J24 -> 0 | T24: =M24-Q24 -> 0 | U24: =T24-S24 -> 0 | V24: =IFERROR(VLOOKUP(A24,CUSTO!A:C,3,0),VLOOKUP(B24,CUSTO!A:C,3,0)) -> 45.476671 | W24: =IFERROR(SUM(T24*V24),0) -> 0 | X24: =IFERROR(T24/Q24,"") | Y24: =IFERROR(U24*V24,"-") -> 0 | Z24: OK
A25: 2701050007 | B25: - | C25: AROMA NATURAL DE CITRUS RB 25395 SAPORITI | D25: 0 | E25: =IFERROR(IFERROR(VLOOKUP(B25,[1]Planilha1!$A$4:$C$277,3,0),VLOOKUP(A25,[1]Planilha1!$A$4:$C$277,3,0)),0) -> 36 | F25: =IFERROR(IFERROR(VLOOKUP(A25,[2]Planilha1!$A$4:$C$258,3,0),VLOOKUP(B25,[2]Planilha1!$A$4:$C$258,3,0)),0) -> 0 | G25: =IFERROR(IFERROR(VLOOKUP(A25,[1]Planilha1!$A$4:$D$277,4,0),VLOOKUP(B25,[1]Planilha1!$A$4:$D$277,4,0)),0) -> 36 | H25: =D25+E25-G25 -> 0 | I25: AROMA | J25: 1 | K25: =VLOOKUP(A25,CONT_ANTE!A:D,4,0) -> 0 | L25: =IF(AND(F25=0,K25<>M25),"!@##@!","ok") -> ok | M25: =IFERROR(VLOOKUP(A25,CONTAGEM!B:G,6,0),VLOOKUP(B25,CONTAGEM!B:G,6,0)) -> 0 | N25: =IFERROR(SUM(M25*V25),0) -> 0 | O25: =SUMIF(SISTEMA!B:B,A25,SISTEMA!I:I)/J25 -> 0 | P25: =SUMIF(SISTEMA!B:B,B25,SISTEMA!I:I) -> 0 | Q25: =O25+P25 -> 0 | R25: =IFERROR(SUM(Q25*V25),0) -> 0 | S25: =IFERROR(VLOOKUP(A25,DIF_ANTE!A:D,4,0),"0")/J25 -> 0 | T25: =M25-Q25 -> 0 | U25: =T25-S25 -> 0 | V25: =IFERROR(VLOOKUP(A25,CUSTO!A:C,3,0),VLOOKUP(B25,CUSTO!A:C,3,0)) -> 88.617222 | W25: =IFERROR(SUM(T25*V25),0) -> 0 | X25: =IFERROR(T25/Q25,"") | Y25: =IFERROR(U25*V25,"-") -> 0 | Z25: OK
A26: 2701050036 | B26: - | C26: AROMA NATURAL DE TANGERINA DOHLER | D26: 119.11 | E26: =IFERROR(IFERROR(VLOOKUP(B26,[1]Planilha1!$A$4:$C$277,3,0),VLOOKUP(A26,[1]Planilha1!$A$4:$C$277,3,0)),0) -> 0 | F26: =IFERROR(IFERROR(VLOOKUP(A26,[2]Planilha1!$A$4:$C$258,3,0),VLOOKUP(B26,[2]Planilha1!$A$4:$C$258,3,0)),0) -> 35.11 | G26: =IFERROR(IFERROR(VLOOKUP(A26,[1]Planilha1!$A$4:$D$277,4,0),VLOOKUP(B26,[1]Planilha1!$A$4:$D$277,4,0)),0) -> 25.8 | H26: =D26+E26-G26 -> 93.31 | I26: AROMA | J26: 1 | K26: =VLOOKUP(A26,CONT_ANTE!A:D,4,0) -> 110 | L26: =IF(AND(F26=0,K26<>M26),"!@##@!","ok") -> ok | M26: =IFERROR(VLOOKUP(A26,CONTAGEM!B:G,6,0),VLOOKUP(B26,CONTAGEM!B:G,6,0)) -> 84 | N26: =IFERROR(SUM(M26*V26),0) -> 12167.98 | O26: =SUMIF(SISTEMA!B:B,A26,SISTEMA!I:I)/J26 -> 93.31 | P26: =SUMIF(SISTEMA!B:B,B26,SISTEMA!I:I) -> 0 | Q26: =O26+P26 -> 93.31 | R26: =IFERROR(SUM(Q26*V26),0) -> 13516.597 | S26: =IFERROR(VLOOKUP(A26,DIF_ANTE!A:D,4,0),"0")/J26 -> -9.11 | T26: =M26-Q26 -> -9.31 | U26: =T26-S26 -> -0.2 | V26: =IFERROR(VLOOKUP(A26,CUSTO!A:C,3,0),VLOOKUP(B26,CUSTO!A:C,3,0)) -> 144.8569 | W26: =IFERROR(SUM(T26*V26),0) -> -1348.6177 | X26: =IFERROR(T26/Q26,"") -> -0.099774944 | Y26: =IFERROR(U26*V26,"-") -> -28.97138 | Z26: OK, PERDA
... A31: 2701160011 | B31: - | C31: CAIXA CER BAMBOA LAGER 12X330ML | D31: 34779 | E31: =IFERROR(IFERROR(VLOOKUP(B31,[1]Planilha1!$A$4:$C$277,3,0),VLOOKUP(A31,[1]Planilha1!$A$4:$C$277,3,0)),0) -> 0 | F31: =IFERROR(IFERROR(VLOOKUP(A31,[2]Planilha1!$A$4:$C$258,3,0),VLOOKUP(B31,[2]Planilha1!$A$4:$C$258,3,0)),0) -> 0 | G31: =IFERROR(IFERROR(VLOOKUP(A31,[1]Planilha1!$A$4:$D$277,4,0),VLOOKUP(B31,[1]Planilha1!$A$4:$D$277,4,0)),0) -> 2179 | H31: =D31+E31-G31 -> 32600 | I31: CAIXA | J31: 1 | K31: =VLOOKUP(A31,CONT_ANTE!A:D,4,0) -> 32600 | L31: =IF(AND(F31=0,K31<>M31),"!@##@!","ok") -> !@##@! | M31: =IFERROR(VLOOKUP(A31,CONTAGEM!B:G,6,0),VLOOKUP(B31,CONTAGEM!B:G,6,0)) -> 32578 | N31: =IFERROR(SUM(M31*V31),0) -> 53251.06 | O31: =SUMIF(SISTEMA!B:B,A31,SISTEMA!I:I)/J31 -> 32600 | P31: =SUMIF(SISTEMA!B:B,B31,SISTEMA!I:I) -> 0 | Q31: =O31+P31 -> 32600 | R31: =IFERROR(SUM(Q31*V31),0) -> 53287.02 | S31: =IFERROR(VLOOKUP(A31,DIF_ANTE!A:D,4,0),"0")/J31 -> -2179 | T31: =M31-Q31 -> -22 | U31: =T31-S31 -> 2157 | V31: =IFERROR(VLOOKUP(A31,CUSTO!A:C,3,0),VLOOKUP(B31,CUSTO!A:C,3,0)) -> 1.6345712 | W31: =IFERROR(SUM(T31*V31),0) -> -35.960566 | X31: =IFERROR(T31/Q31,"") -> -0.00067484663 | Y31: =IFERROR(U31*V31,"-") -> 3525.77 | Z31: ok
A32: 2701160008 | B32: - | C32: CAIXA CER BAMBOA PILSEN 12X300ML | D32: 0 | E32: =IFERROR(IFERROR(VLOOKUP(B32,[1]Planilha1!$A$4:$C$277,3,0),VLOOKUP(A32,[1]Planilha1!$A$4:$C$277,3,0)),0) -> 0 | F32: =IFERROR(IFERROR(VLOOKUP(A32,[2]Planilha1!$A$4:$C$258,3,0),VLOOKUP(B32,[2]Planilha1!$A$4:$C$258,3,0)),0) -> 0 | G32: =IFERROR(IFERROR(VLOOKUP(A32,[1]Planilha1!$A$4:$D$277,4,0),VLOOKUP(B32,[1]Planilha1!$A$4:$D$277,4,0)),0) -> 0 | H32: =D32+E32-G32 -> 0 | I32: CAIXA | J32: 1 | K32: =VLOOKUP(A32,CONT_ANTE!A:D,4,0) -> 0 | L32: =IF(AND(F32=0,K32<>M32),"!@##@!","ok") -> ok | M32: 0 | N32: =IFERROR(SUM(M32*V32),0) -> 0 | O32: =SUMIF(SISTEMA!B:B,A32,SISTEMA!I:I)/J32 -> 0 | P32: =SUMIF(SISTEMA!B:B,B32,SISTEMA!I:I) -> 0 | Q32: =O32+P32 -> 0 | R32: =IFERROR(SUM(Q32*V32),0) -> 0 | S32: =IFERROR(VLOOKUP(A32,DIF_ANTE!A:D,4,0),"0")/J32 -> 0 | T32: =M32-Q32 -> 0 | U32: =T32-S32 -> 0 | V32: =IFERROR(VLOOKUP(A32,CUSTO!A:C,3,0),VLOOKUP(B32,CUSTO!A:C,3,0)) -> 3.726875 | W32: =IFERROR(SUM(T32*V32),0) -> 0 | X32: =IFERROR(T32/Q32,"") | Y32: =IFERROR(U32*V32,"-") -> 0 | Z32: ok
A33: 2701160007 | B33: - | C33: CAIXA CER BAMBOA PILSEN 6X600ML | D33: 0 | E33: =IFERROR(IFERROR(VLOOKUP(B33,[1]Planilha1!$A$4:$C$277,3,0),VLOOKUP(A33,[1]Planilha1!$A$4:$C$277,3,0)),0) -> 0 | F33: =IFERROR(IFERROR(VLOOKUP(A33,[2]Planilha1!$A$4:$C$258,3,0),VLOOKUP(B33,[2]Planilha1!$A$4:$C$258,3,0)),0) -> 0 | G33: =IFERROR(IFERROR(VLOOKUP(A33,[1]Planilha1!$A$4:$D$277,4,0),VLOOKUP(B33,[1]Planilha1!$A$4:$D$277,4,0)),0) -> 0 | H33: =D33+E33-G33 -> 0 | I33: CAIXA | J33: 1 | K33: =VLOOKUP(A33,CONT_ANTE!A:D,4,0) -> 0 | L33: =IF(AND(F33=0,K33<>M33),"!@##@!","ok") -> ok | M33: 0 | N33: =IFERROR(SUM(M33*V33),0) -> 0 | O33: =SUMIF(SISTEMA!B:B,A33,SISTEMA!I:I)/J33 -> 0 | P33: =SUMIF(SISTEMA!B:B,B33,SISTEMA!I:I) -> 0 | Q33: =O33+P33 -> 0 | R33: =IFERROR(SUM(Q33*V33),0) -> 0 | S33: =IFERROR(VLOOKUP(A33,DIF_ANTE!A:D,4,0),"0")/J33 -> 0 | T33: =M33-Q33 -> 0 | U33: =T33-S33 -> 0 | V33: =IFERROR(VLOOKUP(A33,CUSTO!A:C,3,0),VLOOKUP(B33,CUSTO!A:C,3,0)) -> 3.726875 | W33: =IFERROR(SUM(T33*V33),0) -> 0 | X33: =IFERROR(T33/Q33,"") | Y33: =IFERROR(U33*V33,"-") -> 0 | Z33: ok
A34: 2701160006 | B34: - | C34: CAIXA CER MOEMA 12X300ML | D34: 4400 | E34: =IFERROR(IFERROR(VLOOKUP(B34,[1]Planilha1!$A$4:$C$277,3,0),VLOOKUP(A34,[1]Planilha1!$A$4:$C$277,3,0)),0) -> 0 | F34: =IFERROR(IFERROR(VLOOKUP(A34,[2]Planilha1!$A$4:$C$258,3,0),VLOOKUP(B34,[2]Planilha1!$A$4:$C$258,3,0)),0) -> 0 | G34: =IFERROR(IFERROR(VLOOKUP(A34,[1]Planilha1!$A$4:$D$277,4,0),VLOOKUP(B34,[1]Planilha1!$A$4:$D$277,4,0)),0) -> 0 | H34: =D34+E34-G34 -> 4400 | I34: CAIXA | J34: 1 | K34: =VLOOKUP(A34,CONT_ANTE!A:D,4,0) -> 4400 | L34: =IF(AND(F34=0,K34<>M34),"!@##@!","ok") -> ok | M34: =IFERROR(VLOOKUP(A34,CONTAGEM!B:G,6,0),VLOOKUP(B34,CONTAGEM!B:G,6,0)) -> 4400 | N34: =IFERROR(SUM(M34*V34),0) -> 8173.3211 | O34: =SUMIF(SISTEMA!B:B,A34,SISTEMA!I:I)/J34 -> 4400 | P34: =SUMIF(SISTEMA!B:B,B34,SISTEMA!I:I) -> 0 | Q34: =O34+P34 -> 4400 | R34: =IFERROR(SUM(Q34*V34),0) -> 8173.3211 | S34: =IFERROR(VLOOKUP(A34,DIF_ANTE!A:D,4,0),"0")/J34 -> 0 | T34: =M34-Q34 -> 0 | U34: =T34-S34 -> 0 | V34: =IFERROR(VLOOKUP(A34,CUSTO!A:C,3,0),VLOOKUP(B34,CUSTO!A:C,3,0)) -> 1.857573 | W34: =IFERROR(SUM(T34*V34),0) -> 0 | X34: =IFERROR(T34/Q34,"") -> 0 | Y34: =IFERROR(U34*V34,"-") -> 0 | Z34: ok
A35: 2701160005 | B35: - | C35: CAIXA CER MOEMA 6X600ML | D35: 11537 | E35: =IFERROR(IFERROR(VLOOKUP(B35,[1]Planilha1!$A$4:$C$277,3,0),VLOOKUP(A35,[1]Planilha1!$A$4:$C$277,3,0)),0) -> 8705 | F35: =IFERROR(IFERROR(VLOOKUP(A35,[2]Planilha1!$A$4:$C$258,3,0),VLOOKUP(B35,[2]Planilha1!$A$4:$C$258,3,0)),0) -> 5057 | G35: =IFERROR(IFERROR(VLOOKUP(A35,[1]Planilha1!$A$4:$D$277,4,0),VLOOKUP(B35,[1]Planilha1!$A$4:$D$277,4,0)),0) -> 13762 | H35: =D35+E35-G35 -> 6480 | I35: CAIXA | J35: 1 | K35: =VLOOKUP(A35,CONT_ANTE!A:D,4,0) -> 10537 | L35: =IF(AND(F35=0,K35<>M35),"!@##@!","ok") -> ok | M35: =IFERROR(VLOOKUP(A35,CONTAGEM!B:G,6,0),VLOOKUP(B35,CONTAGEM!B:G,6,0)) -> 4950 | N35: =IFERROR(SUM(M35*V35),0) -> 6726.0581 | O35: =SUMIF(SISTEMA!B:B,A35,SISTEMA!I:I)/J35 -> 6480 | P35: =SUMIF(SISTEMA!B:B,B35,SISTEMA!I:I) -> 0 | Q35: =O35+P35 -> 6480 | R35: =IFERROR(SUM(Q35*V35),0) -> 8805.0215 | S35: =IFERROR(VLOOKUP(A35,DIF_ANTE!A:D,4,0),"0")/J35 -> -1000 | T35: =M35-Q35 -> -1530 | U35: =T35-S35 -> -530 | V35: =IFERROR(VLOOKUP(A35,CUSTO!A:C,3,0),VLOOKUP(B35,CUSTO!A:C,3,0)) -> 1.3587996 | W35: =IFERROR(SUM(T35*V35),0) -> -2078.9634 | X35: =IFERROR(T35/Q35,"") -> -0.23611111 | Y35: =IFERROR(U35*V35,"-") -> -720.16379 | Z35: OK
A36: 2701160001 | B36: - | C36: CAIXA GIN JAMES COOK 6X900ML | D36: 20 | E36: =IFERROR(IFERROR(VLOOKUP(B36,[1]Planilha1!$A$4:$C$277,3,0),VLOOKUP(A36,[1]Planilha1!$A$4:$C$277,3,0)),0) -> 0 | F36: =IFERROR(IFERROR(VLOOKUP(A36,[2]Planilha1!$A$4:$C$258,3,0),VLOOKUP(B36,[2]Planilha1!$A$4:$C$258,3,0)),0) -> 0 | G36: =IFERROR(IFERROR(VLOOKUP(A36,[1]Planilha1!$A$4:$D$277,4,0),VLOOKUP(B36,[1]Planilha1!$A$4:$D$277,4,0)),0) -> 0 | H36: =D36+E36-G36 -> 20 | I36: CAIXA | J36: 1 | K36: =VLOOKUP(A36,CONT_ANTE!A:D,4,0) -> 0 | L36: =IF(AND(F36=0,K36<>M36),"!@##@!","ok") -> ok | M36: =IFERROR(VLOOKUP(A36,CONTAGEM!B:G,6,0),VLOOKUP(B36,CONTAGEM!B:G,6,0)) -> 0 | N36: =IFERROR(SUM(M36*V36),0) -> 0 | O36: =SUMIF(SISTEMA!B:B,A36,SISTEMA!I:I)/J36 -> 20 | P36: =SUMIF(SISTEMA!B:B,B36,SISTEMA!I:I) -> 0 | Q36: =O36+P36 -> 20 | R36: =IFERROR(SUM(Q36*V36),0) -> 49.96335 | S36: =IFERROR(VLOOKUP(A36,DIF_ANTE!A:D,4,0),"0")/J36 -> -20 | T36: =M36-Q36 -> -20 | U36: =T36-S36 -> 0 | V36: =IFERROR(VLOOKUP(A36,CUSTO!A:C,3,0),VLOOKUP(B36,CUSTO!A:C,3,0)) -> 2.4981675 | W36: =IFERROR(SUM(T36*V36),0) -> -49.96335 | X36: =IFERROR(T36/Q36,"") -> -1 | Y36: =IFERROR(U36*V36,"-") -> 0 | Z36: ok
A37: 2701160012 | B37: - | C37: CAIXA REFRIGERANTE REFRIKO TUBAINA 12X300ML | D37: 28252 | E37: =IFERROR(IFERROR(VLOOKUP(B37,[1]Planilha1!$A$4:$C$277,3,0),VLOOKUP(A37,[1]Planilha1!$A$4:$C$277,3,0)),0) -> 13588 | F37: =IFERROR(IFERROR(VLOOKUP(A37,[2]Planilha1!$A$4:$C$258,3,0),VLOOKUP(B37,[2]Planilha1!$A$4:$C$258,3,0)),0) -> 9108 | G37: =IFERROR(IFERROR(VLOOKUP(A37,[1]Planilha1!$A$4:$D$277,4,0),VLOOKUP(B37,[1]Planilha1!$A$4:$D$277,4,0)),0) -> 22746 | H37: =D37+E37-G37 -> 19094 | I37: CAIXA | J37: 1 | K37: =VLOOKUP(A37,CONT_ANTE!A:D,4,0) -> 25425 | L37: =IF(AND(F37=0,K37<>M37),"!@##@!","ok") -> ok | M37: =IFERROR(VLOOKUP(A37,CONTAGEM!B:G,6,0),VLOOKUP(B37,CONTAGEM!B:G,6,0)) -> 18175 | N37: =IFERROR(SUM(M37*V37),0) -> 28648.695 | O37: =SUMIF(SISTEMA!B:B,A37,SISTEMA!I:I)/J37 -> 19094 | P37: =SUMIF(SISTEMA!B:B,B37,SISTEMA!I:I) -> 0 | Q37: =O37+P37 -> 19094 | R37: =IFERROR(SUM(Q37*V37),0) -> 30097.286 | S37: =IFERROR(VLOOKUP(A37,DIF_ANTE!A:D,4,0),"0")/J37 -> -2827 | T37: =M37-Q37 -> -919 | U37: =T37-S37 -> 1908 | V37: =IFERROR(VLOOKUP(A37,CUSTO!A:C,3,0),VLOOKUP(B37,CUSTO!A:C,3,0)) -> 1.5762693 | W37: =IFERROR(SUM(T37*V37),0) -> -1448.5915 | X37: =IFERROR(T37/Q37,"") -> -0.048130303 | Y37: =IFERROR(U37*V37,"-") -> 3007.5219 | Z37: OK
A38: 2701160013 | B38: - | C38: CAIXA REFRIGERANTE REFRIKO TUBAINA 12X355ML | D38: 18877 | E38: =IFERROR(IFERROR(VLOOKUP(B38,[1]Planilha1!$A$4:$C$277,3,0),VLOOKUP(A38,[1]Planilha1!$A$4:$C$277,3,0)),0) -> 8272 | F38: =IFERROR(IFERROR(VLOOKUP(A38,[2]Planilha1!$A$4:$C$258,3,0),VLOOKUP(B38,[2]Planilha1!$A$4:$C$258,3,0)),0) -> 1879 | G38: =IFERROR(IFERROR(VLOOKUP(A38,[1]Planilha1!$A$4:$D$277,4,0),VLOOKUP(B38,[1]Planilha1!$A$4:$D$277,4,0)),0) -> 10151 | H38: =D38+E38-G38 -> 16998 | I38: CAIXA | J38: 1 | K38: =VLOOKUP(A38,CONT_ANTE!A:D,4,0) -> 18812 | L38: =IF(AND(F38=0,K38<>M38),"!@##@!","ok") -> ok | M38: =IFERROR(VLOOKUP(A38,CONTAGEM!B:G,6,0),VLOOKUP(B38,CONTAGEM!B:G,6,0)) -> 16640 | N38: =IFERROR(SUM(M38*V38),0) -> 30145.913 | O38: =SUMIF(SISTEMA!B:B,A38,SISTEMA!I:I)/J38 -> 16998 | P38: =SUMIF(SISTEMA!B:B,B38,SISTEMA!I:I) -> 0 | Q38: =O38+P38 -> 16998 | R38: =IFERROR(SUM(Q38*V38),0) -> 30794.485 | S38: =IFERROR(VLOOKUP(A38,DIF_ANTE!A:D,4,0),"0")/J38 -> -65 | T38: =M38-Q38 -> -358 | U38: =T38-S38 -> -293 | V38: =IFERROR(VLOOKUP(A38,CUSTO!A:C,3,0),VLOOKUP(B38,CUSTO!A:C,3,0)) -> 1.8116534 | W38: =IFERROR(SUM(T38*V38),0) -> -648.57193 | X38: =IFERROR(T38/Q38,"") -> -0.021061301 | Y38: =IFERROR(U38*V38,"-") -> -530.81446 | Z38: ok
A39: 2701160009 | B39: - | C39: CAIXA REFRIGERANTE REFRIKO TUBAINA S/ ACUCARES 12X300ML | D39: 24182 | E39: =IFERROR(IFERROR(VLOOKUP(B39,[1]Planilha1!$A$4:$C$277,3,0),VLOOKUP(A39,[1]Planilha1!$A$4:$C$277,3,0)),0) -> 10718 | F39: =IFERROR(IFERROR(VLOOKUP(A39,[2]Planilha1!$A$4:$C$258,3,0),VLOOKUP(B39,[2]Planilha1!$A$4:$C$258,3,0)),0) -> 5674 | G39: =IFERROR(IFERROR(VLOOKUP(A39,[1]Planilha1!$A$4:$D$277,4,0),VLOOKUP(B39,[1]Planilha1!$A$4:$D$277,4,0)),0) -> 16417 | H39: =D39+E39-G39 -> 18483 | I39: CAIXA | J39: 1 | K39: =VLOOKUP(A39,CONT_ANTE!A:D,4,0) -> 23945 | L39: =IF(AND(F39=0,K39<>M39),"!@##@!","ok") -> ok | M39: =IFERROR(VLOOKUP(A39,CONTAGEM!B:G,6,0),VLOOKUP(B39,CONTAGEM!B:G,6,0)) -> 17600 | N39: =IFERROR(SUM(M39*V39),0) -> 27018.554 | O39: =SUMIF(SISTEMA!B:B,A39,SISTEMA!I:I)/J39 -> 18483 | P39: =SUMIF(SISTEMA!B:B,B39,SISTEMA!I:I) -> 0 | Q39: =O39+P39 -> 18483 | R39: =IFERROR(SUM(Q39*V39),0) -> 28374.088 | S39: =IFERROR(VLOOKUP(A39,DIF_ANTE!A:D,4,0),"0")/J39 -> -237 | T39: =M39-Q39 -> -883 | U39: =T39-S39 -> -646 | V39: =IFERROR(VLOOKUP(A39,CUSTO!A:C,3,0),VLOOKUP(B39,CUSTO!A:C,3,0)) -> 1.5351451 | W39: =IFERROR(SUM(T39*V39),0) -> -1355.5332 | X39: =IFERROR(T39/Q39,"") -> -0.04777363 | Y39: =IFERROR(U39*V39,"-") -> -991.70376 | Z39: ok
A40: 2701160002 | B40: - | C40: CAIXA VODKA JAMES COOK 6X900ML | D40: 3112 | E40: =IFERROR(IFERROR(VLOOKUP(B40,[1]Planilha1!$A$4:$C$277,3,0),VLOOKUP(A40,[1]Planilha1!$A$4:$C$277,3,0)),0) -> 950 | F40: =IFERROR(IFERROR(VLOOKUP(A40,[2]Planilha1!$A$4:$C$258,3,0),VLOOKUP(B40,[2]Planilha1!$A$4:$C$258,3,0)),0) -> 0 | G40: =IFERROR(IFERROR(VLOOKUP(A40,[1]Planilha1!$A$4:$D$277,4,0),VLOOKUP(B40,[1]Planilha1!$A$4:$D$277,4,0)),0) -> 975 | H40: =D40+E40-G40 -> 3087 | I40: CAIXA | J40: 1 | K40: =VLOOKUP(A40,CONT_ANTE!A:D,4,0) -> 3284 | L40: =IF(AND(F40=0,K40<>M40),"!@##@!","ok") -> !@##@! | M40: =IFERROR(VLOOKUP(A40,CONTAGEM!B:G,6,0),VLOOKUP(B40,CONTAGEM!B:G,6,0)) -> 3324 | N40: =IFERROR(SUM(M40*V40),0) -> 8303.8961 | O40: =SUMIF(SISTEMA!B:B,A40,SISTEMA!I:I)/J40 -> 3087 | P40: =SUMIF(SISTEMA!B:B,B40,SISTEMA!I:I) -> 0 | Q40: =O40+P40 -> 3087 | R40: =IFERROR(SUM(Q40*V40),0) -> 7711.8313 | S40: =IFERROR(VLOOKUP(A40,DIF_ANTE!A:D,4,0),"0")/J40 -> 172 | T40: =M40-Q40 -> 237 | U40: =T40-S40 -> 65 | V40: =IFERROR(VLOOKUP(A40,CUSTO!A:C,3,0),VLOOKUP(B40,CUSTO!A:C,3,0)) -> 2.4981637 | W40: =IFERROR(SUM(T40*V40),0) -> 592.06479 | X40: =IFERROR(T40/Q40,"") -> 0.076773567 | Y40: =IFERROR(U40*V40,"-") -> 162.38064 | Z40: ok
A41: 2701240002 | B41: - | C41: CANTONEIRA SIMPLES 100X100X1580MM | D41: 4126.6767 | E41: =IFERROR(IFERROR(VLOOKUP(B41,[1]Planilha1!$A$4:$C$277,3,0),VLOOKUP(A41,[1]Planilha1!$A$4:$C$277,3,0)),0) -> 1790.3036 | F41: =IFERROR(IFERROR(VLOOKUP(A41,[2]Planilha1!$A$4:$C$258,3,0),VLOOKUP(B41,[2]Planilha1!$A$4:$C$258,3,0)),0) -> 518.62057 | G41: =IFERROR(IFERROR(VLOOKUP(A41,[1]Planilha1!$A$4:$D$277,4,0),VLOOKUP(B41,[1]Planilha1!$A$4:$D$277,4,0)),0) -> 2308.9242 | H41: =D41+E41-G41 -> 3608.0561 | I41: CAIXA | J41: 1 | K41: =VLOOKUP(A41,CONT_ANTE!A:D,4,0) -> 6200 | L41: =IF(AND(F41=0,K41<>M41),"!@##@!","ok") -> ok | M41: =IFERROR(VLOOKUP(A41,CONTAGEM!B:G,6,0),VLOOKUP(B41,CONTAGEM!B:G,6,0)) -> 4960 | N41: =IFERROR(SUM(M41*V41),0) -> 6052.3065 | O41: =SUMIF(SISTEMA!B:B,A41,SISTEMA!I:I)/J41 -> 3608.0561 | P41: =SUMIF(SISTEMA!B:B,B41,SISTEMA!I:I) -> 0 | Q41: =O41+P41 -> 3608.0561 | R41: =IFERROR(SUM(Q41*V41),0) -> 4402.6333 | S41: =IFERROR(VLOOKUP(A41,DIF_ANTE!A:D,4,0),"0")/J41 -> 2073.3233 | T41: =M41-Q41 -> 1351.9439 | U41: =T41-S41 -> -721.37943 | V41: =IFERROR(VLOOKUP(A41,CUSTO!A:C,3,0),VLOOKUP(B41,CUSTO!A:C,3,0)) -> 1.2202231 | W41: =IFERROR(SUM(T41*V41),0) -> 1649.6731 | X41: =IFERROR(T41/Q41,"") -> 0.37470146 | Y41: =IFERROR(U41*V41,"-") -> -880.24383 | Z41: ok
A42: 2701240004 | B42: - | C42: CHAPA SEM IMPRESSAO 1000X1200MM | D42: 49041.124 | E42: =IFERROR(IFERROR(VLOOKUP(B42,[1]Planilha1!$A$4:$C$277,3,0),VLOOKUP(A42,[1]Planilha1!$A$4:$C$277,3,0)),0) -> 51411 | F42: =IFERROR(IFERROR(VLOOKUP(A42,[2]Planilha1!$A$4:$C$258,3,0),VLOOKUP(B42,[2]Planilha1!$A$4:$C$258,3,0)),0) -> 10014.537 | G42: =IFERROR(IFERROR(VLOOKUP(A42,[1]Planilha1!$A$4:$D$277,4,0),VLOOKUP(B42,[1]Planilha1!$A$4:$D$277,4,0)),0) -> 21425.537 | H42: =D42+E42-G42 -> 79026.587 | I42: CAIXA | J42: 1 | K42: =VLOOKUP(A42,CONT_ANTE!A:D,4,0) -> 40650 | L42: =IF(AND(F42=0,K42<>M42),"!@##@!","ok") -> ok | M42: =IFERROR(VLOOKUP(A42,CONTAGEM!B:G,6,0),VLOOKUP(B42,CONTAGEM!B:G,6,0)) -> 40700 | N42: =IFERROR(SUM(M42*V42),0) -> 35867.818 | O42: =SUMIF(SISTEMA!B:B,A42,SISTEMA!I:I)/J42 -> 51026.587 | P42: =SUMIF(SISTEMA!B:B,B42,SISTEMA!I:I) -> 0 | Q42: =O42+P42 -> 51026.587 | R42: =IFERROR(SUM(Q42*V42),0) -> 44968.362 | S42: =IFERROR(VLOOKUP(A42,DIF_ANTE!A:D,4,0),"0")/J42 -> -8391.1239 | T42: =M42-Q42 -> -10326.587 | U42: =T42-S42 -> -1935.4633 | V42: =IFERROR(VLOOKUP(A42,CUSTO!A:C,3,0),VLOOKUP(B42,CUSTO!A:C,3,0)) -> 0.88127317 | W42: =IFERROR(SUM(T42*V42),0) -> -9100.5442 | X42: =IFERROR(T42/Q42,"") -> -0.2023766 | Y42: =IFERROR(U42*V42,"-") -> -1705.6719 | Z42: ok
A43: 2701240005 | B43: - | C43: CHAPA SEM IMPRESSAO CORRUGADA 1000X1200MM | D43: 7715.0033 | E43: =IFERROR(IFERROR(VLOOKUP(B43,[1]Planilha1!$A$4:$C$277,3,0),VLOOKUP(A43,[1]Planilha1!$A$4:$C$277,3,0)),0) -> 0 | F43: =IFERROR(IFERROR(VLOOKUP(A43,[2]Planilha1!$A$4:$C$258,3,0),VLOOKUP(B43,[2]Planilha1!$A$4:$C$258,3,0)),0) -> 0 | G43: =IFERROR(IFERROR(VLOOKUP(A43,[1]Planilha1!$A$4:$D$277,4,0),VLOOKUP(B43,[1]Planilha1!$A$4:$D$277,4,0)),0) -> 0 | H43: =D43+E43-G43 -> 7715.0033 | I43: CAIXA | J43: 1 | K43: =VLOOKUP(A43,CONT_ANTE!A:D,4,0) -> 7600 | L43: =IF(AND(F43=0,K43<>M43),"!@##@!","ok") -> !@##@! | M43: =IFERROR(VLOOKUP(A43,CONTAGEM!B:G,6,0),VLOOKUP(B43,CONTAGEM!B:G,6,0)) -> 7500 | N43: =IFERROR(SUM(M43*V43),0) -> 25684.382 | O43: =SUMIF(SISTEMA!B:B,A43,SISTEMA!I:I)/J43 -> 7715.0033 | P43: =SUMIF(SISTEMA!B:B,B43,SISTEMA!I:I) -> 0 | Q43: =O43+P43 -> 7715.0033 | R43: =IFERROR(SUM(Q43*V43),0) -> 26420.679 | S43: =IFERROR(VLOOKUP(A43,DIF_ANTE!A:D,4,0),"0")/J43 -> -115.00326 | T43: =M43-Q43 -> -215.00326 | U43: =T43-S43 -> -100 | V43: =IFERROR(VLOOKUP(A43,CUSTO!A:C,3,0),VLOOKUP(B43,CUSTO!A:C,3,0)) -> 3.4245843 | W43: =IFERROR(SUM(T43*V43),0) -> -736.29679 | X43: =IFERROR(T43/Q43,"") -> -0.027868201 | Y43: =IFERROR(U43*V43,"-") -> -342.45843 | Z43: ok
A44: 3002020007 | B44: - | C44: CARVAO ATIVADO | D44: 860 | E44: =IFERROR(IFERROR(VLOOKUP(B44,[1]Planilha1!$A$4:$C$277,3,0),VLOOKUP(A44,[1]Planilha1!$A$4:$C$277,3,0)),0) -> 0 | F44: =IFERROR(IFERROR(VLOOKUP(A44,[2]Planilha1!$A$4:$C$258,3,0),VLOOKUP(B44,[2]Planilha1!$A$4:$C$258,3,0)),0) -> 90 | G44: =IFERROR(IFERROR(VLOOKUP(A44,[1]Planilha1!$A$4:$D$277,4,0),VLOOKUP(B44,[1]Planilha1!$A$4:$D$277,4,0)),0) -> 90 | H44: =D44+E44-G44 -> 770 | I44: CARVAO | J44: 1 | K44: =VLOOKUP(A44,CONT_ANTE!A:D,4,0) -> 800 | L44: =IF(AND(F44=0,K44<>M44),"!@##@!","ok") -> ok | M44: =IFERROR(VLOOKUP(A44,CONTAGEM!B:G,6,0),VLOOKUP(B44,CONTAGEM!B:G,6,0)) -> 770 | N44: =IFERROR(SUM(M44*V44),0) -> 2869.6937 | O44: =SUMIF(SISTEMA!B:B,A44,SISTEMA!I:I)/J44 -> 770 | P44: =SUMIF(SISTEMA!B:B,B44,SISTEMA!I:I) -> 0 | Q44: =O44+P44 -> 770 | R44: =IFERROR(SUM(Q44*V44),0) -> 2869.6937 | S44: =IFERROR(VLOOKUP(A44,DIF_ANTE!A:D,4,0),"0")/J44 -> -60 | T44: =M44-Q44 -> 0 | U44: =T44-S44 -> 60 | V44: =IFERROR(VLOOKUP(A44,CUSTO!A:C,3,0),VLOOKUP(B44,CUSTO!A:C,3,0)) -> 3.726875 | W44: =IFERROR(SUM(T44*V44),0) -> 0 | X44: =IFERROR(T44/Q44,"") -> 0 | Y44: =IFERROR(U44*V44,"-") -> 223.6125 | Z44: OK
A45: 2701090003 | B45: - | C45: ACIDO LACTICO | D45: 974.40009 | E45: =IFERROR(IFERROR(VLOOKUP(B45,[1]Planilha1!$A$4:$C$277,3,0),VLOOKUP(A45,[1]Planilha1!$A$4:$C$277,3,0)),0) -> 1000 | F45: =IFERROR(IFERROR(VLOOKUP(A45,[2]Planilha1!$A$4:$C$258,3,0),VLOOKUP(B45,[2]Planilha1!$A$4:$C$258,3,0)),0) -> 234.7 | G45: =IFERROR(IFERROR(VLOOKUP(A45,[1]Planilha1!$A$4:$D$277,4,0),VLOOKUP(B45,[1]Planilha1!$A$4:$D$277,4,0)),0) -> 234.7 | H45: =D45+E45-G45 -> 1739.7001 | I45: CERVEJARIA | J45: 1 | K45: =VLOOKUP(A45,CONT_ANTE!A:D,4,0) -> 900 | L45: =IF(AND(F45=0,K45<>M45),"!@##@!","ok") -> ok | M45: =IFERROR(VLOOKUP(A45,CONTAGEM!B:G,6,0),VLOOKUP(B45,CONTAGEM!B:G,6,0)) -> 1775 | N45: =IFERROR(SUM(M45*V45),0) -> 17580.097 | O45: =SUMIF(SISTEMA!B:B,A45,SISTEMA!I:I)/J45 -> 1739.7001 | P45: =SUMIF(SISTEMA!B:B,B45,SISTEMA!I:I) -> 0 | Q45: =O45+P45 -> 1739.7001 | R45: =IFERROR(SUM(Q45*V45),0) -> 17230.477 | S45: =IFERROR(VLOOKUP(A45,DIF_ANTE!A:D,4,0),"0")/J45 -> -74.40009 | T45: =M45-Q45 -> 35.29991 | U45: =T45-S45 -> 109.7 | V45: =IFERROR(VLOOKUP(A45,CUSTO!A:C,3,0),VLOOKUP(B45,CUSTO!A:C,3,0)) -> 9.90428 | W45: =IFERROR(SUM(T45*V45),0) -> 349.62019 | X45: =IFERROR(T45/Q45,"") -> 0.020290802 | Y45: =IFERROR(U45*V45,"-") -> 1086.4995 | Z45: OK
...

Sheet Planilha2
L2: Sistema | M2: Produção
K3: Saldo em 31/12 | L3: 2311041 | M3: 2311041
I4: Entradas | J4: jan | K4: =1460160*3 -> 4380480 | L4: =SUM(K4:K6) -> 11681280 | M4: =SUM(L4:L6) -> 11681280
J5: Fev | K5: =1460160*2 -> 2920320
J6: Mar | K6: =1460160*3 -> 4380480
I7: Saidas | J7: Jan | K7: 4929395 | L7: =SUM(K7:K9) -> 11807538 | M7: =4916976+17762 -> 4934738
J8: Fev | K8: 1593143 | M8: =1588356+6231 -> 1594587
J9: Mar | K9: 5285000 | M9: =4641756+16653 -> 4658409
K10: Saldo em 31/03 | L10: =L3+L4-L7 -> 2184783 | M10: =M3+M4-M7-M8-M9 -> 2804587
K11: Contagem 31/03 | L11: 3047780
K14: Saldo em 31/12 | L14: 12830 | M14: 723648 | Q14: jan | R14: fev | S14: mar
K15: Compra | L15: 66340 | M15: 341760 | Q15: 74826 | R15: 50448 | S15: 109824
K16: Consumo | L16: 53770 | M16: 291655 | N16: 298428 | O16: =M16-N16 -> -6773 | Q16: 188964 | R16: 73944 | S16: 198246
K17: Saldo em 31/01 | L17: =L14+L15-L16 -> 25400 | M17: =M14+M15-M16 -> 773753 | Q17: 8478 | R17: 12342 | S17: 13976
K18: Compra | L18: 28070 | M18: 0 | Q18: 26160 | R18: 42078 | S18: 50784
K19: Consumo | L19: 33510 | M19: 179241 | N19: 178812 | O19: =M19-N19 -> 429 | P19: total | Q19: =SUM(Q15:Q18) -> 298428 | R19: =SUM(R15:R18) -> 178812 | S19: =SUM(S15:S18) -> 372830
K20: Saldo em 28/02 | L20: =L17+L18-L19 -> 19960 | M20: =M17+M18-M19 -> 594512
K21: Compra | L21: 70440 | M21: 0
K22: Consumo | L22: 72300 | M22: =433062-59808 -> 373254 | N22: 372830 | O22: =M22-N22 -> 424
K23: Saldo em 31/03 | L23: =L20+L21-L22 -> 18100 | M23: =M20-M22+M21 -> 221258

Sheet CONCILIÇÃO_SEM_VASILHAME
L1: Valor Estoque Físico | O1: Valor Estoque Sistema | T1: Acuracidade Qualitativa | U1: Custo Diferença | V1: Percentual Diferença
L2: =SUBTOTAL(9,BASE_CONCILI12[CUSTO FÍSICO]) -> 207493.66 | O2: =SUBTOTAL(9,BASE_CONCILI12[CUSTO SISTEMA]) -> 0 | T2: =(COUNTIF(BASE_CONCILI12[30/jun],">0")-COUNTIF(BASE_CONCILI12[ACURACIDADE],">1,05")-COUNTIF(BASE_CONCILI12[ACURACIDADE],"<0,95"))/COUNTIF(BASE_CONCILI12[30/jun],">0") -> 1 | U2: =SUBTOTAL(9,BASE_CONCILI12[CUSTO DIVERGÊNCIA]) -> 0 | V2: =U2/O2 -> #DIV/0!
A4: CÓD. SAIB | B4: CÓD. PRODUTO | C4: DESCRIÇÃO | D4: CLASSE | E4: 30/mai | F4: CONSUMO REAL | G4: CONSUMO TEORICO | H4: DIFERENÇA CONSUMO | I4: RECEBIMENTO | J4: TRANSFERÊNCIA | K4: QTDE. FINAL | L4: 30/jun | M4: CUSTO FÍSICO | N4: 01/fev | O4: SISTEMA | P4: CUSTO SISTEMA | Q4: DIFERENÇA ANTERIOR | R4: DIFERENÇA ATUAL | S4: DIFERENÇA MÊS | T4: CUSTO MP (UN) | U4: CUSTO DIVERGÊNCIA | V4: ACURACIDADE | W4: DIFERENÇA VALOR | X4: OBSERVAÇÃO
A5: 55 | C5: ACUCAR CRISTAL | D5: AÇUCAR | E5: =VLOOKUP(BASE_CONCILI12[[#This Row],[CÓD. SAIB]],CONT_ANTE!A:D,4,0) -> #N/A | F5: =SUMIF(#REF!,BASE_CONCILI12[[#This Row],[CÓD. SAIB]],#REF!) -> #REF! | G5: =SUMIF(#REF!,BASE_CONCILI12[[#This Row],[CÓD. SAIB]],#REF!) -> #REF! | H5: =BASE_CONCILI12[[#This Row],[CONSUMO REAL]]-BASE_CONCILI12[[#This Row],[CONSUMO TEORICO]] -> #REF! | I5: =SUMIF(#REF!,BASE_CONCILI12[[#This Row],[CÓD. SAIB]],#REF!) -> #REF! | J5: =SUMIF(#REF!,BASE_CONCILI12[[#This Row],[CÓD. SAIB]],#REF!) -> #REF! | K5: =BASE_CONCILI12[[#This Row],[30/mai]]+BASE_CONCILI12[[#This Row],[RECEBIMENTO]]-BASE_CONCILI12[[#This Row],[TRANSFERÊNCIA]]-BASE_CONCILI12[[#This Row],[CONSUMO REAL]] -> #N/A | L5: =IFERROR(VLOOKUP(BASE_CONCILI12[[#This Row],[CÓD. SAIB]],BASE_CONTAG[[LAVRE]:[CONTAGEM FINAL]],7,0),0) -> 117.84 | M5: =IFERROR(SUM(BASE_CONCILI12[[#This Row],[30/jun]]*BASE_CONCILI12[[#This Row],[CUSTO MP (UN)]]),0) -> 0 | N5: =IFERROR(VLOOKUP(BASE_CONCILI12[[#This Row],[CÓD. SAIB]],BASE_CONTAG[],5,0),"") -> 117.84 | O5: =SUMIF(SISTEMA!#REF!,BASE_CONCILI12[[#This Row],[CÓD. SAIB]],SISTEMA!#REF!) -> #REF! | P5: =IFERROR(SUM(BASE_CONCILI12[[#This Row],[SISTEMA]]*BASE_CONCILI12[[#This Row],[CUSTO MP (UN)]]),0) -> 0 | Q5: =IFERROR(VLOOKUP(BASE_CONCILI12[[#This Row],[CÓD. SAIB]],BASE_DIFERENÇA[],4,0),"0") -> 0 | R5: =BASE_CONCILI12[[#This Row],[30/jun]]-BASE_CONCILI12[[#This Row],[SISTEMA]] -> #REF! | S5: =IFERROR(BASE_CONCILI12[[#This Row],[DIFERENÇA ANTERIOR]]-BASE_CONCILI12[[#This Row],[DIFERENÇA ATUAL]],"-") -> - | T5: =VLOOKUP(BASE_CONCILI12[[#This Row],[CÓD. SAIB]],CUSTO!#REF!,3,0) -> #REF! | U5: =IFERROR(SUM(BASE_CONCILI12[[#This Row],[DIFERENÇA ATUAL]]*BASE_CONCILI12[[#This Row],[CUSTO MP (UN)]]),0) -> 0 | V5: =IFERROR(BASE_CONCILI12[[#This Row],[30/jun]]/BASE_CONCILI12[[#This Row],[SISTEMA]],"") | W5: =IFERROR(BASE_CONCILI12[[#This Row],[DIFERENÇA MÊS]]*BASE_CONCILI12[[#This Row],[CUSTO MP (UN)]],"-") -> - | X5: OK
A6: 31395 | C6: ETANOL HIDRATADO | D6: ALCOOL | E6: =VLOOKUP(BASE_CONCILI12[[#This Row],[CÓD. SAIB]],CONT_ANTE!A:D,4,0) -> #N/A | F6: =SUMIF(#REF!,BASE_CONCILI12[[#This Row],[CÓD. SAIB]],#REF!) -> #REF! | G6: =SUMIF(#REF!,BASE_CONCILI12[[#This Row],[CÓD. SAIB]],#REF!) -> #REF! | H6: =BASE_CONCILI12[[#This Row],[CONSUMO REAL]]-BASE_CONCILI12[[#This Row],[CONSUMO TEORICO]] -> #REF! | I6: =SUMIF(#REF!,BASE_CONCILI12[[#This Row],[CÓD. SAIB]],#REF!) -> #REF! | J6: =SUMIF(#REF!,BASE_CONCILI12[[#This Row],[CÓD. SAIB]],#REF!) -> #REF! | K6: =BASE_CONCILI12[[#This Row],[30/mai]]+BASE_CONCILI12[[#This Row],[RECEBIMENTO]]-BASE_CONCILI12[[#This Row],[TRANSFERÊNCIA]]-BASE_CONCILI12[[#This Row],[CONSUMO REAL]] -> #N/A | L6: =IFERROR(VLOOKUP(BASE_CONCILI12[[#This Row],[CÓD. SAIB]],BASE_CONTAG[[LAVRE]:[CONTAGEM FINAL]],7,0),0) -> 84 | M6: =IFERROR(SUM(BASE_CONCILI12[[#This Row],[30/jun]]*BASE_CONCILI12[[#This Row],[CUSTO MP (UN)]]),0) -> 0 | N6: =IFERROR(VLOOKUP(BASE_CONCILI12[[#This Row],[CÓD. SAIB]],BASE_CONTAG[],5,0),"") -> 84 | O6: =SUMIF(SISTEMA!#REF!,BASE_CONCILI12[[#This Row],[CÓD. SAIB]],SISTEMA!#REF!) -> #REF! | P6: =IFERROR(SUM(BASE_CONCILI12[[#This Row],[SISTEMA]]*BASE_CONCILI12[[#This Row],[CUSTO MP (UN)]]),0) -> 0 | Q6: =IFERROR(VLOOKUP(BASE_CONCILI12[[#This Row],[CÓD. SAIB]],BASE_DIFERENÇA[],4,0),"0") -> 0 | R6: =BASE_CONCILI12[[#This Row],[30/jun]]-BASE_CONCILI12[[#This Row],[SISTEMA]] -> #REF! | S6: =IFERROR(BASE_CONCILI12[[#This Row],[DIFERENÇA ANTERIOR]]-BASE_CONCILI12[[#This Row],[DIFERENÇA ATUAL]],"-") -> - | T6: =VLOOKUP(BASE_CONCILI12[[#This Row],[CÓD. SAIB]],CUSTO!#REF!,3,0) -> #REF! | U6: =IFERROR(SUM(BASE_CONCILI12[[#This Row],[DIFERENÇA ATUAL]]*BASE_CONCILI12[[#This Row],[CUSTO MP (UN)]]),0) -> 0 | V6: =IFERROR(BASE_CONCILI12[[#This Row],[30/jun]]/BASE_CONCILI12[[#This Row],[SISTEMA]],"") | W6: =IFERROR(BASE_CONCILI12[[#This Row],[DIFERENÇA MÊS]]*BASE_CONCILI12[[#This Row],[CUSTO MP (UN)]],"-") -> - | X6: OK
A7: 31352 | C7: AA ENERGY FLAVOR | D7: AROMA | E7: =VLOOKUP(BASE_CONCILI12[[#This Row],[CÓD. SAIB]],CONT_ANTE!A:D,4,0) -> #N/A | F7: =SUMIF(#REF!,BASE_CONCILI12[[#This Row],[CÓD. SAIB]],#REF!) -> #REF! | G7: =SUMIF(#REF!,BASE_CONCILI12[[#This Row],[CÓD. SAIB]],#REF!) -> #REF! | H7: =BASE_CONCILI12[[#This Row],[CONSUMO REAL]]-BASE_CONCILI12[[#This Row],[CONSUMO TEORICO]] -> #REF! | I7: =SUMIF(#REF!,BASE_CONCILI12[[#This Row],[CÓD. SAIB]],#REF!) -> #REF! | J7: =SUMIF(#REF!,BASE_CONCILI12[[#This Row],[CÓD. SAIB]],#REF!) -> #REF! | K7: =BASE_CONCILI12[[#This Row],[30/mai]]+BASE_CONCILI12[[#This Row],[RECEBIMENTO]]-BASE_CONCILI12[[#This Row],[TRANSFERÊNCIA]]-BASE_CONCILI12[[#This Row],[CONSUMO REAL]] -> #N/A | L7: =IFERROR(VLOOKUP(BASE_CONCILI12[[#This Row],[CÓD. SAIB]],BASE_CONTAG[[LAVRE]:[CONTAGEM FINAL]],7,0),0) -> 0 | M7: =IFERROR(SUM(BASE_CONCILI12[[#This Row],[30/jun]]*BASE_CONCILI12[[#This Row],[CUSTO MP (UN)]]),0) -> 0 | N7: =IFERROR(VLOOKUP(BASE_CONCILI12[[#This Row],[CÓD. SAIB]],BASE_CONTAG[],5,0),"") -> 0 | O7: =SUMIF(SISTEMA!#REF!,BASE_CONCILI12[[#This Row],[CÓD. SAIB]],SISTEMA!#REF!) -> #REF! | P7: =IFERROR(SUM(BASE_CONCILI12[[#This Row],[SISTEMA]]*BASE_CONCILI12[[#This Row],[CUSTO MP (UN)]]),0) -> 0 | Q7: =IFERROR(VLOOKUP(BASE_CONCILI12[[#This Row],[CÓD. SAIB]],BASE_DIFERENÇA[],4,0),"0") -> 0 | R7: =BASE_CONCILI12[[#This Row],[30/jun]]-BASE_CONCILI12[[#This Row],[SISTEMA]] -> #REF! | S7: =IFERROR(BASE_CONCILI12[[#This Row],[DIFERENÇA ANTERIOR]]-BASE_CONCILI12[[#This Row],[DIFERENÇA ATUAL]],"-") -> - | T7: =VLOOKUP(BASE_CONCILI12[[#This Row],[CÓD. SAIB]],CUSTO!#REF!,3,0) -> #REF! | U7: =IFERROR(SUM(BASE_CONCILI12[[#This Row],[DIFERENÇA ATUAL]]*BASE_CONCILI12[[#This Row],[CUSTO MP (UN)]]),0) -> 0 | V7: =IFERROR(BASE_CONCILI12[[#This Row],[30/jun]]/BASE_CONCILI12[[#This Row],[SISTEMA]],"") | W7: =IFERROR(BASE_CONCILI12[[#This Row],[DIFERENÇA MÊS]]*BASE_CONCILI12[[#This Row],[CUSTO MP (UN)]],"-") -> - | X7: OK
A8: 2089 | C8: AROMA ART DE TUTTI FRUTTI RB 10766 | D8: AROMA | E8: =VLOOKUP(BASE_CONCILI12[[#This Row],[CÓD. SAIB]],CONT_ANTE!A:D,4,0) -> #N/A | F8: =SUMIF(#REF!,BASE_CONCILI12[[#This Row],[CÓD. SAIB]],#REF!) -> #REF! | G8: =SUMIF(#REF!,BASE_CONCILI12[[#This Row],[CÓD. SAIB]],#REF!) -> #REF! | H8: =BASE_CONCILI12[[#This Row],[CONSUMO REAL]]-BASE_CONCILI12[[#This Row],[CONSUMO TEORICO]] -> #REF! | I8: =SUMIF(#REF!,BASE_CONCILI12[[#This Row],[CÓD. SAIB]],#REF!) -> #REF! | J8: =SUMIF(#REF!,BASE_CONCILI12[[#This Row],[CÓD. SAIB]],#REF!) -> #REF! | K8: =BASE_CONCILI12[[#This Row],[30/mai]]+BASE_CONCILI12[[#This Row],[RECEBIMENTO]]-BASE_CONCILI12[[#This Row],[TRANSFERÊNCIA]]-BASE_CONCILI12[[#This Row],[CONSUMO REAL]] -> #N/A | L8: =IFERROR(VLOOKUP(BASE_CONCILI12[[#This Row],[CÓD. SAIB]],BASE_CONTAG[[LAVRE]:[CONTAGEM FINAL]],7,0),0) -> 0 | M8: =IFERROR(SUM(BASE_CONCILI12[[#This Row],[30/jun]]*BASE_CONCILI12[[#This Row],[CUSTO MP (UN)]]),0) -> 0 | N8: =IFERROR(VLOOKUP(BASE_CONCILI12[[#This Row],[CÓD. SAIB]],BASE_CONTAG[],5,0),"") | O8: =SUMIF(SISTEMA!#REF!,BASE_CONCILI12[[#This Row],[CÓD. SAIB]],SISTEMA!#REF!) -> #REF! | P8: =IFERROR(SUM(BASE_CONCILI12[[#This Row],[SISTEMA]]*BASE_CONCILI12[[#This Row],[CUSTO MP (UN)]]),0) -> 0 | Q8: =IFERROR(VLOOKUP(BASE_CONCILI12[[#This Row],[CÓD. SAIB]],BASE_DIFERENÇA[],4,0),"0") -> 0 | R8: =BASE_CONCILI12[[#This Row],[30/jun]]-BASE_CONCILI12[[#This Row],[SISTEMA]] -> #REF! | S8: =IFERROR(BASE_CONCILI12[[#This Row],[DIFERENÇA ANTERIOR]]-BASE_CONCILI12[[#This Row],[DIFERENÇA ATUAL]],"-") -> - | T8: =VLOOKUP(BASE_CONCILI12[[#This Row],[CÓD. SAIB]],CUSTO!#REF!,3,0) -> #REF! | U8: =IFERROR(SUM(BASE_CONCILI12[[#This Row],[DIFERENÇA ATUAL]]*BASE_CONCILI12[[#This Row],[CUSTO MP (UN)]]),0) -> 0 | V8: =IFERROR(BASE_CONCILI12[[#This Row],[30/jun]]/BASE_CONCILI12[[#This Row],[SISTEMA]],"") | W8: =IFERROR(BASE_CONCILI12[[#This Row],[DIFERENÇA MÊS]]*BASE_CONCILI12[[#This Row],[CUSTO MP (UN)]],"-") -> - | X8: OK
